2025-08-18 20:38:16 [INFO] [root] 수출입은행 API 요청: URL='https://oapi.koreaexim.go.kr/site/program/financial/exchangeJSON', Params='{'authkey': '[REDACTED]', 'searchdate': '20250818', 'data': 'AP01'}'
2025-08-18 20:38:17 [ERROR] [root] 수출입은행 API(AP01) 요청 중 오류: HTTPSConnectionPool(host='oapi.koreaexim.go.kr', port=443): Max retries exceeded with url: /site/program/financial/exchangeJSON?authkey=YOUR_EXIM_API_KEY_HERE&searchdate=20250818&data=AP01 (Caused by SSLError(SSLCertVerificationError(1, '[SSL: CERTIFICATE_VERIFY_FAILED] certificate verify failed: self-signed certificate in certificate chain (_ssl.c:1010)')))
Traceback (most recent call last):
  File "/home/jules/.pyenv/versions/3.12.11/lib/python3.12/site-packages/urllib3/connectionpool.py", line 464, in _make_request
    self._validate_conn(conn)
  File "/home/jules/.pyenv/versions/3.12.11/lib/python3.12/site-packages/urllib3/connectionpool.py", line 1093, in _validate_conn
    conn.connect()
  File "/home/jules/.pyenv/versions/3.12.11/lib/python3.12/site-packages/urllib3/connection.py", line 790, in connect
    sock_and_verified = _ssl_wrap_socket_and_match_hostname(
                        ^^^^^^^^^^^^^^^^^^^^^^^^^^^^^^^^^^^^
  File "/home/jules/.pyenv/versions/3.12.11/lib/python3.12/site-packages/urllib3/connection.py", line 969, in _ssl_wrap_socket_and_match_hostname
    ssl_sock = ssl_wrap_socket(
               ^^^^^^^^^^^^^^^^
  File "/home/jules/.pyenv/versions/3.12.11/lib/python3.12/site-packages/urllib3/util/ssl_.py", line 480, in ssl_wrap_socket
    ssl_sock = _ssl_wrap_socket_impl(sock, context, tls_in_tls, server_hostname)
               ^^^^^^^^^^^^^^^^^^^^^^^^^^^^^^^^^^^^^^^^^^^^^^^^^^^^^^^^^^^^^^^^^
  File "/home/jules/.pyenv/versions/3.12.11/lib/python3.12/site-packages/urllib3/util/ssl_.py", line 524, in _ssl_wrap_socket_impl
    return ssl_context.wrap_socket(sock, server_hostname=server_hostname)
           ^^^^^^^^^^^^^^^^^^^^^^^^^^^^^^^^^^^^^^^^^^^^^^^^^^^^^^^^^^^^^^
  File "/home/jules/.pyenv/versions/3.12.11/lib/python3.12/ssl.py", line 455, in wrap_socket
    return self.sslsocket_class._create(
           ^^^^^^^^^^^^^^^^^^^^^^^^^^^^^
  File "/home/jules/.pyenv/versions/3.12.11/lib/python3.12/ssl.py", line 1041, in _create
    self.do_handshake()
  File "/home/jules/.pyenv/versions/3.12.11/lib/python3.12/ssl.py", line 1319, in do_handshake
    self._sslobj.do_handshake()
ssl.SSLCertVerificationError: [SSL: CERTIFICATE_VERIFY_FAILED] certificate verify failed: self-signed certificate in certificate chain (_ssl.c:1010)

During handling of the above exception, another exception occurred:

Traceback (most recent call last):
  File "/home/jules/.pyenv/versions/3.12.11/lib/python3.12/site-packages/urllib3/connectionpool.py", line 787, in urlopen
    response = self._make_request(
               ^^^^^^^^^^^^^^^^^^^
  File "/home/jules/.pyenv/versions/3.12.11/lib/python3.12/site-packages/urllib3/connectionpool.py", line 488, in _make_request
    raise new_e
urllib3.exceptions.SSLError: [SSL: CERTIFICATE_VERIFY_FAILED] certificate verify failed: self-signed certificate in certificate chain (_ssl.c:1010)

The above exception was the direct cause of the following exception:

Traceback (most recent call last):
  File "/home/jules/.pyenv/versions/3.12.11/lib/python3.12/site-packages/requests/adapters.py", line 667, in send
    resp = conn.urlopen(
           ^^^^^^^^^^^^^
  File "/home/jules/.pyenv/versions/3.12.11/lib/python3.12/site-packages/urllib3/connectionpool.py", line 841, in urlopen
    retries = retries.increment(
              ^^^^^^^^^^^^^^^^^^
  File "/home/jules/.pyenv/versions/3.12.11/lib/python3.12/site-packages/urllib3/util/retry.py", line 519, in increment
    raise MaxRetryError(_pool, url, reason) from reason  # type: ignore[arg-type]
    ^^^^^^^^^^^^^^^^^^^^^^^^^^^^^^^^^^^^^^^^^^^^^^^^^^^
urllib3.exceptions.MaxRetryError: HTTPSConnectionPool(host='oapi.koreaexim.go.kr', port=443): Max retries exceeded with url: /site/program/financial/exchangeJSON?authkey=YOUR_EXIM_API_KEY_HERE&searchdate=20250818&data=AP01 (Caused by SSLError(SSLCertVerificationError(1, '[SSL: CERTIFICATE_VERIFY_FAILED] certificate verify failed: self-signed certificate in certificate chain (_ssl.c:1010)')))

During handling of the above exception, another exception occurred:

Traceback (most recent call last):
  File "/app/utils/api_handlers/exim.py", line 33, in _fetch_exim_data
    response = await asyncio.to_thread(session.get, BASE_URL, params=params, timeout=10)
               ^^^^^^^^^^^^^^^^^^^^^^^^^^^^^^^^^^^^^^^^^^^^^^^^^^^^^^^^^^^^^^^^^^^^^^^^^
  File "/home/jules/.pyenv/versions/3.12.11/lib/python3.12/asyncio/threads.py", line 25, in to_thread
    return await loop.run_in_executor(None, func_call)
           ^^^^^^^^^^^^^^^^^^^^^^^^^^^^^^^^^^^^^^^^^^^
  File "/home/jules/.pyenv/versions/3.12.11/lib/python3.12/concurrent/futures/thread.py", line 59, in run
    result = self.fn(*self.args, **self.kwargs)
             ^^^^^^^^^^^^^^^^^^^^^^^^^^^^^^^^^^
  File "/home/jules/.pyenv/versions/3.12.11/lib/python3.12/site-packages/requests/sessions.py", line 602, in get
    return self.request("GET", url, **kwargs)
           ^^^^^^^^^^^^^^^^^^^^^^^^^^^^^^^^^^
  File "/home/jules/.pyenv/versions/3.12.11/lib/python3.12/site-packages/requests/sessions.py", line 589, in request
    resp = self.send(prep, **send_kwargs)
           ^^^^^^^^^^^^^^^^^^^^^^^^^^^^^^
  File "/home/jules/.pyenv/versions/3.12.11/lib/python3.12/site-packages/requests/sessions.py", line 703, in send
    r = adapter.send(request, **kwargs)
        ^^^^^^^^^^^^^^^^^^^^^^^^^^^^^^^
  File "/home/jules/.pyenv/versions/3.12.11/lib/python3.12/site-packages/requests/adapters.py", line 698, in send
    raise SSLError(e, request=request)
requests.exceptions.SSLError: HTTPSConnectionPool(host='oapi.koreaexim.go.kr', port=443): Max retries exceeded with url: /site/program/financial/exchangeJSON?authkey=YOUR_EXIM_API_KEY_HERE&searchdate=20250818&data=AP01 (Caused by SSLError(SSLCertVerificationError(1, '[SSL: CERTIFICATE_VERIFY_FAILED] certificate verify failed: self-signed certificate in certificate chain (_ssl.c:1010)')))
2025-08-18 20:38:17 [INFO] [root] 수출입은행 API 요청: URL='https://oapi.koreaexim.go.kr/site/program/financial/exchangeJSON', Params='{'authkey': '[REDACTED]', 'searchdate': '20250818', 'data': 'AP01'}'
2025-08-18 20:38:18 [ERROR] [root] 수출입은행 API(AP01) 요청 중 오류: HTTPSConnectionPool(host='oapi.koreaexim.go.kr', port=443): Max retries exceeded with url: /site/program/financial/exchangeJSON?authkey=YOUR_EXIM_API_KEY_HERE&searchdate=20250818&data=AP01 (Caused by SSLError(SSLCertVerificationError(1, '[SSL: CERTIFICATE_VERIFY_FAILED] certificate verify failed: self-signed certificate in certificate chain (_ssl.c:1010)')))
Traceback (most recent call last):
  File "/home/jules/.pyenv/versions/3.12.11/lib/python3.12/site-packages/urllib3/connectionpool.py", line 464, in _make_request
    self._validate_conn(conn)
  File "/home/jules/.pyenv/versions/3.12.11/lib/python3.12/site-packages/urllib3/connectionpool.py", line 1093, in _validate_conn
    conn.connect()
  File "/home/jules/.pyenv/versions/3.12.11/lib/python3.12/site-packages/urllib3/connection.py", line 790, in connect
    sock_and_verified = _ssl_wrap_socket_and_match_hostname(
                        ^^^^^^^^^^^^^^^^^^^^^^^^^^^^^^^^^^^^
  File "/home/jules/.pyenv/versions/3.12.11/lib/python3.12/site-packages/urllib3/connection.py", line 969, in _ssl_wrap_socket_and_match_hostname
    ssl_sock = ssl_wrap_socket(
               ^^^^^^^^^^^^^^^^
  File "/home/jules/.pyenv/versions/3.12.11/lib/python3.12/site-packages/urllib3/util/ssl_.py", line 480, in ssl_wrap_socket
    ssl_sock = _ssl_wrap_socket_impl(sock, context, tls_in_tls, server_hostname)
               ^^^^^^^^^^^^^^^^^^^^^^^^^^^^^^^^^^^^^^^^^^^^^^^^^^^^^^^^^^^^^^^^^
  File "/home/jules/.pyenv/versions/3.12.11/lib/python3.12/site-packages/urllib3/util/ssl_.py", line 524, in _ssl_wrap_socket_impl
    return ssl_context.wrap_socket(sock, server_hostname=server_hostname)
           ^^^^^^^^^^^^^^^^^^^^^^^^^^^^^^^^^^^^^^^^^^^^^^^^^^^^^^^^^^^^^^
  File "/home/jules/.pyenv/versions/3.12.11/lib/python3.12/ssl.py", line 455, in wrap_socket
    return self.sslsocket_class._create(
           ^^^^^^^^^^^^^^^^^^^^^^^^^^^^^
  File "/home/jules/.pyenv/versions/3.12.11/lib/python3.12/ssl.py", line 1041, in _create
    self.do_handshake()
  File "/home/jules/.pyenv/versions/3.12.11/lib/python3.12/ssl.py", line 1319, in do_handshake
    self._sslobj.do_handshake()
ssl.SSLCertVerificationError: [SSL: CERTIFICATE_VERIFY_FAILED] certificate verify failed: self-signed certificate in certificate chain (_ssl.c:1010)

During handling of the above exception, another exception occurred:

Traceback (most recent call last):
  File "/home/jules/.pyenv/versions/3.12.11/lib/python3.12/site-packages/urllib3/connectionpool.py", line 787, in urlopen
    response = self._make_request(
               ^^^^^^^^^^^^^^^^^^^
  File "/home/jules/.pyenv/versions/3.12.11/lib/python3.12/site-packages/urllib3/connectionpool.py", line 488, in _make_request
    raise new_e
urllib3.exceptions.SSLError: [SSL: CERTIFICATE_VERIFY_FAILED] certificate verify failed: self-signed certificate in certificate chain (_ssl.c:1010)

The above exception was the direct cause of the following exception:

Traceback (most recent call last):
  File "/home/jules/.pyenv/versions/3.12.11/lib/python3.12/site-packages/requests/adapters.py", line 667, in send
    resp = conn.urlopen(
           ^^^^^^^^^^^^^
  File "/home/jules/.pyenv/versions/3.12.11/lib/python3.12/site-packages/urllib3/connectionpool.py", line 841, in urlopen
    retries = retries.increment(
              ^^^^^^^^^^^^^^^^^^
  File "/home/jules/.pyenv/versions/3.12.11/lib/python3.12/site-packages/urllib3/util/retry.py", line 519, in increment
    raise MaxRetryError(_pool, url, reason) from reason  # type: ignore[arg-type]
    ^^^^^^^^^^^^^^^^^^^^^^^^^^^^^^^^^^^^^^^^^^^^^^^^^^^
urllib3.exceptions.MaxRetryError: HTTPSConnectionPool(host='oapi.koreaexim.go.kr', port=443): Max retries exceeded with url: /site/program/financial/exchangeJSON?authkey=YOUR_EXIM_API_KEY_HERE&searchdate=20250818&data=AP01 (Caused by SSLError(SSLCertVerificationError(1, '[SSL: CERTIFICATE_VERIFY_FAILED] certificate verify failed: self-signed certificate in certificate chain (_ssl.c:1010)')))

During handling of the above exception, another exception occurred:

Traceback (most recent call last):
  File "/app/utils/api_handlers/exim.py", line 33, in _fetch_exim_data
    response = await asyncio.to_thread(session.get, BASE_URL, params=params, timeout=10)
               ^^^^^^^^^^^^^^^^^^^^^^^^^^^^^^^^^^^^^^^^^^^^^^^^^^^^^^^^^^^^^^^^^^^^^^^^^
  File "/home/jules/.pyenv/versions/3.12.11/lib/python3.12/asyncio/threads.py", line 25, in to_thread
    return await loop.run_in_executor(None, func_call)
           ^^^^^^^^^^^^^^^^^^^^^^^^^^^^^^^^^^^^^^^^^^^
  File "/home/jules/.pyenv/versions/3.12.11/lib/python3.12/concurrent/futures/thread.py", line 59, in run
    result = self.fn(*self.args, **self.kwargs)
             ^^^^^^^^^^^^^^^^^^^^^^^^^^^^^^^^^^
  File "/home/jules/.pyenv/versions/3.12.11/lib/python3.12/site-packages/requests/sessions.py", line 602, in get
    return self.request("GET", url, **kwargs)
           ^^^^^^^^^^^^^^^^^^^^^^^^^^^^^^^^^^
  File "/home/jules/.pyenv/versions/3.12.11/lib/python3.12/site-packages/requests/sessions.py", line 589, in request
    resp = self.send(prep, **send_kwargs)
           ^^^^^^^^^^^^^^^^^^^^^^^^^^^^^^
  File "/home/jules/.pyenv/versions/3.12.11/lib/python3.12/site-packages/requests/sessions.py", line 703, in send
    r = adapter.send(request, **kwargs)
        ^^^^^^^^^^^^^^^^^^^^^^^^^^^^^^^
  File "/home/jules/.pyenv/versions/3.12.11/lib/python3.12/site-packages/requests/adapters.py", line 698, in send
    raise SSLError(e, request=request)
requests.exceptions.SSLError: HTTPSConnectionPool(host='oapi.koreaexim.go.kr', port=443): Max retries exceeded with url: /site/program/financial/exchangeJSON?authkey=YOUR_EXIM_API_KEY_HERE&searchdate=20250818&data=AP01 (Caused by SSLError(SSLCertVerificationError(1, '[SSL: CERTIFICATE_VERIFY_FAILED] certificate verify failed: self-signed certificate in certificate chain (_ssl.c:1010)')))
2025-08-18 20:39:17 [INFO] [root] 수출입은행 API 요청: URL='https://oapi.koreaexim.go.kr/site/program/financial/exchangeJSON', Params='{'authkey': '[REDACTED]', 'searchdate': '20250818', 'data': 'AP01'}'
2025-08-18 20:39:17 [ERROR] [root] 수출입은행 API(AP01) 요청 중 오류: HTTPSConnectionPool(host='oapi.koreaexim.go.kr', port=443): Max retries exceeded with url: /site/program/financial/exchangeJSON?authkey=YOUR_EXIM_API_KEY_HERE&searchdate=20250818&data=AP01 (Caused by SSLError(SSLCertVerificationError(1, '[SSL: CERTIFICATE_VERIFY_FAILED] certificate verify failed: self-signed certificate in certificate chain (_ssl.c:1010)')))
Traceback (most recent call last):
  File "/home/jules/.pyenv/versions/3.12.11/lib/python3.12/site-packages/urllib3/connectionpool.py", line 464, in _make_request
    self._validate_conn(conn)
  File "/home/jules/.pyenv/versions/3.12.11/lib/python3.12/site-packages/urllib3/connectionpool.py", line 1093, in _validate_conn
    conn.connect()
  File "/home/jules/.pyenv/versions/3.12.11/lib/python3.12/site-packages/urllib3/connection.py", line 790, in connect
    sock_and_verified = _ssl_wrap_socket_and_match_hostname(
                        ^^^^^^^^^^^^^^^^^^^^^^^^^^^^^^^^^^^^
  File "/home/jules/.pyenv/versions/3.12.11/lib/python3.12/site-packages/urllib3/connection.py", line 969, in _ssl_wrap_socket_and_match_hostname
    ssl_sock = ssl_wrap_socket(
               ^^^^^^^^^^^^^^^^
  File "/home/jules/.pyenv/versions/3.12.11/lib/python3.12/site-packages/urllib3/util/ssl_.py", line 480, in ssl_wrap_socket
    ssl_sock = _ssl_wrap_socket_impl(sock, context, tls_in_tls, server_hostname)
               ^^^^^^^^^^^^^^^^^^^^^^^^^^^^^^^^^^^^^^^^^^^^^^^^^^^^^^^^^^^^^^^^^
  File "/home/jules/.pyenv/versions/3.12.11/lib/python3.12/site-packages/urllib3/util/ssl_.py", line 524, in _ssl_wrap_socket_impl
    return ssl_context.wrap_socket(sock, server_hostname=server_hostname)
           ^^^^^^^^^^^^^^^^^^^^^^^^^^^^^^^^^^^^^^^^^^^^^^^^^^^^^^^^^^^^^^
  File "/home/jules/.pyenv/versions/3.12.11/lib/python3.12/ssl.py", line 455, in wrap_socket
    return self.sslsocket_class._create(
           ^^^^^^^^^^^^^^^^^^^^^^^^^^^^^
  File "/home/jules/.pyenv/versions/3.12.11/lib/python3.12/ssl.py", line 1041, in _create
    self.do_handshake()
  File "/home/jules/.pyenv/versions/3.12.11/lib/python3.12/ssl.py", line 1319, in do_handshake
    self._sslobj.do_handshake()
ssl.SSLCertVerificationError: [SSL: CERTIFICATE_VERIFY_FAILED] certificate verify failed: self-signed certificate in certificate chain (_ssl.c:1010)

During handling of the above exception, another exception occurred:

Traceback (most recent call last):
  File "/home/jules/.pyenv/versions/3.12.11/lib/python3.12/site-packages/urllib3/connectionpool.py", line 787, in urlopen
    response = self._make_request(
               ^^^^^^^^^^^^^^^^^^^
  File "/home/jules/.pyenv/versions/3.12.11/lib/python3.12/site-packages/urllib3/connectionpool.py", line 488, in _make_request
    raise new_e
urllib3.exceptions.SSLError: [SSL: CERTIFICATE_VERIFY_FAILED] certificate verify failed: self-signed certificate in certificate chain (_ssl.c:1010)

The above exception was the direct cause of the following exception:

Traceback (most recent call last):
  File "/home/jules/.pyenv/versions/3.12.11/lib/python3.12/site-packages/requests/adapters.py", line 667, in send
    resp = conn.urlopen(
           ^^^^^^^^^^^^^
  File "/home/jules/.pyenv/versions/3.12.11/lib/python3.12/site-packages/urllib3/connectionpool.py", line 841, in urlopen
    retries = retries.increment(
              ^^^^^^^^^^^^^^^^^^
  File "/home/jules/.pyenv/versions/3.12.11/lib/python3.12/site-packages/urllib3/util/retry.py", line 519, in increment
    raise MaxRetryError(_pool, url, reason) from reason  # type: ignore[arg-type]
    ^^^^^^^^^^^^^^^^^^^^^^^^^^^^^^^^^^^^^^^^^^^^^^^^^^^
urllib3.exceptions.MaxRetryError: HTTPSConnectionPool(host='oapi.koreaexim.go.kr', port=443): Max retries exceeded with url: /site/program/financial/exchangeJSON?authkey=YOUR_EXIM_API_KEY_HERE&searchdate=20250818&data=AP01 (Caused by SSLError(SSLCertVerificationError(1, '[SSL: CERTIFICATE_VERIFY_FAILED] certificate verify failed: self-signed certificate in certificate chain (_ssl.c:1010)')))

During handling of the above exception, another exception occurred:

Traceback (most recent call last):
  File "/app/utils/api_handlers/exim.py", line 33, in _fetch_exim_data
    response = await asyncio.to_thread(session.get, BASE_URL, params=params, timeout=10)
               ^^^^^^^^^^^^^^^^^^^^^^^^^^^^^^^^^^^^^^^^^^^^^^^^^^^^^^^^^^^^^^^^^^^^^^^^^
  File "/home/jules/.pyenv/versions/3.12.11/lib/python3.12/asyncio/threads.py", line 25, in to_thread
    return await loop.run_in_executor(None, func_call)
           ^^^^^^^^^^^^^^^^^^^^^^^^^^^^^^^^^^^^^^^^^^^
  File "/home/jules/.pyenv/versions/3.12.11/lib/python3.12/concurrent/futures/thread.py", line 59, in run
    result = self.fn(*self.args, **self.kwargs)
             ^^^^^^^^^^^^^^^^^^^^^^^^^^^^^^^^^^
  File "/home/jules/.pyenv/versions/3.12.11/lib/python3.12/site-packages/requests/sessions.py", line 602, in get
    return self.request("GET", url, **kwargs)
           ^^^^^^^^^^^^^^^^^^^^^^^^^^^^^^^^^^
  File "/home/jules/.pyenv/versions/3.12.11/lib/python3.12/site-packages/requests/sessions.py", line 589, in request
    resp = self.send(prep, **send_kwargs)
           ^^^^^^^^^^^^^^^^^^^^^^^^^^^^^^
  File "/home/jules/.pyenv/versions/3.12.11/lib/python3.12/site-packages/requests/sessions.py", line 703, in send
    r = adapter.send(request, **kwargs)
        ^^^^^^^^^^^^^^^^^^^^^^^^^^^^^^^
  File "/home/jules/.pyenv/versions/3.12.11/lib/python3.12/site-packages/requests/adapters.py", line 698, in send
    raise SSLError(e, request=request)
requests.exceptions.SSLError: HTTPSConnectionPool(host='oapi.koreaexim.go.kr', port=443): Max retries exceeded with url: /site/program/financial/exchangeJSON?authkey=YOUR_EXIM_API_KEY_HERE&searchdate=20250818&data=AP01 (Caused by SSLError(SSLCertVerificationError(1, '[SSL: CERTIFICATE_VERIFY_FAILED] certificate verify failed: self-signed certificate in certificate chain (_ssl.c:1010)')))
2025-08-18 20:39:17 [INFO] [root] 수출입은행 API 요청: URL='https://oapi.koreaexim.go.kr/site/program/financial/exchangeJSON', Params='{'authkey': '[REDACTED]', 'searchdate': '20250818', 'data': 'AP01'}'
2025-08-18 20:39:17 [ERROR] [root] 수출입은행 API(AP01) 요청 중 오류: HTTPSConnectionPool(host='oapi.koreaexim.go.kr', port=443): Max retries exceeded with url: /site/program/financial/exchangeJSON?authkey=YOUR_EXIM_API_KEY_HERE&searchdate=20250818&data=AP01 (Caused by SSLError(SSLCertVerificationError(1, '[SSL: CERTIFICATE_VERIFY_FAILED] certificate verify failed: self-signed certificate in certificate chain (_ssl.c:1010)')))
Traceback (most recent call last):
  File "/home/jules/.pyenv/versions/3.12.11/lib/python3.12/site-packages/urllib3/connectionpool.py", line 464, in _make_request
    self._validate_conn(conn)
  File "/home/jules/.pyenv/versions/3.12.11/lib/python3.12/site-packages/urllib3/connectionpool.py", line 1093, in _validate_conn
    conn.connect()
  File "/home/jules/.pyenv/versions/3.12.11/lib/python3.12/site-packages/urllib3/connection.py", line 790, in connect
    sock_and_verified = _ssl_wrap_socket_and_match_hostname(
                        ^^^^^^^^^^^^^^^^^^^^^^^^^^^^^^^^^^^^
  File "/home/jules/.pyenv/versions/3.12.11/lib/python3.12/site-packages/urllib3/connection.py", line 969, in _ssl_wrap_socket_and_match_hostname
    ssl_sock = ssl_wrap_socket(
               ^^^^^^^^^^^^^^^^
  File "/home/jules/.pyenv/versions/3.12.11/lib/python3.12/site-packages/urllib3/util/ssl_.py", line 480, in ssl_wrap_socket
    ssl_sock = _ssl_wrap_socket_impl(sock, context, tls_in_tls, server_hostname)
               ^^^^^^^^^^^^^^^^^^^^^^^^^^^^^^^^^^^^^^^^^^^^^^^^^^^^^^^^^^^^^^^^^
  File "/home/jules/.pyenv/versions/3.12.11/lib/python3.12/site-packages/urllib3/util/ssl_.py", line 524, in _ssl_wrap_socket_impl
    return ssl_context.wrap_socket(sock, server_hostname=server_hostname)
           ^^^^^^^^^^^^^^^^^^^^^^^^^^^^^^^^^^^^^^^^^^^^^^^^^^^^^^^^^^^^^^
  File "/home/jules/.pyenv/versions/3.12.11/lib/python3.12/ssl.py", line 455, in wrap_socket
    return self.sslsocket_class._create(
           ^^^^^^^^^^^^^^^^^^^^^^^^^^^^^
  File "/home/jules/.pyenv/versions/3.12.11/lib/python3.12/ssl.py", line 1041, in _create
    self.do_handshake()
  File "/home/jules/.pyenv/versions/3.12.11/lib/python3.12/ssl.py", line 1319, in do_handshake
    self._sslobj.do_handshake()
ssl.SSLCertVerificationError: [SSL: CERTIFICATE_VERIFY_FAILED] certificate verify failed: self-signed certificate in certificate chain (_ssl.c:1010)

During handling of the above exception, another exception occurred:

Traceback (most recent call last):
  File "/home/jules/.pyenv/versions/3.12.11/lib/python3.12/site-packages/urllib3/connectionpool.py", line 787, in urlopen
    response = self._make_request(
               ^^^^^^^^^^^^^^^^^^^
  File "/home/jules/.pyenv/versions/3.12.11/lib/python3.12/site-packages/urllib3/connectionpool.py", line 488, in _make_request
    raise new_e
urllib3.exceptions.SSLError: [SSL: CERTIFICATE_VERIFY_FAILED] certificate verify failed: self-signed certificate in certificate chain (_ssl.c:1010)

The above exception was the direct cause of the following exception:

Traceback (most recent call last):
  File "/home/jules/.pyenv/versions/3.12.11/lib/python3.12/site-packages/requests/adapters.py", line 667, in send
    resp = conn.urlopen(
           ^^^^^^^^^^^^^
  File "/home/jules/.pyenv/versions/3.12.11/lib/python3.12/site-packages/urllib3/connectionpool.py", line 841, in urlopen
    retries = retries.increment(
              ^^^^^^^^^^^^^^^^^^
  File "/home/jules/.pyenv/versions/3.12.11/lib/python3.12/site-packages/urllib3/util/retry.py", line 519, in increment
    raise MaxRetryError(_pool, url, reason) from reason  # type: ignore[arg-type]
    ^^^^^^^^^^^^^^^^^^^^^^^^^^^^^^^^^^^^^^^^^^^^^^^^^^^
urllib3.exceptions.MaxRetryError: HTTPSConnectionPool(host='oapi.koreaexim.go.kr', port=443): Max retries exceeded with url: /site/program/financial/exchangeJSON?authkey=YOUR_EXIM_API_KEY_HERE&searchdate=20250818&data=AP01 (Caused by SSLError(SSLCertVerificationError(1, '[SSL: CERTIFICATE_VERIFY_FAILED] certificate verify failed: self-signed certificate in certificate chain (_ssl.c:1010)')))

During handling of the above exception, another exception occurred:

Traceback (most recent call last):
  File "/app/utils/api_handlers/exim.py", line 33, in _fetch_exim_data
    response = await asyncio.to_thread(session.get, BASE_URL, params=params, timeout=10)
               ^^^^^^^^^^^^^^^^^^^^^^^^^^^^^^^^^^^^^^^^^^^^^^^^^^^^^^^^^^^^^^^^^^^^^^^^^
  File "/home/jules/.pyenv/versions/3.12.11/lib/python3.12/asyncio/threads.py", line 25, in to_thread
    return await loop.run_in_executor(None, func_call)
           ^^^^^^^^^^^^^^^^^^^^^^^^^^^^^^^^^^^^^^^^^^^
  File "/home/jules/.pyenv/versions/3.12.11/lib/python3.12/concurrent/futures/thread.py", line 59, in run
    result = self.fn(*self.args, **self.kwargs)
             ^^^^^^^^^^^^^^^^^^^^^^^^^^^^^^^^^^
  File "/home/jules/.pyenv/versions/3.12.11/lib/python3.12/site-packages/requests/sessions.py", line 602, in get
    return self.request("GET", url, **kwargs)
           ^^^^^^^^^^^^^^^^^^^^^^^^^^^^^^^^^^
  File "/home/jules/.pyenv/versions/3.12.11/lib/python3.12/site-packages/requests/sessions.py", line 589, in request
    resp = self.send(prep, **send_kwargs)
           ^^^^^^^^^^^^^^^^^^^^^^^^^^^^^^
  File "/home/jules/.pyenv/versions/3.12.11/lib/python3.12/site-packages/requests/sessions.py", line 703, in send
    r = adapter.send(request, **kwargs)
        ^^^^^^^^^^^^^^^^^^^^^^^^^^^^^^^
  File "/home/jules/.pyenv/versions/3.12.11/lib/python3.12/site-packages/requests/adapters.py", line 698, in send
    raise SSLError(e, request=request)
requests.exceptions.SSLError: HTTPSConnectionPool(host='oapi.koreaexim.go.kr', port=443): Max retries exceeded with url: /site/program/financial/exchangeJSON?authkey=YOUR_EXIM_API_KEY_HERE&searchdate=20250818&data=AP01 (Caused by SSLError(SSLCertVerificationError(1, '[SSL: CERTIFICATE_VERIFY_FAILED] certificate verify failed: self-signed certificate in certificate chain (_ssl.c:1010)')))
2025-08-18 20:39:56 [INFO] [root] 수출입은행 API 요청: URL='https://oapi.koreaexim.go.kr/site/program/financial/exchangeJSON', Params='{'authkey': '[REDACTED]', 'searchdate': '20250818', 'data': 'AP01'}'
2025-08-18 20:39:57 [INFO] [root] 수출입은행 API 요청: URL='https://oapi.koreaexim.go.kr/site/program/financial/exchangeJSON', Params='{'authkey': '[REDACTED]', 'searchdate': '20250818', 'data': 'AP01'}'
2025-08-18 20:47:53 [INFO] [root] 수출입은행 API 요청: URL='https://oapi.koreaexim.go.kr/site/program/financial/exchangeJSON', Params='{'authkey': '[REDACTED]', 'searchdate': '20250818', 'data': 'AP01'}'
2025-08-18 20:48:53 [INFO] [root] 수출입은행 API 요청: URL='https://oapi.koreaexim.go.kr/site/program/financial/exchangeJSON', Params='{'authkey': '[REDACTED]', 'searchdate': '20250818', 'data': 'AP01'}'
2025-08-18 20:48:54 [ERROR] [root] 수출입은행 API(AP01) 처리 중 오류: HTTPSConnectionPool(host='oapi.koreaexim.go.kr', port=443): Max retries exceeded with url: /site/program/financial/exchangeJSON?authkey=YOUR_EXIM_API_KEY_HERE&searchdate=20250818&data=AP01 (Caused by SSLError(SSLCertVerificationError(1, '[SSL: CERTIFICATE_VERIFY_FAILED] certificate verify failed: self-signed certificate in certificate chain (_ssl.c:1010)')))
Traceback (most recent call last):
  File "/home/jules/.pyenv/versions/3.12.11/lib/python3.12/site-packages/urllib3/connectionpool.py", line 464, in _make_request
    self._validate_conn(conn)
  File "/home/jules/.pyenv/versions/3.12.11/lib/python3.12/site-packages/urllib3/connectionpool.py", line 1093, in _validate_conn
    conn.connect()
  File "/home/jules/.pyenv/versions/3.12.11/lib/python3.12/site-packages/urllib3/connection.py", line 790, in connect
    sock_and_verified = _ssl_wrap_socket_and_match_hostname(
                        ^^^^^^^^^^^^^^^^^^^^^^^^^^^^^^^^^^^^
  File "/home/jules/.pyenv/versions/3.12.11/lib/python3.12/site-packages/urllib3/connection.py", line 969, in _ssl_wrap_socket_and_match_hostname
    ssl_sock = ssl_wrap_socket(
               ^^^^^^^^^^^^^^^^
  File "/home/jules/.pyenv/versions/3.12.11/lib/python3.12/site-packages/urllib3/util/ssl_.py", line 480, in ssl_wrap_socket
    ssl_sock = _ssl_wrap_socket_impl(sock, context, tls_in_tls, server_hostname)
               ^^^^^^^^^^^^^^^^^^^^^^^^^^^^^^^^^^^^^^^^^^^^^^^^^^^^^^^^^^^^^^^^^
  File "/home/jules/.pyenv/versions/3.12.11/lib/python3.12/site-packages/urllib3/util/ssl_.py", line 524, in _ssl_wrap_socket_impl
    return ssl_context.wrap_socket(sock, server_hostname=server_hostname)
           ^^^^^^^^^^^^^^^^^^^^^^^^^^^^^^^^^^^^^^^^^^^^^^^^^^^^^^^^^^^^^^
  File "/home/jules/.pyenv/versions/3.12.11/lib/python3.12/ssl.py", line 455, in wrap_socket
    return self.sslsocket_class._create(
           ^^^^^^^^^^^^^^^^^^^^^^^^^^^^^
  File "/home/jules/.pyenv/versions/3.12.11/lib/python3.12/ssl.py", line 1041, in _create
    self.do_handshake()
  File "/home/jules/.pyenv/versions/3.12.11/lib/python3.12/ssl.py", line 1319, in do_handshake
    self._sslobj.do_handshake()
ssl.SSLCertVerificationError: [SSL: CERTIFICATE_VERIFY_FAILED] certificate verify failed: self-signed certificate in certificate chain (_ssl.c:1010)

During handling of the above exception, another exception occurred:

Traceback (most recent call last):
  File "/home/jules/.pyenv/versions/3.12.11/lib/python3.12/site-packages/urllib3/connectionpool.py", line 787, in urlopen
    response = self._make_request(
               ^^^^^^^^^^^^^^^^^^^
  File "/home/jules/.pyenv/versions/3.12.11/lib/python3.12/site-packages/urllib3/connectionpool.py", line 488, in _make_request
    raise new_e
urllib3.exceptions.SSLError: [SSL: CERTIFICATE_VERIFY_FAILED] certificate verify failed: self-signed certificate in certificate chain (_ssl.c:1010)

The above exception was the direct cause of the following exception:

Traceback (most recent call last):
  File "/home/jules/.pyenv/versions/3.12.11/lib/python3.12/site-packages/requests/adapters.py", line 667, in send
    resp = conn.urlopen(
           ^^^^^^^^^^^^^
  File "/home/jules/.pyenv/versions/3.12.11/lib/python3.12/site-packages/urllib3/connectionpool.py", line 841, in urlopen
    retries = retries.increment(
              ^^^^^^^^^^^^^^^^^^
  File "/home/jules/.pyenv/versions/3.12.11/lib/python3.12/site-packages/urllib3/util/retry.py", line 519, in increment
    raise MaxRetryError(_pool, url, reason) from reason  # type: ignore[arg-type]
    ^^^^^^^^^^^^^^^^^^^^^^^^^^^^^^^^^^^^^^^^^^^^^^^^^^^
urllib3.exceptions.MaxRetryError: HTTPSConnectionPool(host='oapi.koreaexim.go.kr', port=443): Max retries exceeded with url: /site/program/financial/exchangeJSON?authkey=YOUR_EXIM_API_KEY_HERE&searchdate=20250818&data=AP01 (Caused by SSLError(SSLCertVerificationError(1, '[SSL: CERTIFICATE_VERIFY_FAILED] certificate verify failed: self-signed certificate in certificate chain (_ssl.c:1010)')))

During handling of the above exception, another exception occurred:

Traceback (most recent call last):
  File "/app/utils/api_handlers/exim.py", line 32, in _fetch_exim_data
    response = await asyncio.to_thread(session.get, BASE_URL, params=params, timeout=10)
               ^^^^^^^^^^^^^^^^^^^^^^^^^^^^^^^^^^^^^^^^^^^^^^^^^^^^^^^^^^^^^^^^^^^^^^^^^
  File "/home/jules/.pyenv/versions/3.12.11/lib/python3.12/asyncio/threads.py", line 25, in to_thread
    return await loop.run_in_executor(None, func_call)
           ^^^^^^^^^^^^^^^^^^^^^^^^^^^^^^^^^^^^^^^^^^^
  File "/home/jules/.pyenv/versions/3.12.11/lib/python3.12/concurrent/futures/thread.py", line 59, in run
    result = self.fn(*self.args, **self.kwargs)
             ^^^^^^^^^^^^^^^^^^^^^^^^^^^^^^^^^^
  File "/home/jules/.pyenv/versions/3.12.11/lib/python3.12/site-packages/requests/sessions.py", line 602, in get
    return self.request("GET", url, **kwargs)
           ^^^^^^^^^^^^^^^^^^^^^^^^^^^^^^^^^^
  File "/home/jules/.pyenv/versions/3.12.11/lib/python3.12/site-packages/requests/sessions.py", line 589, in request
    resp = self.send(prep, **send_kwargs)
           ^^^^^^^^^^^^^^^^^^^^^^^^^^^^^^
  File "/home/jules/.pyenv/versions/3.12.11/lib/python3.12/site-packages/requests/sessions.py", line 703, in send
    r = adapter.send(request, **kwargs)
        ^^^^^^^^^^^^^^^^^^^^^^^^^^^^^^^
  File "/home/jules/.pyenv/versions/3.12.11/lib/python3.12/site-packages/requests/adapters.py", line 698, in send
    raise SSLError(e, request=request)
requests.exceptions.SSLError: HTTPSConnectionPool(host='oapi.koreaexim.go.kr', port=443): Max retries exceeded with url: /site/program/financial/exchangeJSON?authkey=YOUR_EXIM_API_KEY_HERE&searchdate=20250818&data=AP01 (Caused by SSLError(SSLCertVerificationError(1, '[SSL: CERTIFICATE_VERIFY_FAILED] certificate verify failed: self-signed certificate in certificate chain (_ssl.c:1010)')))
2025-08-18 20:48:54 [INFO] [root] 수출입은행 API 요청: URL='https://oapi.koreaexim.go.kr/site/program/financial/exchangeJSON', Params='{'authkey': '[REDACTED]', 'searchdate': '20250818', 'data': 'AP01'}'
2025-08-18 20:48:54 [ERROR] [root] 수출입은행 API(AP01) 처리 중 오류: HTTPSConnectionPool(host='oapi.koreaexim.go.kr', port=443): Max retries exceeded with url: /site/program/financial/exchangeJSON?authkey=YOUR_EXIM_API_KEY_HERE&searchdate=20250818&data=AP01 (Caused by SSLError(SSLCertVerificationError(1, '[SSL: CERTIFICATE_VERIFY_FAILED] certificate verify failed: self-signed certificate in certificate chain (_ssl.c:1010)')))
Traceback (most recent call last):
  File "/home/jules/.pyenv/versions/3.12.11/lib/python3.12/site-packages/urllib3/connectionpool.py", line 464, in _make_request
    self._validate_conn(conn)
  File "/home/jules/.pyenv/versions/3.12.11/lib/python3.12/site-packages/urllib3/connectionpool.py", line 1093, in _validate_conn
    conn.connect()
  File "/home/jules/.pyenv/versions/3.12.11/lib/python3.12/site-packages/urllib3/connection.py", line 790, in connect
    sock_and_verified = _ssl_wrap_socket_and_match_hostname(
                        ^^^^^^^^^^^^^^^^^^^^^^^^^^^^^^^^^^^^
  File "/home/jules/.pyenv/versions/3.12.11/lib/python3.12/site-packages/urllib3/connection.py", line 969, in _ssl_wrap_socket_and_match_hostname
    ssl_sock = ssl_wrap_socket(
               ^^^^^^^^^^^^^^^^
  File "/home/jules/.pyenv/versions/3.12.11/lib/python3.12/site-packages/urllib3/util/ssl_.py", line 480, in ssl_wrap_socket
    ssl_sock = _ssl_wrap_socket_impl(sock, context, tls_in_tls, server_hostname)
               ^^^^^^^^^^^^^^^^^^^^^^^^^^^^^^^^^^^^^^^^^^^^^^^^^^^^^^^^^^^^^^^^^
  File "/home/jules/.pyenv/versions/3.12.11/lib/python3.12/site-packages/urllib3/util/ssl_.py", line 524, in _ssl_wrap_socket_impl
    return ssl_context.wrap_socket(sock, server_hostname=server_hostname)
           ^^^^^^^^^^^^^^^^^^^^^^^^^^^^^^^^^^^^^^^^^^^^^^^^^^^^^^^^^^^^^^
  File "/home/jules/.pyenv/versions/3.12.11/lib/python3.12/ssl.py", line 455, in wrap_socket
    return self.sslsocket_class._create(
           ^^^^^^^^^^^^^^^^^^^^^^^^^^^^^
  File "/home/jules/.pyenv/versions/3.12.11/lib/python3.12/ssl.py", line 1041, in _create
    self.do_handshake()
  File "/home/jules/.pyenv/versions/3.12.11/lib/python3.12/ssl.py", line 1319, in do_handshake
    self._sslobj.do_handshake()
ssl.SSLCertVerificationError: [SSL: CERTIFICATE_VERIFY_FAILED] certificate verify failed: self-signed certificate in certificate chain (_ssl.c:1010)

During handling of the above exception, another exception occurred:

Traceback (most recent call last):
  File "/home/jules/.pyenv/versions/3.12.11/lib/python3.12/site-packages/urllib3/connectionpool.py", line 787, in urlopen
    response = self._make_request(
               ^^^^^^^^^^^^^^^^^^^
  File "/home/jules/.pyenv/versions/3.12.11/lib/python3.12/site-packages/urllib3/connectionpool.py", line 488, in _make_request
    raise new_e
urllib3.exceptions.SSLError: [SSL: CERTIFICATE_VERIFY_FAILED] certificate verify failed: self-signed certificate in certificate chain (_ssl.c:1010)

The above exception was the direct cause of the following exception:

Traceback (most recent call last):
  File "/home/jules/.pyenv/versions/3.12.11/lib/python3.12/site-packages/requests/adapters.py", line 667, in send
    resp = conn.urlopen(
           ^^^^^^^^^^^^^
  File "/home/jules/.pyenv/versions/3.12.11/lib/python3.12/site-packages/urllib3/connectionpool.py", line 841, in urlopen
    retries = retries.increment(
              ^^^^^^^^^^^^^^^^^^
  File "/home/jules/.pyenv/versions/3.12.11/lib/python3.12/site-packages/urllib3/util/retry.py", line 519, in increment
    raise MaxRetryError(_pool, url, reason) from reason  # type: ignore[arg-type]
    ^^^^^^^^^^^^^^^^^^^^^^^^^^^^^^^^^^^^^^^^^^^^^^^^^^^
urllib3.exceptions.MaxRetryError: HTTPSConnectionPool(host='oapi.koreaexim.go.kr', port=443): Max retries exceeded with url: /site/program/financial/exchangeJSON?authkey=YOUR_EXIM_API_KEY_HERE&searchdate=20250818&data=AP01 (Caused by SSLError(SSLCertVerificationError(1, '[SSL: CERTIFICATE_VERIFY_FAILED] certificate verify failed: self-signed certificate in certificate chain (_ssl.c:1010)')))

During handling of the above exception, another exception occurred:

Traceback (most recent call last):
  File "/app/utils/api_handlers/exim.py", line 32, in _fetch_exim_data
    response = await asyncio.to_thread(session.get, BASE_URL, params=params, timeout=10)
               ^^^^^^^^^^^^^^^^^^^^^^^^^^^^^^^^^^^^^^^^^^^^^^^^^^^^^^^^^^^^^^^^^^^^^^^^^
  File "/home/jules/.pyenv/versions/3.12.11/lib/python3.12/asyncio/threads.py", line 25, in to_thread
    return await loop.run_in_executor(None, func_call)
           ^^^^^^^^^^^^^^^^^^^^^^^^^^^^^^^^^^^^^^^^^^^
  File "/home/jules/.pyenv/versions/3.12.11/lib/python3.12/concurrent/futures/thread.py", line 59, in run
    result = self.fn(*self.args, **self.kwargs)
             ^^^^^^^^^^^^^^^^^^^^^^^^^^^^^^^^^^
  File "/home/jules/.pyenv/versions/3.12.11/lib/python3.12/site-packages/requests/sessions.py", line 602, in get
    return self.request("GET", url, **kwargs)
           ^^^^^^^^^^^^^^^^^^^^^^^^^^^^^^^^^^
  File "/home/jules/.pyenv/versions/3.12.11/lib/python3.12/site-packages/requests/sessions.py", line 589, in request
    resp = self.send(prep, **send_kwargs)
           ^^^^^^^^^^^^^^^^^^^^^^^^^^^^^^
  File "/home/jules/.pyenv/versions/3.12.11/lib/python3.12/site-packages/requests/sessions.py", line 703, in send
    r = adapter.send(request, **kwargs)
        ^^^^^^^^^^^^^^^^^^^^^^^^^^^^^^^
  File "/home/jules/.pyenv/versions/3.12.11/lib/python3.12/site-packages/requests/adapters.py", line 698, in send
    raise SSLError(e, request=request)
requests.exceptions.SSLError: HTTPSConnectionPool(host='oapi.koreaexim.go.kr', port=443): Max retries exceeded with url: /site/program/financial/exchangeJSON?authkey=YOUR_EXIM_API_KEY_HERE&searchdate=20250818&data=AP01 (Caused by SSLError(SSLCertVerificationError(1, '[SSL: CERTIFICATE_VERIFY_FAILED] certificate verify failed: self-signed certificate in certificate chain (_ssl.c:1010)')))
2025-08-18 20:49:36 [INFO] [root] 수출입은행 API 요청: URL='https://oapi.koreaexim.go.kr/site/program/financial/exchangeJSON', Params='{'authkey': '[REDACTED]', 'searchdate': '20250818', 'data': 'AP01'}'
2025-08-18 20:49:37 [WARNING] [root] 수출입은행 환율 API 응답에서 'USD' 통화를 찾지 못했습니다.
2025-08-18 20:49:37 [INFO] [root] 수출입은행 API 요청: URL='https://oapi.koreaexim.go.kr/site/program/financial/exchangeJSON', Params='{'authkey': '[REDACTED]', 'searchdate': '20250818', 'data': 'AP01'}'
2025-08-18 20:49:38 [WARNING] [root] 수출입은행 환율 API 응답에서 'JPY' 통화를 찾지 못했습니다.
{"timestamp": "2025-08-18T21:24:36.819337+09:00", "level": "WARNING", "name": "root", "message": "수출입은행 환율 API 응답에서 'EUR' 통화를 찾지 못했습니다."}
{"timestamp": "2025-08-18T21:39:51.293614+09:00", "level": "WARNING", "name": "root", "message": "수출입은행 환율 API 응답에서 'EUR' 통화를 찾지 못했습니다."}
{"timestamp": "2025-08-18T21:39:51.300972+09:00", "level": "INFO", "name": "root", "message": "Geocoding cache MISS for query: 'Eiffel Tower'"}
{"timestamp": "2025-08-18T21:39:52.415088+09:00", "level": "INFO", "name": "root", "message": "Geocoding cache MISS for query: 'Springfield'"}
{"timestamp": "2025-08-18T21:39:53.523986+09:00", "level": "INFO", "name": "root", "message": "Geocoding cache MISS for query: 'a_made_up_place_12345'"}
{"timestamp": "2025-08-18T21:39:54.632579+09:00", "level": "INFO", "name": "root", "message": "Geocoding cache MISS for query: 'Tokyo'"}
{"timestamp": "2025-08-18T21:39:55.736394+09:00", "level": "INFO", "name": "root", "message": "Geocoding cache HIT for query: 'Tokyo'"}
{"timestamp": "2025-08-18T21:51:05.067844+09:00", "level": "WARNING", "name": "root", "message": "수출입은행 환율 API 응답에서 'EUR' 통화를 찾지 못했습니다."}
{"timestamp": "2025-08-18T21:51:05.074280+09:00", "level": "ERROR", "name": "root", "message": "Foursquare API 키(FOURSQUARE_API_KEY)가 설정되지 않았습니다."}
{"timestamp": "2025-08-18T21:51:05.132391+09:00", "level": "ERROR", "name": "root", "message": "Foursquare API 키(FOURSQUARE_API_KEY)가 설정되지 않았습니다."}
{"timestamp": "2025-08-18T21:51:05.139914+09:00", "level": "INFO", "name": "root", "message": "Geocoding cache MISS for query: 'Eiffel Tower'"}
{"timestamp": "2025-08-18T21:51:06.251480+09:00", "level": "INFO", "name": "root", "message": "Geocoding cache MISS for query: 'Springfield'"}
{"timestamp": "2025-08-18T21:51:07.360992+09:00", "level": "INFO", "name": "root", "message": "Geocoding cache MISS for query: 'a_made_up_place_12345'"}
{"timestamp": "2025-08-18T21:51:08.470325+09:00", "level": "INFO", "name": "root", "message": "Geocoding cache MISS for query: 'Tokyo'"}
{"timestamp": "2025-08-18T21:51:09.573747+09:00", "level": "INFO", "name": "root", "message": "Geocoding cache HIT for query: 'Tokyo'"}
{"timestamp": "2025-08-18T21:51:09.579652+09:00", "level": "ERROR", "name": "root", "message": "OpenWeatherMap API 키(OPENWEATHERMAP_API_KEY)가 설정되지 않았습니다."}
{"timestamp": "2025-08-18T21:51:09.590047+09:00", "level": "ERROR", "name": "root", "message": "OpenWeatherMap API 키(OPENWEATHERMAP_API_KEY)가 설정되지 않았습니다."}
{"timestamp": "2025-08-18T21:51:09.598200+09:00", "level": "ERROR", "name": "root", "message": "Ticketmaster API 키(TICKETMASTER_API_KEY)가 설정되지 않았습니다."}
{"timestamp": "2025-08-18T21:51:09.605245+09:00", "level": "ERROR", "name": "root", "message": "Ticketmaster API 키(TICKETMASTER_API_KEY)가 설정되지 않았습니다."}
{"timestamp": "2025-08-18T21:53:39.902899+09:00", "level": "WARNING", "name": "root", "message": "수출입은행 환율 API 응답에서 'EUR' 통화를 찾지 못했습니다."}
{"timestamp": "2025-08-18T21:53:39.909880+09:00", "level": "INFO", "name": "root", "message": "Foursquare API 요청: URL='https://api.foursquare.com/v3/places/search', Params='{'ll': '35.68,139.69', 'limit': 10, 'sort': 'RELEVANCE'}'"}
{"timestamp": "2025-08-18T21:53:39.918326+09:00", "level": "INFO", "name": "root", "message": "Foursquare API 요청: URL='https://api.foursquare.com/v3/places/search', Params='{'ll': '35.68,139.69', 'limit': 10, 'sort': 'RELEVANCE'}'"}
{"timestamp": "2025-08-18T21:53:39.919559+09:00", "level": "ERROR", "name": "root", "message": "Foursquare API(35.68,139.69) 처리 중 예기치 않은 오류: Network Error", "exc_info": "Traceback (most recent call last):\n  File \"/app/utils/api_handlers/foursquare.py\", line 33, in get_places_by_coords\n    response = await asyncio.to_thread(session.get, url, headers=headers, params=params, timeout=15)\n               ^^^^^^^^^^^^^^^^^^^^^^^^^^^^^^^^^^^^^^^^^^^^^^^^^^^^^^^^^^^^^^^^^^^^^^^^^^^^^^^^^^^^^\n  File \"/home/jules/.pyenv/versions/3.12.11/lib/python3.12/asyncio/threads.py\", line 25, in to_thread\n    return await loop.run_in_executor(None, func_call)\n           ^^^^^^^^^^^^^^^^^^^^^^^^^^^^^^^^^^^^^^^^^^^\n  File \"/home/jules/.pyenv/versions/3.12.11/lib/python3.12/concurrent/futures/thread.py\", line 59, in run\n    result = self.fn(*self.args, **self.kwargs)\n             ^^^^^^^^^^^^^^^^^^^^^^^^^^^^^^^^^^\n  File \"/home/jules/.pyenv/versions/3.12.11/lib/python3.12/unittest/mock.py\", line 1139, in __call__\n    return self._mock_call(*args, **kwargs)\n           ^^^^^^^^^^^^^^^^^^^^^^^^^^^^^^^^\n  File \"/home/jules/.pyenv/versions/3.12.11/lib/python3.12/unittest/mock.py\", line 1143, in _mock_call\n    return self._execute_mock_call(*args, **kwargs)\n           ^^^^^^^^^^^^^^^^^^^^^^^^^^^^^^^^^^^^^^^^\n  File \"/home/jules/.pyenv/versions/3.12.11/lib/python3.12/unittest/mock.py\", line 1198, in _execute_mock_call\n    raise effect\nException: Network Error"}
{"timestamp": "2025-08-18T21:53:40.001565+09:00", "level": "INFO", "name": "root", "message": "Geocoding cache MISS for query: 'Eiffel Tower'"}
{"timestamp": "2025-08-18T21:53:41.111023+09:00", "level": "INFO", "name": "root", "message": "Geocoding cache MISS for query: 'Springfield'"}
{"timestamp": "2025-08-18T21:53:42.220951+09:00", "level": "INFO", "name": "root", "message": "Geocoding cache MISS for query: 'a_made_up_place_12345'"}
{"timestamp": "2025-08-18T21:53:43.334190+09:00", "level": "INFO", "name": "root", "message": "Geocoding cache MISS for query: 'Tokyo'"}
{"timestamp": "2025-08-18T21:53:44.439744+09:00", "level": "INFO", "name": "root", "message": "Geocoding cache HIT for query: 'Tokyo'"}
{"timestamp": "2025-08-18T21:53:44.451409+09:00", "level": "INFO", "name": "root", "message": "OpenWeatherMap API 요청: URL='https://api.openweathermap.org/data/2.5/weather', Params='{'lat': 35.68, 'lon': 139.69, 'appid': '[REDACTED]', 'units': 'metric', 'lang': 'kr'}'"}
{"timestamp": "2025-08-18T21:53:44.466134+09:00", "level": "INFO", "name": "root", "message": "OpenWeatherMap API 요청: URL='https://api.openweathermap.org/data/2.5/weather', Params='{'lat': 35.68, 'lon': 139.69, 'appid': '[REDACTED]', 'units': 'metric', 'lang': 'kr'}'"}
{"timestamp": "2025-08-18T21:53:44.467961+09:00", "level": "ERROR", "name": "root", "message": "OpenWeatherMap API(35.68,139.69) 처리 중 예기치 않은 오류: Network Error", "exc_info": "Traceback (most recent call last):\n  File \"/app/utils/api_handlers/openweathermap.py\", line 31, in get_weather_by_coords\n    response = await asyncio.to_thread(session.get, url, params=params, timeout=10)\n               ^^^^^^^^^^^^^^^^^^^^^^^^^^^^^^^^^^^^^^^^^^^^^^^^^^^^^^^^^^^^^^^^^^^^\n  File \"/home/jules/.pyenv/versions/3.12.11/lib/python3.12/asyncio/threads.py\", line 25, in to_thread\n    return await loop.run_in_executor(None, func_call)\n           ^^^^^^^^^^^^^^^^^^^^^^^^^^^^^^^^^^^^^^^^^^^\n  File \"/home/jules/.pyenv/versions/3.12.11/lib/python3.12/concurrent/futures/thread.py\", line 59, in run\n    result = self.fn(*self.args, **self.kwargs)\n             ^^^^^^^^^^^^^^^^^^^^^^^^^^^^^^^^^^\n  File \"/home/jules/.pyenv/versions/3.12.11/lib/python3.12/unittest/mock.py\", line 1139, in __call__\n    return self._mock_call(*args, **kwargs)\n           ^^^^^^^^^^^^^^^^^^^^^^^^^^^^^^^^\n  File \"/home/jules/.pyenv/versions/3.12.11/lib/python3.12/unittest/mock.py\", line 1143, in _mock_call\n    return self._execute_mock_call(*args, **kwargs)\n           ^^^^^^^^^^^^^^^^^^^^^^^^^^^^^^^^^^^^^^^^\n  File \"/home/jules/.pyenv/versions/3.12.11/lib/python3.12/unittest/mock.py\", line 1198, in _execute_mock_call\n    raise effect\nException: Network Error"}
{"timestamp": "2025-08-18T21:53:44.488492+09:00", "level": "INFO", "name": "root", "message": "Ticketmaster API 요청: URL='https://app.ticketmaster.com/discovery/v2/events.json', Params='{'apikey': 'DUMMY_API_KEY', 'latlong': '35.68,139.69', 'radius': 50, 'unit': 'km', 'startDateTime': '2025-08-18T12:53:44Z', 'endDateTime': '2025-09-17T12:53:44Z', 'sort': 'date,asc'}'"}
{"timestamp": "2025-08-18T21:53:44.497724+09:00", "level": "INFO", "name": "root", "message": "Ticketmaster API 요청: URL='https://app.ticketmaster.com/discovery/v2/events.json', Params='{'apikey': 'DUMMY_API_KEY', 'latlong': '35.68,139.69', 'radius': 50, 'unit': 'km', 'startDateTime': '2025-08-18T12:53:44Z', 'endDateTime': '2025-09-17T12:53:44Z', 'sort': 'date,asc'}'"}
{"timestamp": "2025-08-18T21:53:44.499382+09:00", "level": "ERROR", "name": "root", "message": "Ticketmaster API(35.68,139.69) 처리 중 예기치 않은 오류: Network Error", "exc_info": "Traceback (most recent call last):\n  File \"/app/utils/api_handlers/ticketmaster.py\", line 37, in get_events_by_coords\n    response = await asyncio.to_thread(session.get, url, params=params, timeout=15)\n               ^^^^^^^^^^^^^^^^^^^^^^^^^^^^^^^^^^^^^^^^^^^^^^^^^^^^^^^^^^^^^^^^^^^^\n  File \"/home/jules/.pyenv/versions/3.12.11/lib/python3.12/asyncio/threads.py\", line 25, in to_thread\n    return await loop.run_in_executor(None, func_call)\n           ^^^^^^^^^^^^^^^^^^^^^^^^^^^^^^^^^^^^^^^^^^^\n  File \"/home/jules/.pyenv/versions/3.12.11/lib/python3.12/concurrent/futures/thread.py\", line 59, in run\n    result = self.fn(*self.args, **self.kwargs)\n             ^^^^^^^^^^^^^^^^^^^^^^^^^^^^^^^^^^\n  File \"/home/jules/.pyenv/versions/3.12.11/lib/python3.12/unittest/mock.py\", line 1139, in __call__\n    return self._mock_call(*args, **kwargs)\n           ^^^^^^^^^^^^^^^^^^^^^^^^^^^^^^^^\n  File \"/home/jules/.pyenv/versions/3.12.11/lib/python3.12/unittest/mock.py\", line 1143, in _mock_call\n    return self._execute_mock_call(*args, **kwargs)\n           ^^^^^^^^^^^^^^^^^^^^^^^^^^^^^^^^^^^^^^^^\n  File \"/home/jules/.pyenv/versions/3.12.11/lib/python3.12/unittest/mock.py\", line 1198, in _execute_mock_call\n    raise effect\nException: Network Error"}
{"timestamp": "2025-08-18T21:54:59.322125+09:00", "level": "WARNING", "name": "root", "message": "수출입은행 환율 API 응답에서 'EUR' 통화를 찾지 못했습니다."}
{"timestamp": "2025-08-18T21:54:59.328963+09:00", "level": "INFO", "name": "root", "message": "Foursquare API 요청: URL='https://api.foursquare.com/v3/places/search', Params='{'ll': '35.68,139.69', 'limit': 10, 'sort': 'RELEVANCE'}'"}
{"timestamp": "2025-08-18T21:54:59.336524+09:00", "level": "INFO", "name": "root", "message": "Foursquare API 요청: URL='https://api.foursquare.com/v3/places/search', Params='{'ll': '35.68,139.69', 'limit': 10, 'sort': 'RELEVANCE'}'"}
{"timestamp": "2025-08-18T21:54:59.337739+09:00", "level": "ERROR", "name": "root", "message": "Foursquare API(35.68,139.69) 요청 중 오류: Network Error", "exc_info": "Traceback (most recent call last):\n  File \"/app/utils/api_handlers/foursquare.py\", line 33, in get_places_by_coords\n    response = await asyncio.to_thread(session.get, url, headers=headers, params=params, timeout=15)\n               ^^^^^^^^^^^^^^^^^^^^^^^^^^^^^^^^^^^^^^^^^^^^^^^^^^^^^^^^^^^^^^^^^^^^^^^^^^^^^^^^^^^^^\n  File \"/home/jules/.pyenv/versions/3.12.11/lib/python3.12/asyncio/threads.py\", line 25, in to_thread\n    return await loop.run_in_executor(None, func_call)\n           ^^^^^^^^^^^^^^^^^^^^^^^^^^^^^^^^^^^^^^^^^^^\n  File \"/home/jules/.pyenv/versions/3.12.11/lib/python3.12/concurrent/futures/thread.py\", line 59, in run\n    result = self.fn(*self.args, **self.kwargs)\n             ^^^^^^^^^^^^^^^^^^^^^^^^^^^^^^^^^^\n  File \"/home/jules/.pyenv/versions/3.12.11/lib/python3.12/unittest/mock.py\", line 1139, in __call__\n    return self._mock_call(*args, **kwargs)\n           ^^^^^^^^^^^^^^^^^^^^^^^^^^^^^^^^\n  File \"/home/jules/.pyenv/versions/3.12.11/lib/python3.12/unittest/mock.py\", line 1143, in _mock_call\n    return self._execute_mock_call(*args, **kwargs)\n           ^^^^^^^^^^^^^^^^^^^^^^^^^^^^^^^^^^^^^^^^\n  File \"/home/jules/.pyenv/versions/3.12.11/lib/python3.12/unittest/mock.py\", line 1198, in _execute_mock_call\n    raise effect\nrequests.exceptions.RequestException: Network Error"}
{"timestamp": "2025-08-18T21:54:59.349668+09:00", "level": "INFO", "name": "root", "message": "Geocoding cache MISS for query: 'Eiffel Tower'"}
{"timestamp": "2025-08-18T21:55:00.458903+09:00", "level": "INFO", "name": "root", "message": "Geocoding cache MISS for query: 'Springfield'"}
{"timestamp": "2025-08-18T21:55:01.567863+09:00", "level": "INFO", "name": "root", "message": "Geocoding cache MISS for query: 'a_made_up_place_12345'"}
{"timestamp": "2025-08-18T21:55:02.677195+09:00", "level": "INFO", "name": "root", "message": "Geocoding cache MISS for query: 'Tokyo'"}
{"timestamp": "2025-08-18T21:55:03.781080+09:00", "level": "INFO", "name": "root", "message": "Geocoding cache HIT for query: 'Tokyo'"}
{"timestamp": "2025-08-18T21:55:03.787445+09:00", "level": "INFO", "name": "root", "message": "OpenWeatherMap API 요청: URL='https://api.openweathermap.org/data/2.5/weather', Params='{'lat': 35.68, 'lon': 139.69, 'appid': '[REDACTED]', 'units': 'metric', 'lang': 'kr'}'"}
{"timestamp": "2025-08-18T21:55:03.795371+09:00", "level": "INFO", "name": "root", "message": "OpenWeatherMap API 요청: URL='https://api.openweathermap.org/data/2.5/weather', Params='{'lat': 35.68, 'lon': 139.69, 'appid': '[REDACTED]', 'units': 'metric', 'lang': 'kr'}'"}
{"timestamp": "2025-08-18T21:55:03.796875+09:00", "level": "ERROR", "name": "root", "message": "OpenWeatherMap API(35.68,139.69) 요청 중 오류: Network Error", "exc_info": "Traceback (most recent call last):\n  File \"/app/utils/api_handlers/openweathermap.py\", line 31, in get_weather_by_coords\n    response = await asyncio.to_thread(session.get, url, params=params, timeout=10)\n               ^^^^^^^^^^^^^^^^^^^^^^^^^^^^^^^^^^^^^^^^^^^^^^^^^^^^^^^^^^^^^^^^^^^^\n  File \"/home/jules/.pyenv/versions/3.12.11/lib/python3.12/asyncio/threads.py\", line 25, in to_thread\n    return await loop.run_in_executor(None, func_call)\n           ^^^^^^^^^^^^^^^^^^^^^^^^^^^^^^^^^^^^^^^^^^^\n  File \"/home/jules/.pyenv/versions/3.12.11/lib/python3.12/concurrent/futures/thread.py\", line 59, in run\n    result = self.fn(*self.args, **self.kwargs)\n             ^^^^^^^^^^^^^^^^^^^^^^^^^^^^^^^^^^\n  File \"/home/jules/.pyenv/versions/3.12.11/lib/python3.12/unittest/mock.py\", line 1139, in __call__\n    return self._mock_call(*args, **kwargs)\n           ^^^^^^^^^^^^^^^^^^^^^^^^^^^^^^^^\n  File \"/home/jules/.pyenv/versions/3.12.11/lib/python3.12/unittest/mock.py\", line 1143, in _mock_call\n    return self._execute_mock_call(*args, **kwargs)\n           ^^^^^^^^^^^^^^^^^^^^^^^^^^^^^^^^^^^^^^^^\n  File \"/home/jules/.pyenv/versions/3.12.11/lib/python3.12/unittest/mock.py\", line 1198, in _execute_mock_call\n    raise effect\nrequests.exceptions.RequestException: Network Error"}
{"timestamp": "2025-08-18T21:55:03.805154+09:00", "level": "INFO", "name": "root", "message": "Ticketmaster API 요청: URL='https://app.ticketmaster.com/discovery/v2/events.json', Params='{'apikey': 'DUMMY_API_KEY', 'latlong': '35.68,139.69', 'radius': 50, 'unit': 'km', 'startDateTime': '2025-08-18T12:55:03Z', 'endDateTime': '2025-09-17T12:55:03Z', 'sort': 'date,asc'}'"}
{"timestamp": "2025-08-18T21:55:03.810981+09:00", "level": "INFO", "name": "root", "message": "Ticketmaster API 요청: URL='https://app.ticketmaster.com/discovery/v2/events.json', Params='{'apikey': 'DUMMY_API_KEY', 'latlong': '35.68,139.69', 'radius': 50, 'unit': 'km', 'startDateTime': '2025-08-18T12:55:03Z', 'endDateTime': '2025-09-17T12:55:03Z', 'sort': 'date,asc'}'"}
{"timestamp": "2025-08-18T21:55:03.811924+09:00", "level": "ERROR", "name": "root", "message": "Ticketmaster API(35.68,139.69) 요청 중 오류: Network Error", "exc_info": "Traceback (most recent call last):\n  File \"/app/utils/api_handlers/ticketmaster.py\", line 37, in get_events_by_coords\n    response = await asyncio.to_thread(session.get, url, params=params, timeout=15)\n               ^^^^^^^^^^^^^^^^^^^^^^^^^^^^^^^^^^^^^^^^^^^^^^^^^^^^^^^^^^^^^^^^^^^^\n  File \"/home/jules/.pyenv/versions/3.12.11/lib/python3.12/asyncio/threads.py\", line 25, in to_thread\n    return await loop.run_in_executor(None, func_call)\n           ^^^^^^^^^^^^^^^^^^^^^^^^^^^^^^^^^^^^^^^^^^^\n  File \"/home/jules/.pyenv/versions/3.12.11/lib/python3.12/concurrent/futures/thread.py\", line 59, in run\n    result = self.fn(*self.args, **self.kwargs)\n             ^^^^^^^^^^^^^^^^^^^^^^^^^^^^^^^^^^\n  File \"/home/jules/.pyenv/versions/3.12.11/lib/python3.12/unittest/mock.py\", line 1139, in __call__\n    return self._mock_call(*args, **kwargs)\n           ^^^^^^^^^^^^^^^^^^^^^^^^^^^^^^^^\n  File \"/home/jules/.pyenv/versions/3.12.11/lib/python3.12/unittest/mock.py\", line 1143, in _mock_call\n    return self._execute_mock_call(*args, **kwargs)\n           ^^^^^^^^^^^^^^^^^^^^^^^^^^^^^^^^^^^^^^^^\n  File \"/home/jules/.pyenv/versions/3.12.11/lib/python3.12/unittest/mock.py\", line 1198, in _execute_mock_call\n    raise effect\nrequests.exceptions.RequestException: Network Error"}
{"timestamp": "2025-08-18T22:07:38.179631+09:00", "level": "WARNING", "name": "root", "message": "수출입은행 환율 API 응답에서 'EUR' 통화를 찾지 못했습니다."}
{"timestamp": "2025-08-18T22:07:38.186666+09:00", "level": "INFO", "name": "root", "message": "Foursquare API 요청: URL='https://api.foursquare.com/v3/places/search', Params='{'ll': '35.68,139.69', 'limit': 10, 'sort': 'RELEVANCE'}'"}
{"timestamp": "2025-08-18T22:07:38.194676+09:00", "level": "INFO", "name": "root", "message": "Foursquare API 요청: URL='https://api.foursquare.com/v3/places/search', Params='{'ll': '35.68,139.69', 'limit': 10, 'sort': 'RELEVANCE'}'"}
{"timestamp": "2025-08-18T22:07:38.195466+09:00", "level": "ERROR", "name": "root", "message": "Foursquare API(35.68,139.69) 요청 중 오류: Network Error", "exc_info": "Traceback (most recent call last):\n  File \"/app/utils/api_handlers/foursquare.py\", line 33, in get_places_by_coords\n    response = await asyncio.to_thread(session.get, url, headers=headers, params=params, timeout=15)\n               ^^^^^^^^^^^^^^^^^^^^^^^^^^^^^^^^^^^^^^^^^^^^^^^^^^^^^^^^^^^^^^^^^^^^^^^^^^^^^^^^^^^^^\n  File \"/home/jules/.pyenv/versions/3.12.11/lib/python3.12/asyncio/threads.py\", line 25, in to_thread\n    return await loop.run_in_executor(None, func_call)\n           ^^^^^^^^^^^^^^^^^^^^^^^^^^^^^^^^^^^^^^^^^^^\n  File \"/home/jules/.pyenv/versions/3.12.11/lib/python3.12/concurrent/futures/thread.py\", line 59, in run\n    result = self.fn(*self.args, **self.kwargs)\n             ^^^^^^^^^^^^^^^^^^^^^^^^^^^^^^^^^^\n  File \"/home/jules/.pyenv/versions/3.12.11/lib/python3.12/unittest/mock.py\", line 1139, in __call__\n    return self._mock_call(*args, **kwargs)\n           ^^^^^^^^^^^^^^^^^^^^^^^^^^^^^^^^\n  File \"/home/jules/.pyenv/versions/3.12.11/lib/python3.12/unittest/mock.py\", line 1143, in _mock_call\n    return self._execute_mock_call(*args, **kwargs)\n           ^^^^^^^^^^^^^^^^^^^^^^^^^^^^^^^^^^^^^^^^\n  File \"/home/jules/.pyenv/versions/3.12.11/lib/python3.12/unittest/mock.py\", line 1198, in _execute_mock_call\n    raise effect\nrequests.exceptions.RequestException: Network Error"}
{"timestamp": "2025-08-18T22:07:38.206612+09:00", "level": "INFO", "name": "root", "message": "Geocoding cache MISS for query: 'Eiffel Tower'"}
{"timestamp": "2025-08-18T22:07:39.314599+09:00", "level": "INFO", "name": "root", "message": "Geocoding cache MISS for query: 'Springfield'"}
{"timestamp": "2025-08-18T22:07:40.423429+09:00", "level": "INFO", "name": "root", "message": "Geocoding cache MISS for query: 'a_made_up_place_12345'"}
{"timestamp": "2025-08-18T22:07:41.531864+09:00", "level": "INFO", "name": "root", "message": "Geocoding cache MISS for query: 'Tokyo'"}
{"timestamp": "2025-08-18T22:07:42.635085+09:00", "level": "INFO", "name": "root", "message": "Geocoding cache HIT for query: 'Tokyo'"}
{"timestamp": "2025-08-18T22:07:42.640598+09:00", "level": "INFO", "name": "root", "message": "OpenWeatherMap API 요청: URL='https://api.openweathermap.org/data/2.5/weather', Params='{'lat': 35.68, 'lon': 139.69, 'appid': '[REDACTED]', 'units': 'metric', 'lang': 'kr'}'"}
{"timestamp": "2025-08-18T22:07:42.645472+09:00", "level": "INFO", "name": "root", "message": "OpenWeatherMap API 요청: URL='https://api.openweathermap.org/data/2.5/weather', Params='{'lat': 35.68, 'lon': 139.69, 'appid': '[REDACTED]', 'units': 'metric', 'lang': 'kr'}'"}
{"timestamp": "2025-08-18T22:07:42.646200+09:00", "level": "ERROR", "name": "root", "message": "OpenWeatherMap API(35.68,139.69) 요청 중 오류: Network Error", "exc_info": "Traceback (most recent call last):\n  File \"/app/utils/api_handlers/openweathermap.py\", line 31, in get_weather_by_coords\n    response = await asyncio.to_thread(session.get, url, params=params, timeout=10)\n               ^^^^^^^^^^^^^^^^^^^^^^^^^^^^^^^^^^^^^^^^^^^^^^^^^^^^^^^^^^^^^^^^^^^^\n  File \"/home/jules/.pyenv/versions/3.12.11/lib/python3.12/asyncio/threads.py\", line 25, in to_thread\n    return await loop.run_in_executor(None, func_call)\n           ^^^^^^^^^^^^^^^^^^^^^^^^^^^^^^^^^^^^^^^^^^^\n  File \"/home/jules/.pyenv/versions/3.12.11/lib/python3.12/concurrent/futures/thread.py\", line 59, in run\n    result = self.fn(*self.args, **self.kwargs)\n             ^^^^^^^^^^^^^^^^^^^^^^^^^^^^^^^^^^\n  File \"/home/jules/.pyenv/versions/3.12.11/lib/python3.12/unittest/mock.py\", line 1139, in __call__\n    return self._mock_call(*args, **kwargs)\n           ^^^^^^^^^^^^^^^^^^^^^^^^^^^^^^^^\n  File \"/home/jules/.pyenv/versions/3.12.11/lib/python3.12/unittest/mock.py\", line 1143, in _mock_call\n    return self._execute_mock_call(*args, **kwargs)\n           ^^^^^^^^^^^^^^^^^^^^^^^^^^^^^^^^^^^^^^^^\n  File \"/home/jules/.pyenv/versions/3.12.11/lib/python3.12/unittest/mock.py\", line 1198, in _execute_mock_call\n    raise effect\nrequests.exceptions.RequestException: Network Error"}
{"timestamp": "2025-08-18T22:07:42.653726+09:00", "level": "INFO", "name": "root", "message": "Ticketmaster API 요청: URL='https://app.ticketmaster.com/discovery/v2/events.json', Params='{'apikey': 'DUMMY_API_KEY', 'latlong': '35.68,139.69', 'radius': 50, 'unit': 'km', 'startDateTime': '2025-08-18T13:07:42Z', 'endDateTime': '2025-09-17T13:07:42Z', 'sort': 'date,asc'}'"}
{"timestamp": "2025-08-18T22:07:42.658585+09:00", "level": "INFO", "name": "root", "message": "Ticketmaster API 요청: URL='https://app.ticketmaster.com/discovery/v2/events.json', Params='{'apikey': 'DUMMY_API_KEY', 'latlong': '35.68,139.69', 'radius': 50, 'unit': 'km', 'startDateTime': '2025-08-18T13:07:42Z', 'endDateTime': '2025-09-17T13:07:42Z', 'sort': 'date,asc'}'"}
{"timestamp": "2025-08-18T22:07:42.659356+09:00", "level": "ERROR", "name": "root", "message": "Ticketmaster API(35.68,139.69) 요청 중 오류: Network Error", "exc_info": "Traceback (most recent call last):\n  File \"/app/utils/api_handlers/ticketmaster.py\", line 37, in get_events_by_coords\n    response = await asyncio.to_thread(session.get, url, params=params, timeout=15)\n               ^^^^^^^^^^^^^^^^^^^^^^^^^^^^^^^^^^^^^^^^^^^^^^^^^^^^^^^^^^^^^^^^^^^^\n  File \"/home/jules/.pyenv/versions/3.12.11/lib/python3.12/asyncio/threads.py\", line 25, in to_thread\n    return await loop.run_in_executor(None, func_call)\n           ^^^^^^^^^^^^^^^^^^^^^^^^^^^^^^^^^^^^^^^^^^^\n  File \"/home/jules/.pyenv/versions/3.12.11/lib/python3.12/concurrent/futures/thread.py\", line 59, in run\n    result = self.fn(*self.args, **self.kwargs)\n             ^^^^^^^^^^^^^^^^^^^^^^^^^^^^^^^^^^\n  File \"/home/jules/.pyenv/versions/3.12.11/lib/python3.12/unittest/mock.py\", line 1139, in __call__\n    return self._mock_call(*args, **kwargs)\n           ^^^^^^^^^^^^^^^^^^^^^^^^^^^^^^^^\n  File \"/home/jules/.pyenv/versions/3.12.11/lib/python3.12/unittest/mock.py\", line 1143, in _mock_call\n    return self._execute_mock_call(*args, **kwargs)\n           ^^^^^^^^^^^^^^^^^^^^^^^^^^^^^^^^^^^^^^^^\n  File \"/home/jules/.pyenv/versions/3.12.11/lib/python3.12/unittest/mock.py\", line 1198, in _execute_mock_call\n    raise effect\nrequests.exceptions.RequestException: Network Error"}
{"timestamp": "2025-08-18T22:07:42.665108+09:00", "level": "INFO", "name": "root", "message": "ToolsCog 초기화 완료."}
{"timestamp": "2025-08-18T22:07:42.667952+09:00", "level": "INFO", "name": "root", "message": "Travel recommendation for 'Seoul, South Korea' (37.56, 126.97), country: kr"}
{"timestamp": "2025-08-18T22:07:42.670773+09:00", "level": "INFO", "name": "root", "message": "ToolsCog 초기화 완료."}
{"timestamp": "2025-08-18T22:07:42.674559+09:00", "level": "INFO", "name": "root", "message": "Travel recommendation for 'Paris, France' (48.85, 2.29), country: fr"}
