{"timestamp": "2025-09-16T16:13:58.194054+09:00", "level": "ERROR", "name": "root", "message": "Foursquare API(35.68,139.69) 요청 중 오류: Network Error", "source": "foursquare.py:51", "function": "get_places_by_coords", "exc_info": "Traceback (most recent call last):\n  File \"/Users/gimhyeonmin/masamong/utils/api_handlers/foursquare.py\", line 33, in get_places_by_coords\n    response = await asyncio.to_thread(session.get, url, headers=headers, params=params, timeout=15)\n               ^^^^^^^^^^^^^^^^^^^^^^^^^^^^^^^^^^^^^^^^^^^^^^^^^^^^^^^^^^^^^^^^^^^^^^^^^^^^^^^^^^^^^\n  File \"/Library/Frameworks/Python.framework/Versions/3.13/lib/python3.13/asyncio/threads.py\", line 25, in to_thread\n    return await loop.run_in_executor(None, func_call)\n           ^^^^^^^^^^^^^^^^^^^^^^^^^^^^^^^^^^^^^^^^^^^\n  File \"/Library/Frameworks/Python.framework/Versions/3.13/lib/python3.13/concurrent/futures/thread.py\", line 59, in run\n    result = self.fn(*self.args, **self.kwargs)\n  File \"/Library/Frameworks/Python.framework/Versions/3.13/lib/python3.13/unittest/mock.py\", line 1167, in __call__\n    return self._mock_call(*args, **kwargs)\n           ~~~~~~~~~~~~~~~^^^^^^^^^^^^^^^^^\n  File \"/Library/Frameworks/Python.framework/Versions/3.13/lib/python3.13/unittest/mock.py\", line 1171, in _mock_call\n    return self._execute_mock_call(*args, **kwargs)\n           ~~~~~~~~~~~~~~~~~~~~~~~^^^^^^^^^^^^^^^^^\n  File \"/Library/Frameworks/Python.framework/Versions/3.13/lib/python3.13/unittest/mock.py\", line 1226, in _execute_mock_call\n    raise effect\nrequests.exceptions.RequestException: Network Error", "trace_id": "N/A"}
{"timestamp": "2025-09-16T16:14:02.637731+09:00", "level": "ERROR", "name": "root", "message": "OpenWeatherMap API(35.68,139.69) 요청 중 오류: Network Error", "source": "openweathermap.py:53", "function": "get_weather_by_coords", "exc_info": "Traceback (most recent call last):\n  File \"/Users/gimhyeonmin/masamong/utils/api_handlers/openweathermap.py\", line 31, in get_weather_by_coords\n    response = await asyncio.to_thread(session.get, url, params=params, timeout=10)\n               ^^^^^^^^^^^^^^^^^^^^^^^^^^^^^^^^^^^^^^^^^^^^^^^^^^^^^^^^^^^^^^^^^^^^\n  File \"/Library/Frameworks/Python.framework/Versions/3.13/lib/python3.13/asyncio/threads.py\", line 25, in to_thread\n    return await loop.run_in_executor(None, func_call)\n           ^^^^^^^^^^^^^^^^^^^^^^^^^^^^^^^^^^^^^^^^^^^\n  File \"/Library/Frameworks/Python.framework/Versions/3.13/lib/python3.13/concurrent/futures/thread.py\", line 59, in run\n    result = self.fn(*self.args, **self.kwargs)\n  File \"/Library/Frameworks/Python.framework/Versions/3.13/lib/python3.13/unittest/mock.py\", line 1167, in __call__\n    return self._mock_call(*args, **kwargs)\n           ~~~~~~~~~~~~~~~^^^^^^^^^^^^^^^^^\n  File \"/Library/Frameworks/Python.framework/Versions/3.13/lib/python3.13/unittest/mock.py\", line 1171, in _mock_call\n    return self._execute_mock_call(*args, **kwargs)\n           ~~~~~~~~~~~~~~~~~~~~~~~^^^^^^^^^^^^^^^^^\n  File \"/Library/Frameworks/Python.framework/Versions/3.13/lib/python3.13/unittest/mock.py\", line 1226, in _execute_mock_call\n    raise effect\nrequests.exceptions.RequestException: Network Error", "trace_id": "N/A"}
{"timestamp": "2025-09-16T16:14:02.646887+09:00", "level": "ERROR", "name": "root", "message": "Ticketmaster API(35.68,139.69) 요청 중 오류: Network Error", "source": "ticketmaster.py:57", "function": "get_events_by_coords", "exc_info": "Traceback (most recent call last):\n  File \"/Users/gimhyeonmin/masamong/utils/api_handlers/ticketmaster.py\", line 37, in get_events_by_coords\n    response = await asyncio.to_thread(session.get, url, params=params, timeout=15)\n               ^^^^^^^^^^^^^^^^^^^^^^^^^^^^^^^^^^^^^^^^^^^^^^^^^^^^^^^^^^^^^^^^^^^^\n  File \"/Library/Frameworks/Python.framework/Versions/3.13/lib/python3.13/asyncio/threads.py\", line 25, in to_thread\n    return await loop.run_in_executor(None, func_call)\n           ^^^^^^^^^^^^^^^^^^^^^^^^^^^^^^^^^^^^^^^^^^^\n  File \"/Library/Frameworks/Python.framework/Versions/3.13/lib/python3.13/concurrent/futures/thread.py\", line 59, in run\n    result = self.fn(*self.args, **self.kwargs)\n  File \"/Library/Frameworks/Python.framework/Versions/3.13/lib/python3.13/unittest/mock.py\", line 1167, in __call__\n    return self._mock_call(*args, **kwargs)\n           ~~~~~~~~~~~~~~~^^^^^^^^^^^^^^^^^\n  File \"/Library/Frameworks/Python.framework/Versions/3.13/lib/python3.13/unittest/mock.py\", line 1171, in _mock_call\n    return self._execute_mock_call(*args, **kwargs)\n           ~~~~~~~~~~~~~~~~~~~~~~~^^^^^^^^^^^^^^^^^\n  File \"/Library/Frameworks/Python.framework/Versions/3.13/lib/python3.13/unittest/mock.py\", line 1226, in _execute_mock_call\n    raise effect\nrequests.exceptions.RequestException: Network Error", "trace_id": "N/A"}
{"timestamp": "2025-09-16T16:15:10.730088+09:00", "level": "ERROR", "name": "root", "message": "Foursquare API(35.68,139.69) 요청 중 오류: Network Error", "source": "foursquare.py:51", "function": "get_places_by_coords", "exc_info": "Traceback (most recent call last):\n  File \"/Users/gimhyeonmin/masamong/utils/api_handlers/foursquare.py\", line 33, in get_places_by_coords\n    response = await asyncio.to_thread(session.get, url, headers=headers, params=params, timeout=15)\n               ^^^^^^^^^^^^^^^^^^^^^^^^^^^^^^^^^^^^^^^^^^^^^^^^^^^^^^^^^^^^^^^^^^^^^^^^^^^^^^^^^^^^^\n  File \"/Library/Frameworks/Python.framework/Versions/3.13/lib/python3.13/asyncio/threads.py\", line 25, in to_thread\n    return await loop.run_in_executor(None, func_call)\n           ^^^^^^^^^^^^^^^^^^^^^^^^^^^^^^^^^^^^^^^^^^^\n  File \"/Library/Frameworks/Python.framework/Versions/3.13/lib/python3.13/concurrent/futures/thread.py\", line 59, in run\n    result = self.fn(*self.args, **self.kwargs)\n  File \"/Library/Frameworks/Python.framework/Versions/3.13/lib/python3.13/unittest/mock.py\", line 1167, in __call__\n    return self._mock_call(*args, **kwargs)\n           ~~~~~~~~~~~~~~~^^^^^^^^^^^^^^^^^\n  File \"/Library/Frameworks/Python.framework/Versions/3.13/lib/python3.13/unittest/mock.py\", line 1171, in _mock_call\n    return self._execute_mock_call(*args, **kwargs)\n           ~~~~~~~~~~~~~~~~~~~~~~~^^^^^^^^^^^^^^^^^\n  File \"/Library/Frameworks/Python.framework/Versions/3.13/lib/python3.13/unittest/mock.py\", line 1226, in _execute_mock_call\n    raise effect\nrequests.exceptions.RequestException: Network Error", "trace_id": "N/A"}
{"timestamp": "2025-09-16T16:15:15.171710+09:00", "level": "ERROR", "name": "root", "message": "OpenWeatherMap API(35.68,139.69) 요청 중 오류: Network Error", "source": "openweathermap.py:53", "function": "get_weather_by_coords", "exc_info": "Traceback (most recent call last):\n  File \"/Users/gimhyeonmin/masamong/utils/api_handlers/openweathermap.py\", line 31, in get_weather_by_coords\n    response = await asyncio.to_thread(session.get, url, params=params, timeout=10)\n               ^^^^^^^^^^^^^^^^^^^^^^^^^^^^^^^^^^^^^^^^^^^^^^^^^^^^^^^^^^^^^^^^^^^^\n  File \"/Library/Frameworks/Python.framework/Versions/3.13/lib/python3.13/asyncio/threads.py\", line 25, in to_thread\n    return await loop.run_in_executor(None, func_call)\n           ^^^^^^^^^^^^^^^^^^^^^^^^^^^^^^^^^^^^^^^^^^^\n  File \"/Library/Frameworks/Python.framework/Versions/3.13/lib/python3.13/concurrent/futures/thread.py\", line 59, in run\n    result = self.fn(*self.args, **self.kwargs)\n  File \"/Library/Frameworks/Python.framework/Versions/3.13/lib/python3.13/unittest/mock.py\", line 1167, in __call__\n    return self._mock_call(*args, **kwargs)\n           ~~~~~~~~~~~~~~~^^^^^^^^^^^^^^^^^\n  File \"/Library/Frameworks/Python.framework/Versions/3.13/lib/python3.13/unittest/mock.py\", line 1171, in _mock_call\n    return self._execute_mock_call(*args, **kwargs)\n           ~~~~~~~~~~~~~~~~~~~~~~~^^^^^^^^^^^^^^^^^\n  File \"/Library/Frameworks/Python.framework/Versions/3.13/lib/python3.13/unittest/mock.py\", line 1226, in _execute_mock_call\n    raise effect\nrequests.exceptions.RequestException: Network Error", "trace_id": "N/A"}
{"timestamp": "2025-09-16T16:16:08.900208+09:00", "level": "ERROR", "name": "root", "message": "Foursquare API(35.68,139.69) 요청 중 오류: Network Error", "source": "foursquare.py:51", "function": "get_places_by_coords", "exc_info": "Traceback (most recent call last):\n  File \"/Users/gimhyeonmin/masamong/utils/api_handlers/foursquare.py\", line 33, in get_places_by_coords\n    response = await asyncio.to_thread(session.get, url, headers=headers, params=params, timeout=15)\n               ^^^^^^^^^^^^^^^^^^^^^^^^^^^^^^^^^^^^^^^^^^^^^^^^^^^^^^^^^^^^^^^^^^^^^^^^^^^^^^^^^^^^^\n  File \"/Library/Frameworks/Python.framework/Versions/3.13/lib/python3.13/asyncio/threads.py\", line 25, in to_thread\n    return await loop.run_in_executor(None, func_call)\n           ^^^^^^^^^^^^^^^^^^^^^^^^^^^^^^^^^^^^^^^^^^^\n  File \"/Library/Frameworks/Python.framework/Versions/3.13/lib/python3.13/concurrent/futures/thread.py\", line 59, in run\n    result = self.fn(*self.args, **self.kwargs)\n  File \"/Library/Frameworks/Python.framework/Versions/3.13/lib/python3.13/unittest/mock.py\", line 1167, in __call__\n    return self._mock_call(*args, **kwargs)\n           ~~~~~~~~~~~~~~~^^^^^^^^^^^^^^^^^\n  File \"/Library/Frameworks/Python.framework/Versions/3.13/lib/python3.13/unittest/mock.py\", line 1171, in _mock_call\n    return self._execute_mock_call(*args, **kwargs)\n           ~~~~~~~~~~~~~~~~~~~~~~~^^^^^^^^^^^^^^^^^\n  File \"/Library/Frameworks/Python.framework/Versions/3.13/lib/python3.13/unittest/mock.py\", line 1226, in _execute_mock_call\n    raise effect\nrequests.exceptions.RequestException: Network Error", "trace_id": "N/A"}
{"timestamp": "2025-09-16T16:16:13.344814+09:00", "level": "ERROR", "name": "root", "message": "OpenWeatherMap API(35.68,139.69) 요청 중 오류: Network Error", "source": "openweathermap.py:53", "function": "get_weather_by_coords", "exc_info": "Traceback (most recent call last):\n  File \"/Users/gimhyeonmin/masamong/utils/api_handlers/openweathermap.py\", line 31, in get_weather_by_coords\n    response = await asyncio.to_thread(session.get, url, params=params, timeout=10)\n               ^^^^^^^^^^^^^^^^^^^^^^^^^^^^^^^^^^^^^^^^^^^^^^^^^^^^^^^^^^^^^^^^^^^^\n  File \"/Library/Frameworks/Python.framework/Versions/3.13/lib/python3.13/asyncio/threads.py\", line 25, in to_thread\n    return await loop.run_in_executor(None, func_call)\n           ^^^^^^^^^^^^^^^^^^^^^^^^^^^^^^^^^^^^^^^^^^^\n  File \"/Library/Frameworks/Python.framework/Versions/3.13/lib/python3.13/concurrent/futures/thread.py\", line 59, in run\n    result = self.fn(*self.args, **self.kwargs)\n  File \"/Library/Frameworks/Python.framework/Versions/3.13/lib/python3.13/unittest/mock.py\", line 1167, in __call__\n    return self._mock_call(*args, **kwargs)\n           ~~~~~~~~~~~~~~~^^^^^^^^^^^^^^^^^\n  File \"/Library/Frameworks/Python.framework/Versions/3.13/lib/python3.13/unittest/mock.py\", line 1171, in _mock_call\n    return self._execute_mock_call(*args, **kwargs)\n           ~~~~~~~~~~~~~~~~~~~~~~~^^^^^^^^^^^^^^^^^\n  File \"/Library/Frameworks/Python.framework/Versions/3.13/lib/python3.13/unittest/mock.py\", line 1226, in _execute_mock_call\n    raise effect\nrequests.exceptions.RequestException: Network Error", "trace_id": "N/A"}
{"timestamp": "2025-09-16T16:16:13.353824+09:00", "level": "ERROR", "name": "root", "message": "Ticketmaster API(35.68,139.69) 요청 중 오류: Network Error", "source": "ticketmaster.py:57", "function": "get_events_by_coords", "exc_info": "Traceback (most recent call last):\n  File \"/Users/gimhyeonmin/masamong/utils/api_handlers/ticketmaster.py\", line 37, in get_events_by_coords\n    response = await asyncio.to_thread(session.get, url, params=params, timeout=15)\n               ^^^^^^^^^^^^^^^^^^^^^^^^^^^^^^^^^^^^^^^^^^^^^^^^^^^^^^^^^^^^^^^^^^^^\n  File \"/Library/Frameworks/Python.framework/Versions/3.13/lib/python3.13/asyncio/threads.py\", line 25, in to_thread\n    return await loop.run_in_executor(None, func_call)\n           ^^^^^^^^^^^^^^^^^^^^^^^^^^^^^^^^^^^^^^^^^^^\n  File \"/Library/Frameworks/Python.framework/Versions/3.13/lib/python3.13/concurrent/futures/thread.py\", line 59, in run\n    result = self.fn(*self.args, **self.kwargs)\n  File \"/Library/Frameworks/Python.framework/Versions/3.13/lib/python3.13/unittest/mock.py\", line 1167, in __call__\n    return self._mock_call(*args, **kwargs)\n           ~~~~~~~~~~~~~~~^^^^^^^^^^^^^^^^^\n  File \"/Library/Frameworks/Python.framework/Versions/3.13/lib/python3.13/unittest/mock.py\", line 1171, in _mock_call\n    return self._execute_mock_call(*args, **kwargs)\n           ~~~~~~~~~~~~~~~~~~~~~~~^^^^^^^^^^^^^^^^^\n  File \"/Library/Frameworks/Python.framework/Versions/3.13/lib/python3.13/unittest/mock.py\", line 1226, in _execute_mock_call\n    raise effect\nrequests.exceptions.RequestException: Network Error", "trace_id": "N/A"}
{"timestamp": "2025-09-16T16:16:25.227175+09:00", "level": "ERROR", "name": "root", "message": "Foursquare API(35.68,139.69) 요청 중 오류: Network Error", "source": "foursquare.py:51", "function": "get_places_by_coords", "exc_info": "Traceback (most recent call last):\n  File \"/Users/gimhyeonmin/masamong/utils/api_handlers/foursquare.py\", line 33, in get_places_by_coords\n    response = await asyncio.to_thread(session.get, url, headers=headers, params=params, timeout=15)\n               ^^^^^^^^^^^^^^^^^^^^^^^^^^^^^^^^^^^^^^^^^^^^^^^^^^^^^^^^^^^^^^^^^^^^^^^^^^^^^^^^^^^^^\n  File \"/Library/Frameworks/Python.framework/Versions/3.13/lib/python3.13/asyncio/threads.py\", line 25, in to_thread\n    return await loop.run_in_executor(None, func_call)\n           ^^^^^^^^^^^^^^^^^^^^^^^^^^^^^^^^^^^^^^^^^^^\n  File \"/Library/Frameworks/Python.framework/Versions/3.13/lib/python3.13/concurrent/futures/thread.py\", line 59, in run\n    result = self.fn(*self.args, **self.kwargs)\n  File \"/Library/Frameworks/Python.framework/Versions/3.13/lib/python3.13/unittest/mock.py\", line 1167, in __call__\n    return self._mock_call(*args, **kwargs)\n           ~~~~~~~~~~~~~~~^^^^^^^^^^^^^^^^^\n  File \"/Library/Frameworks/Python.framework/Versions/3.13/lib/python3.13/unittest/mock.py\", line 1171, in _mock_call\n    return self._execute_mock_call(*args, **kwargs)\n           ~~~~~~~~~~~~~~~~~~~~~~~^^^^^^^^^^^^^^^^^\n  File \"/Library/Frameworks/Python.framework/Versions/3.13/lib/python3.13/unittest/mock.py\", line 1226, in _execute_mock_call\n    raise effect\nrequests.exceptions.RequestException: Network Error", "trace_id": "N/A"}
{"timestamp": "2025-09-16T16:16:29.675554+09:00", "level": "ERROR", "name": "root", "message": "OpenWeatherMap API(35.68,139.69) 요청 중 오류: Network Error", "source": "openweathermap.py:53", "function": "get_weather_by_coords", "exc_info": "Traceback (most recent call last):\n  File \"/Users/gimhyeonmin/masamong/utils/api_handlers/openweathermap.py\", line 31, in get_weather_by_coords\n    response = await asyncio.to_thread(session.get, url, params=params, timeout=10)\n               ^^^^^^^^^^^^^^^^^^^^^^^^^^^^^^^^^^^^^^^^^^^^^^^^^^^^^^^^^^^^^^^^^^^^\n  File \"/Library/Frameworks/Python.framework/Versions/3.13/lib/python3.13/asyncio/threads.py\", line 25, in to_thread\n    return await loop.run_in_executor(None, func_call)\n           ^^^^^^^^^^^^^^^^^^^^^^^^^^^^^^^^^^^^^^^^^^^\n  File \"/Library/Frameworks/Python.framework/Versions/3.13/lib/python3.13/concurrent/futures/thread.py\", line 59, in run\n    result = self.fn(*self.args, **self.kwargs)\n  File \"/Library/Frameworks/Python.framework/Versions/3.13/lib/python3.13/unittest/mock.py\", line 1167, in __call__\n    return self._mock_call(*args, **kwargs)\n           ~~~~~~~~~~~~~~~^^^^^^^^^^^^^^^^^\n  File \"/Library/Frameworks/Python.framework/Versions/3.13/lib/python3.13/unittest/mock.py\", line 1171, in _mock_call\n    return self._execute_mock_call(*args, **kwargs)\n           ~~~~~~~~~~~~~~~~~~~~~~~^^^^^^^^^^^^^^^^^\n  File \"/Library/Frameworks/Python.framework/Versions/3.13/lib/python3.13/unittest/mock.py\", line 1226, in _execute_mock_call\n    raise effect\nrequests.exceptions.RequestException: Network Error", "trace_id": "N/A"}
{"timestamp": "2025-09-16T16:16:29.685093+09:00", "level": "ERROR", "name": "root", "message": "Ticketmaster API(35.68,139.69) 요청 중 오류: Network Error", "source": "ticketmaster.py:57", "function": "get_events_by_coords", "exc_info": "Traceback (most recent call last):\n  File \"/Users/gimhyeonmin/masamong/utils/api_handlers/ticketmaster.py\", line 37, in get_events_by_coords\n    response = await asyncio.to_thread(session.get, url, params=params, timeout=15)\n               ^^^^^^^^^^^^^^^^^^^^^^^^^^^^^^^^^^^^^^^^^^^^^^^^^^^^^^^^^^^^^^^^^^^^\n  File \"/Library/Frameworks/Python.framework/Versions/3.13/lib/python3.13/asyncio/threads.py\", line 25, in to_thread\n    return await loop.run_in_executor(None, func_call)\n           ^^^^^^^^^^^^^^^^^^^^^^^^^^^^^^^^^^^^^^^^^^^\n  File \"/Library/Frameworks/Python.framework/Versions/3.13/lib/python3.13/concurrent/futures/thread.py\", line 59, in run\n    result = self.fn(*self.args, **self.kwargs)\n  File \"/Library/Frameworks/Python.framework/Versions/3.13/lib/python3.13/unittest/mock.py\", line 1167, in __call__\n    return self._mock_call(*args, **kwargs)\n           ~~~~~~~~~~~~~~~^^^^^^^^^^^^^^^^^\n  File \"/Library/Frameworks/Python.framework/Versions/3.13/lib/python3.13/unittest/mock.py\", line 1171, in _mock_call\n    return self._execute_mock_call(*args, **kwargs)\n           ~~~~~~~~~~~~~~~~~~~~~~~^^^^^^^^^^^^^^^^^\n  File \"/Library/Frameworks/Python.framework/Versions/3.13/lib/python3.13/unittest/mock.py\", line 1226, in _execute_mock_call\n    raise effect\nrequests.exceptions.RequestException: Network Error", "trace_id": "N/A"}
{"timestamp": "2025-09-16T16:25:54.909408+09:00", "level": "ERROR", "name": "root", "message": "Foursquare API(35.68,139.69) 요청 중 오류: Network Error", "source": "foursquare.py:51", "function": "get_places_by_coords", "exc_info": "Traceback (most recent call last):\n  File \"/Users/gimhyeonmin/masamong/utils/api_handlers/foursquare.py\", line 33, in get_places_by_coords\n    response = await asyncio.to_thread(session.get, url, headers=headers, params=params, timeout=15)\n               ^^^^^^^^^^^^^^^^^^^^^^^^^^^^^^^^^^^^^^^^^^^^^^^^^^^^^^^^^^^^^^^^^^^^^^^^^^^^^^^^^^^^^\n  File \"/Library/Frameworks/Python.framework/Versions/3.13/lib/python3.13/asyncio/threads.py\", line 25, in to_thread\n    return await loop.run_in_executor(None, func_call)\n           ^^^^^^^^^^^^^^^^^^^^^^^^^^^^^^^^^^^^^^^^^^^\n  File \"/Library/Frameworks/Python.framework/Versions/3.13/lib/python3.13/concurrent/futures/thread.py\", line 59, in run\n    result = self.fn(*self.args, **self.kwargs)\n  File \"/Library/Frameworks/Python.framework/Versions/3.13/lib/python3.13/unittest/mock.py\", line 1167, in __call__\n    return self._mock_call(*args, **kwargs)\n           ~~~~~~~~~~~~~~~^^^^^^^^^^^^^^^^^\n  File \"/Library/Frameworks/Python.framework/Versions/3.13/lib/python3.13/unittest/mock.py\", line 1171, in _mock_call\n    return self._execute_mock_call(*args, **kwargs)\n           ~~~~~~~~~~~~~~~~~~~~~~~^^^^^^^^^^^^^^^^^\n  File \"/Library/Frameworks/Python.framework/Versions/3.13/lib/python3.13/unittest/mock.py\", line 1226, in _execute_mock_call\n    raise effect\nrequests.exceptions.RequestException: Network Error", "trace_id": "N/A"}
{"timestamp": "2025-09-16T16:25:59.344605+09:00", "level": "ERROR", "name": "root", "message": "OpenWeatherMap API(35.68,139.69) 요청 중 오류: Network Error", "source": "openweathermap.py:53", "function": "get_weather_by_coords", "exc_info": "Traceback (most recent call last):\n  File \"/Users/gimhyeonmin/masamong/utils/api_handlers/openweathermap.py\", line 31, in get_weather_by_coords\n    response = await asyncio.to_thread(session.get, url, params=params, timeout=10)\n               ^^^^^^^^^^^^^^^^^^^^^^^^^^^^^^^^^^^^^^^^^^^^^^^^^^^^^^^^^^^^^^^^^^^^\n  File \"/Library/Frameworks/Python.framework/Versions/3.13/lib/python3.13/asyncio/threads.py\", line 25, in to_thread\n    return await loop.run_in_executor(None, func_call)\n           ^^^^^^^^^^^^^^^^^^^^^^^^^^^^^^^^^^^^^^^^^^^\n  File \"/Library/Frameworks/Python.framework/Versions/3.13/lib/python3.13/concurrent/futures/thread.py\", line 59, in run\n    result = self.fn(*self.args, **self.kwargs)\n  File \"/Library/Frameworks/Python.framework/Versions/3.13/lib/python3.13/unittest/mock.py\", line 1167, in __call__\n    return self._mock_call(*args, **kwargs)\n           ~~~~~~~~~~~~~~~^^^^^^^^^^^^^^^^^\n  File \"/Library/Frameworks/Python.framework/Versions/3.13/lib/python3.13/unittest/mock.py\", line 1171, in _mock_call\n    return self._execute_mock_call(*args, **kwargs)\n           ~~~~~~~~~~~~~~~~~~~~~~~^^^^^^^^^^^^^^^^^\n  File \"/Library/Frameworks/Python.framework/Versions/3.13/lib/python3.13/unittest/mock.py\", line 1226, in _execute_mock_call\n    raise effect\nrequests.exceptions.RequestException: Network Error", "trace_id": "N/A"}
{"timestamp": "2025-09-16T16:25:59.349478+09:00", "level": "ERROR", "name": "root", "message": "Ticketmaster API(35.68,139.69) 요청 중 오류: Network Error", "source": "ticketmaster.py:57", "function": "get_events_by_coords", "exc_info": "Traceback (most recent call last):\n  File \"/Users/gimhyeonmin/masamong/utils/api_handlers/ticketmaster.py\", line 37, in get_events_by_coords\n    response = await asyncio.to_thread(session.get, url, params=params, timeout=15)\n               ^^^^^^^^^^^^^^^^^^^^^^^^^^^^^^^^^^^^^^^^^^^^^^^^^^^^^^^^^^^^^^^^^^^^\n  File \"/Library/Frameworks/Python.framework/Versions/3.13/lib/python3.13/asyncio/threads.py\", line 25, in to_thread\n    return await loop.run_in_executor(None, func_call)\n           ^^^^^^^^^^^^^^^^^^^^^^^^^^^^^^^^^^^^^^^^^^^\n  File \"/Library/Frameworks/Python.framework/Versions/3.13/lib/python3.13/concurrent/futures/thread.py\", line 59, in run\n    result = self.fn(*self.args, **self.kwargs)\n  File \"/Library/Frameworks/Python.framework/Versions/3.13/lib/python3.13/unittest/mock.py\", line 1167, in __call__\n    return self._mock_call(*args, **kwargs)\n           ~~~~~~~~~~~~~~~^^^^^^^^^^^^^^^^^\n  File \"/Library/Frameworks/Python.framework/Versions/3.13/lib/python3.13/unittest/mock.py\", line 1171, in _mock_call\n    return self._execute_mock_call(*args, **kwargs)\n           ~~~~~~~~~~~~~~~~~~~~~~~^^^^^^^^^^^^^^^^^\n  File \"/Library/Frameworks/Python.framework/Versions/3.13/lib/python3.13/unittest/mock.py\", line 1226, in _execute_mock_call\n    raise effect\nrequests.exceptions.RequestException: Network Error", "trace_id": "N/A"}
