{"timestamp": "2025-09-16T16:13:58.194054+09:00", "level": "ERROR", "name": "root", "message": "Foursquare API(35.68,139.69) 요청 중 오류: Network Error", "source": "foursquare.py:51", "function": "get_places_by_coords", "exc_info": "Traceback (most recent call last):\n  File \"/Users/gimhyeonmin/masamong/utils/api_handlers/foursquare.py\", line 33, in get_places_by_coords\n    response = await asyncio.to_thread(session.get, url, headers=headers, params=params, timeout=15)\n               ^^^^^^^^^^^^^^^^^^^^^^^^^^^^^^^^^^^^^^^^^^^^^^^^^^^^^^^^^^^^^^^^^^^^^^^^^^^^^^^^^^^^^\n  File \"/Library/Frameworks/Python.framework/Versions/3.13/lib/python3.13/asyncio/threads.py\", line 25, in to_thread\n    return await loop.run_in_executor(None, func_call)\n           ^^^^^^^^^^^^^^^^^^^^^^^^^^^^^^^^^^^^^^^^^^^\n  File \"/Library/Frameworks/Python.framework/Versions/3.13/lib/python3.13/concurrent/futures/thread.py\", line 59, in run\n    result = self.fn(*self.args, **self.kwargs)\n  File \"/Library/Frameworks/Python.framework/Versions/3.13/lib/python3.13/unittest/mock.py\", line 1167, in __call__\n    return self._mock_call(*args, **kwargs)\n           ~~~~~~~~~~~~~~~^^^^^^^^^^^^^^^^^\n  File \"/Library/Frameworks/Python.framework/Versions/3.13/lib/python3.13/unittest/mock.py\", line 1171, in _mock_call\n    return self._execute_mock_call(*args, **kwargs)\n           ~~~~~~~~~~~~~~~~~~~~~~~^^^^^^^^^^^^^^^^^\n  File \"/Library/Frameworks/Python.framework/Versions/3.13/lib/python3.13/unittest/mock.py\", line 1226, in _execute_mock_call\n    raise effect\nrequests.exceptions.RequestException: Network Error", "trace_id": "N/A"}
{"timestamp": "2025-09-16T16:14:02.637731+09:00", "level": "ERROR", "name": "root", "message": "OpenWeatherMap API(35.68,139.69) 요청 중 오류: Network Error", "source": "openweathermap.py:53", "function": "get_weather_by_coords", "exc_info": "Traceback (most recent call last):\n  File \"/Users/gimhyeonmin/masamong/utils/api_handlers/openweathermap.py\", line 31, in get_weather_by_coords\n    response = await asyncio.to_thread(session.get, url, params=params, timeout=10)\n               ^^^^^^^^^^^^^^^^^^^^^^^^^^^^^^^^^^^^^^^^^^^^^^^^^^^^^^^^^^^^^^^^^^^^\n  File \"/Library/Frameworks/Python.framework/Versions/3.13/lib/python3.13/asyncio/threads.py\", line 25, in to_thread\n    return await loop.run_in_executor(None, func_call)\n           ^^^^^^^^^^^^^^^^^^^^^^^^^^^^^^^^^^^^^^^^^^^\n  File \"/Library/Frameworks/Python.framework/Versions/3.13/lib/python3.13/concurrent/futures/thread.py\", line 59, in run\n    result = self.fn(*self.args, **self.kwargs)\n  File \"/Library/Frameworks/Python.framework/Versions/3.13/lib/python3.13/unittest/mock.py\", line 1167, in __call__\n    return self._mock_call(*args, **kwargs)\n           ~~~~~~~~~~~~~~~^^^^^^^^^^^^^^^^^\n  File \"/Library/Frameworks/Python.framework/Versions/3.13/lib/python3.13/unittest/mock.py\", line 1171, in _mock_call\n    return self._execute_mock_call(*args, **kwargs)\n           ~~~~~~~~~~~~~~~~~~~~~~~^^^^^^^^^^^^^^^^^\n  File \"/Library/Frameworks/Python.framework/Versions/3.13/lib/python3.13/unittest/mock.py\", line 1226, in _execute_mock_call\n    raise effect\nrequests.exceptions.RequestException: Network Error", "trace_id": "N/A"}
{"timestamp": "2025-09-16T16:14:02.646887+09:00", "level": "ERROR", "name": "root", "message": "Ticketmaster API(35.68,139.69) 요청 중 오류: Network Error", "source": "ticketmaster.py:57", "function": "get_events_by_coords", "exc_info": "Traceback (most recent call last):\n  File \"/Users/gimhyeonmin/masamong/utils/api_handlers/ticketmaster.py\", line 37, in get_events_by_coords\n    response = await asyncio.to_thread(session.get, url, params=params, timeout=15)\n               ^^^^^^^^^^^^^^^^^^^^^^^^^^^^^^^^^^^^^^^^^^^^^^^^^^^^^^^^^^^^^^^^^^^^\n  File \"/Library/Frameworks/Python.framework/Versions/3.13/lib/python3.13/asyncio/threads.py\", line 25, in to_thread\n    return await loop.run_in_executor(None, func_call)\n           ^^^^^^^^^^^^^^^^^^^^^^^^^^^^^^^^^^^^^^^^^^^\n  File \"/Library/Frameworks/Python.framework/Versions/3.13/lib/python3.13/concurrent/futures/thread.py\", line 59, in run\n    result = self.fn(*self.args, **self.kwargs)\n  File \"/Library/Frameworks/Python.framework/Versions/3.13/lib/python3.13/unittest/mock.py\", line 1167, in __call__\n    return self._mock_call(*args, **kwargs)\n           ~~~~~~~~~~~~~~~^^^^^^^^^^^^^^^^^\n  File \"/Library/Frameworks/Python.framework/Versions/3.13/lib/python3.13/unittest/mock.py\", line 1171, in _mock_call\n    return self._execute_mock_call(*args, **kwargs)\n           ~~~~~~~~~~~~~~~~~~~~~~~^^^^^^^^^^^^^^^^^\n  File \"/Library/Frameworks/Python.framework/Versions/3.13/lib/python3.13/unittest/mock.py\", line 1226, in _execute_mock_call\n    raise effect\nrequests.exceptions.RequestException: Network Error", "trace_id": "N/A"}
{"timestamp": "2025-09-16T16:15:10.730088+09:00", "level": "ERROR", "name": "root", "message": "Foursquare API(35.68,139.69) 요청 중 오류: Network Error", "source": "foursquare.py:51", "function": "get_places_by_coords", "exc_info": "Traceback (most recent call last):\n  File \"/Users/gimhyeonmin/masamong/utils/api_handlers/foursquare.py\", line 33, in get_places_by_coords\n    response = await asyncio.to_thread(session.get, url, headers=headers, params=params, timeout=15)\n               ^^^^^^^^^^^^^^^^^^^^^^^^^^^^^^^^^^^^^^^^^^^^^^^^^^^^^^^^^^^^^^^^^^^^^^^^^^^^^^^^^^^^^\n  File \"/Library/Frameworks/Python.framework/Versions/3.13/lib/python3.13/asyncio/threads.py\", line 25, in to_thread\n    return await loop.run_in_executor(None, func_call)\n           ^^^^^^^^^^^^^^^^^^^^^^^^^^^^^^^^^^^^^^^^^^^\n  File \"/Library/Frameworks/Python.framework/Versions/3.13/lib/python3.13/concurrent/futures/thread.py\", line 59, in run\n    result = self.fn(*self.args, **self.kwargs)\n  File \"/Library/Frameworks/Python.framework/Versions/3.13/lib/python3.13/unittest/mock.py\", line 1167, in __call__\n    return self._mock_call(*args, **kwargs)\n           ~~~~~~~~~~~~~~~^^^^^^^^^^^^^^^^^\n  File \"/Library/Frameworks/Python.framework/Versions/3.13/lib/python3.13/unittest/mock.py\", line 1171, in _mock_call\n    return self._execute_mock_call(*args, **kwargs)\n           ~~~~~~~~~~~~~~~~~~~~~~~^^^^^^^^^^^^^^^^^\n  File \"/Library/Frameworks/Python.framework/Versions/3.13/lib/python3.13/unittest/mock.py\", line 1226, in _execute_mock_call\n    raise effect\nrequests.exceptions.RequestException: Network Error", "trace_id": "N/A"}
{"timestamp": "2025-09-16T16:15:15.171710+09:00", "level": "ERROR", "name": "root", "message": "OpenWeatherMap API(35.68,139.69) 요청 중 오류: Network Error", "source": "openweathermap.py:53", "function": "get_weather_by_coords", "exc_info": "Traceback (most recent call last):\n  File \"/Users/gimhyeonmin/masamong/utils/api_handlers/openweathermap.py\", line 31, in get_weather_by_coords\n    response = await asyncio.to_thread(session.get, url, params=params, timeout=10)\n               ^^^^^^^^^^^^^^^^^^^^^^^^^^^^^^^^^^^^^^^^^^^^^^^^^^^^^^^^^^^^^^^^^^^^\n  File \"/Library/Frameworks/Python.framework/Versions/3.13/lib/python3.13/asyncio/threads.py\", line 25, in to_thread\n    return await loop.run_in_executor(None, func_call)\n           ^^^^^^^^^^^^^^^^^^^^^^^^^^^^^^^^^^^^^^^^^^^\n  File \"/Library/Frameworks/Python.framework/Versions/3.13/lib/python3.13/concurrent/futures/thread.py\", line 59, in run\n    result = self.fn(*self.args, **self.kwargs)\n  File \"/Library/Frameworks/Python.framework/Versions/3.13/lib/python3.13/unittest/mock.py\", line 1167, in __call__\n    return self._mock_call(*args, **kwargs)\n           ~~~~~~~~~~~~~~~^^^^^^^^^^^^^^^^^\n  File \"/Library/Frameworks/Python.framework/Versions/3.13/lib/python3.13/unittest/mock.py\", line 1171, in _mock_call\n    return self._execute_mock_call(*args, **kwargs)\n           ~~~~~~~~~~~~~~~~~~~~~~~^^^^^^^^^^^^^^^^^\n  File \"/Library/Frameworks/Python.framework/Versions/3.13/lib/python3.13/unittest/mock.py\", line 1226, in _execute_mock_call\n    raise effect\nrequests.exceptions.RequestException: Network Error", "trace_id": "N/A"}
{"timestamp": "2025-09-16T16:16:08.900208+09:00", "level": "ERROR", "name": "root", "message": "Foursquare API(35.68,139.69) 요청 중 오류: Network Error", "source": "foursquare.py:51", "function": "get_places_by_coords", "exc_info": "Traceback (most recent call last):\n  File \"/Users/gimhyeonmin/masamong/utils/api_handlers/foursquare.py\", line 33, in get_places_by_coords\n    response = await asyncio.to_thread(session.get, url, headers=headers, params=params, timeout=15)\n               ^^^^^^^^^^^^^^^^^^^^^^^^^^^^^^^^^^^^^^^^^^^^^^^^^^^^^^^^^^^^^^^^^^^^^^^^^^^^^^^^^^^^^\n  File \"/Library/Frameworks/Python.framework/Versions/3.13/lib/python3.13/asyncio/threads.py\", line 25, in to_thread\n    return await loop.run_in_executor(None, func_call)\n           ^^^^^^^^^^^^^^^^^^^^^^^^^^^^^^^^^^^^^^^^^^^\n  File \"/Library/Frameworks/Python.framework/Versions/3.13/lib/python3.13/concurrent/futures/thread.py\", line 59, in run\n    result = self.fn(*self.args, **self.kwargs)\n  File \"/Library/Frameworks/Python.framework/Versions/3.13/lib/python3.13/unittest/mock.py\", line 1167, in __call__\n    return self._mock_call(*args, **kwargs)\n           ~~~~~~~~~~~~~~~^^^^^^^^^^^^^^^^^\n  File \"/Library/Frameworks/Python.framework/Versions/3.13/lib/python3.13/unittest/mock.py\", line 1171, in _mock_call\n    return self._execute_mock_call(*args, **kwargs)\n           ~~~~~~~~~~~~~~~~~~~~~~~^^^^^^^^^^^^^^^^^\n  File \"/Library/Frameworks/Python.framework/Versions/3.13/lib/python3.13/unittest/mock.py\", line 1226, in _execute_mock_call\n    raise effect\nrequests.exceptions.RequestException: Network Error", "trace_id": "N/A"}
{"timestamp": "2025-09-16T16:16:13.344814+09:00", "level": "ERROR", "name": "root", "message": "OpenWeatherMap API(35.68,139.69) 요청 중 오류: Network Error", "source": "openweathermap.py:53", "function": "get_weather_by_coords", "exc_info": "Traceback (most recent call last):\n  File \"/Users/gimhyeonmin/masamong/utils/api_handlers/openweathermap.py\", line 31, in get_weather_by_coords\n    response = await asyncio.to_thread(session.get, url, params=params, timeout=10)\n               ^^^^^^^^^^^^^^^^^^^^^^^^^^^^^^^^^^^^^^^^^^^^^^^^^^^^^^^^^^^^^^^^^^^^\n  File \"/Library/Frameworks/Python.framework/Versions/3.13/lib/python3.13/asyncio/threads.py\", line 25, in to_thread\n    return await loop.run_in_executor(None, func_call)\n           ^^^^^^^^^^^^^^^^^^^^^^^^^^^^^^^^^^^^^^^^^^^\n  File \"/Library/Frameworks/Python.framework/Versions/3.13/lib/python3.13/concurrent/futures/thread.py\", line 59, in run\n    result = self.fn(*self.args, **self.kwargs)\n  File \"/Library/Frameworks/Python.framework/Versions/3.13/lib/python3.13/unittest/mock.py\", line 1167, in __call__\n    return self._mock_call(*args, **kwargs)\n           ~~~~~~~~~~~~~~~^^^^^^^^^^^^^^^^^\n  File \"/Library/Frameworks/Python.framework/Versions/3.13/lib/python3.13/unittest/mock.py\", line 1171, in _mock_call\n    return self._execute_mock_call(*args, **kwargs)\n           ~~~~~~~~~~~~~~~~~~~~~~~^^^^^^^^^^^^^^^^^\n  File \"/Library/Frameworks/Python.framework/Versions/3.13/lib/python3.13/unittest/mock.py\", line 1226, in _execute_mock_call\n    raise effect\nrequests.exceptions.RequestException: Network Error", "trace_id": "N/A"}
{"timestamp": "2025-09-16T16:16:13.353824+09:00", "level": "ERROR", "name": "root", "message": "Ticketmaster API(35.68,139.69) 요청 중 오류: Network Error", "source": "ticketmaster.py:57", "function": "get_events_by_coords", "exc_info": "Traceback (most recent call last):\n  File \"/Users/gimhyeonmin/masamong/utils/api_handlers/ticketmaster.py\", line 37, in get_events_by_coords\n    response = await asyncio.to_thread(session.get, url, params=params, timeout=15)\n               ^^^^^^^^^^^^^^^^^^^^^^^^^^^^^^^^^^^^^^^^^^^^^^^^^^^^^^^^^^^^^^^^^^^^\n  File \"/Library/Frameworks/Python.framework/Versions/3.13/lib/python3.13/asyncio/threads.py\", line 25, in to_thread\n    return await loop.run_in_executor(None, func_call)\n           ^^^^^^^^^^^^^^^^^^^^^^^^^^^^^^^^^^^^^^^^^^^\n  File \"/Library/Frameworks/Python.framework/Versions/3.13/lib/python3.13/concurrent/futures/thread.py\", line 59, in run\n    result = self.fn(*self.args, **self.kwargs)\n  File \"/Library/Frameworks/Python.framework/Versions/3.13/lib/python3.13/unittest/mock.py\", line 1167, in __call__\n    return self._mock_call(*args, **kwargs)\n           ~~~~~~~~~~~~~~~^^^^^^^^^^^^^^^^^\n  File \"/Library/Frameworks/Python.framework/Versions/3.13/lib/python3.13/unittest/mock.py\", line 1171, in _mock_call\n    return self._execute_mock_call(*args, **kwargs)\n           ~~~~~~~~~~~~~~~~~~~~~~~^^^^^^^^^^^^^^^^^\n  File \"/Library/Frameworks/Python.framework/Versions/3.13/lib/python3.13/unittest/mock.py\", line 1226, in _execute_mock_call\n    raise effect\nrequests.exceptions.RequestException: Network Error", "trace_id": "N/A"}
{"timestamp": "2025-09-16T16:16:25.227175+09:00", "level": "ERROR", "name": "root", "message": "Foursquare API(35.68,139.69) 요청 중 오류: Network Error", "source": "foursquare.py:51", "function": "get_places_by_coords", "exc_info": "Traceback (most recent call last):\n  File \"/Users/gimhyeonmin/masamong/utils/api_handlers/foursquare.py\", line 33, in get_places_by_coords\n    response = await asyncio.to_thread(session.get, url, headers=headers, params=params, timeout=15)\n               ^^^^^^^^^^^^^^^^^^^^^^^^^^^^^^^^^^^^^^^^^^^^^^^^^^^^^^^^^^^^^^^^^^^^^^^^^^^^^^^^^^^^^\n  File \"/Library/Frameworks/Python.framework/Versions/3.13/lib/python3.13/asyncio/threads.py\", line 25, in to_thread\n    return await loop.run_in_executor(None, func_call)\n           ^^^^^^^^^^^^^^^^^^^^^^^^^^^^^^^^^^^^^^^^^^^\n  File \"/Library/Frameworks/Python.framework/Versions/3.13/lib/python3.13/concurrent/futures/thread.py\", line 59, in run\n    result = self.fn(*self.args, **self.kwargs)\n  File \"/Library/Frameworks/Python.framework/Versions/3.13/lib/python3.13/unittest/mock.py\", line 1167, in __call__\n    return self._mock_call(*args, **kwargs)\n           ~~~~~~~~~~~~~~~^^^^^^^^^^^^^^^^^\n  File \"/Library/Frameworks/Python.framework/Versions/3.13/lib/python3.13/unittest/mock.py\", line 1171, in _mock_call\n    return self._execute_mock_call(*args, **kwargs)\n           ~~~~~~~~~~~~~~~~~~~~~~~^^^^^^^^^^^^^^^^^\n  File \"/Library/Frameworks/Python.framework/Versions/3.13/lib/python3.13/unittest/mock.py\", line 1226, in _execute_mock_call\n    raise effect\nrequests.exceptions.RequestException: Network Error", "trace_id": "N/A"}
{"timestamp": "2025-09-16T16:16:29.675554+09:00", "level": "ERROR", "name": "root", "message": "OpenWeatherMap API(35.68,139.69) 요청 중 오류: Network Error", "source": "openweathermap.py:53", "function": "get_weather_by_coords", "exc_info": "Traceback (most recent call last):\n  File \"/Users/gimhyeonmin/masamong/utils/api_handlers/openweathermap.py\", line 31, in get_weather_by_coords\n    response = await asyncio.to_thread(session.get, url, params=params, timeout=10)\n               ^^^^^^^^^^^^^^^^^^^^^^^^^^^^^^^^^^^^^^^^^^^^^^^^^^^^^^^^^^^^^^^^^^^^\n  File \"/Library/Frameworks/Python.framework/Versions/3.13/lib/python3.13/asyncio/threads.py\", line 25, in to_thread\n    return await loop.run_in_executor(None, func_call)\n           ^^^^^^^^^^^^^^^^^^^^^^^^^^^^^^^^^^^^^^^^^^^\n  File \"/Library/Frameworks/Python.framework/Versions/3.13/lib/python3.13/concurrent/futures/thread.py\", line 59, in run\n    result = self.fn(*self.args, **self.kwargs)\n  File \"/Library/Frameworks/Python.framework/Versions/3.13/lib/python3.13/unittest/mock.py\", line 1167, in __call__\n    return self._mock_call(*args, **kwargs)\n           ~~~~~~~~~~~~~~~^^^^^^^^^^^^^^^^^\n  File \"/Library/Frameworks/Python.framework/Versions/3.13/lib/python3.13/unittest/mock.py\", line 1171, in _mock_call\n    return self._execute_mock_call(*args, **kwargs)\n           ~~~~~~~~~~~~~~~~~~~~~~~^^^^^^^^^^^^^^^^^\n  File \"/Library/Frameworks/Python.framework/Versions/3.13/lib/python3.13/unittest/mock.py\", line 1226, in _execute_mock_call\n    raise effect\nrequests.exceptions.RequestException: Network Error", "trace_id": "N/A"}
{"timestamp": "2025-09-16T16:16:29.685093+09:00", "level": "ERROR", "name": "root", "message": "Ticketmaster API(35.68,139.69) 요청 중 오류: Network Error", "source": "ticketmaster.py:57", "function": "get_events_by_coords", "exc_info": "Traceback (most recent call last):\n  File \"/Users/gimhyeonmin/masamong/utils/api_handlers/ticketmaster.py\", line 37, in get_events_by_coords\n    response = await asyncio.to_thread(session.get, url, params=params, timeout=15)\n               ^^^^^^^^^^^^^^^^^^^^^^^^^^^^^^^^^^^^^^^^^^^^^^^^^^^^^^^^^^^^^^^^^^^^\n  File \"/Library/Frameworks/Python.framework/Versions/3.13/lib/python3.13/asyncio/threads.py\", line 25, in to_thread\n    return await loop.run_in_executor(None, func_call)\n           ^^^^^^^^^^^^^^^^^^^^^^^^^^^^^^^^^^^^^^^^^^^\n  File \"/Library/Frameworks/Python.framework/Versions/3.13/lib/python3.13/concurrent/futures/thread.py\", line 59, in run\n    result = self.fn(*self.args, **self.kwargs)\n  File \"/Library/Frameworks/Python.framework/Versions/3.13/lib/python3.13/unittest/mock.py\", line 1167, in __call__\n    return self._mock_call(*args, **kwargs)\n           ~~~~~~~~~~~~~~~^^^^^^^^^^^^^^^^^\n  File \"/Library/Frameworks/Python.framework/Versions/3.13/lib/python3.13/unittest/mock.py\", line 1171, in _mock_call\n    return self._execute_mock_call(*args, **kwargs)\n           ~~~~~~~~~~~~~~~~~~~~~~~^^^^^^^^^^^^^^^^^\n  File \"/Library/Frameworks/Python.framework/Versions/3.13/lib/python3.13/unittest/mock.py\", line 1226, in _execute_mock_call\n    raise effect\nrequests.exceptions.RequestException: Network Error", "trace_id": "N/A"}
{"timestamp": "2025-09-16T16:25:54.909408+09:00", "level": "ERROR", "name": "root", "message": "Foursquare API(35.68,139.69) 요청 중 오류: Network Error", "source": "foursquare.py:51", "function": "get_places_by_coords", "exc_info": "Traceback (most recent call last):\n  File \"/Users/gimhyeonmin/masamong/utils/api_handlers/foursquare.py\", line 33, in get_places_by_coords\n    response = await asyncio.to_thread(session.get, url, headers=headers, params=params, timeout=15)\n               ^^^^^^^^^^^^^^^^^^^^^^^^^^^^^^^^^^^^^^^^^^^^^^^^^^^^^^^^^^^^^^^^^^^^^^^^^^^^^^^^^^^^^\n  File \"/Library/Frameworks/Python.framework/Versions/3.13/lib/python3.13/asyncio/threads.py\", line 25, in to_thread\n    return await loop.run_in_executor(None, func_call)\n           ^^^^^^^^^^^^^^^^^^^^^^^^^^^^^^^^^^^^^^^^^^^\n  File \"/Library/Frameworks/Python.framework/Versions/3.13/lib/python3.13/concurrent/futures/thread.py\", line 59, in run\n    result = self.fn(*self.args, **self.kwargs)\n  File \"/Library/Frameworks/Python.framework/Versions/3.13/lib/python3.13/unittest/mock.py\", line 1167, in __call__\n    return self._mock_call(*args, **kwargs)\n           ~~~~~~~~~~~~~~~^^^^^^^^^^^^^^^^^\n  File \"/Library/Frameworks/Python.framework/Versions/3.13/lib/python3.13/unittest/mock.py\", line 1171, in _mock_call\n    return self._execute_mock_call(*args, **kwargs)\n           ~~~~~~~~~~~~~~~~~~~~~~~^^^^^^^^^^^^^^^^^\n  File \"/Library/Frameworks/Python.framework/Versions/3.13/lib/python3.13/unittest/mock.py\", line 1226, in _execute_mock_call\n    raise effect\nrequests.exceptions.RequestException: Network Error", "trace_id": "N/A"}
{"timestamp": "2025-09-16T16:25:59.344605+09:00", "level": "ERROR", "name": "root", "message": "OpenWeatherMap API(35.68,139.69) 요청 중 오류: Network Error", "source": "openweathermap.py:53", "function": "get_weather_by_coords", "exc_info": "Traceback (most recent call last):\n  File \"/Users/gimhyeonmin/masamong/utils/api_handlers/openweathermap.py\", line 31, in get_weather_by_coords\n    response = await asyncio.to_thread(session.get, url, params=params, timeout=10)\n               ^^^^^^^^^^^^^^^^^^^^^^^^^^^^^^^^^^^^^^^^^^^^^^^^^^^^^^^^^^^^^^^^^^^^\n  File \"/Library/Frameworks/Python.framework/Versions/3.13/lib/python3.13/asyncio/threads.py\", line 25, in to_thread\n    return await loop.run_in_executor(None, func_call)\n           ^^^^^^^^^^^^^^^^^^^^^^^^^^^^^^^^^^^^^^^^^^^\n  File \"/Library/Frameworks/Python.framework/Versions/3.13/lib/python3.13/concurrent/futures/thread.py\", line 59, in run\n    result = self.fn(*self.args, **self.kwargs)\n  File \"/Library/Frameworks/Python.framework/Versions/3.13/lib/python3.13/unittest/mock.py\", line 1167, in __call__\n    return self._mock_call(*args, **kwargs)\n           ~~~~~~~~~~~~~~~^^^^^^^^^^^^^^^^^\n  File \"/Library/Frameworks/Python.framework/Versions/3.13/lib/python3.13/unittest/mock.py\", line 1171, in _mock_call\n    return self._execute_mock_call(*args, **kwargs)\n           ~~~~~~~~~~~~~~~~~~~~~~~^^^^^^^^^^^^^^^^^\n  File \"/Library/Frameworks/Python.framework/Versions/3.13/lib/python3.13/unittest/mock.py\", line 1226, in _execute_mock_call\n    raise effect\nrequests.exceptions.RequestException: Network Error", "trace_id": "N/A"}
{"timestamp": "2025-09-16T16:25:59.349478+09:00", "level": "ERROR", "name": "root", "message": "Ticketmaster API(35.68,139.69) 요청 중 오류: Network Error", "source": "ticketmaster.py:57", "function": "get_events_by_coords", "exc_info": "Traceback (most recent call last):\n  File \"/Users/gimhyeonmin/masamong/utils/api_handlers/ticketmaster.py\", line 37, in get_events_by_coords\n    response = await asyncio.to_thread(session.get, url, params=params, timeout=15)\n               ^^^^^^^^^^^^^^^^^^^^^^^^^^^^^^^^^^^^^^^^^^^^^^^^^^^^^^^^^^^^^^^^^^^^\n  File \"/Library/Frameworks/Python.framework/Versions/3.13/lib/python3.13/asyncio/threads.py\", line 25, in to_thread\n    return await loop.run_in_executor(None, func_call)\n           ^^^^^^^^^^^^^^^^^^^^^^^^^^^^^^^^^^^^^^^^^^^\n  File \"/Library/Frameworks/Python.framework/Versions/3.13/lib/python3.13/concurrent/futures/thread.py\", line 59, in run\n    result = self.fn(*self.args, **self.kwargs)\n  File \"/Library/Frameworks/Python.framework/Versions/3.13/lib/python3.13/unittest/mock.py\", line 1167, in __call__\n    return self._mock_call(*args, **kwargs)\n           ~~~~~~~~~~~~~~~^^^^^^^^^^^^^^^^^\n  File \"/Library/Frameworks/Python.framework/Versions/3.13/lib/python3.13/unittest/mock.py\", line 1171, in _mock_call\n    return self._execute_mock_call(*args, **kwargs)\n           ~~~~~~~~~~~~~~~~~~~~~~~^^^^^^^^^^^^^^^^^\n  File \"/Library/Frameworks/Python.framework/Versions/3.13/lib/python3.13/unittest/mock.py\", line 1226, in _execute_mock_call\n    raise effect\nrequests.exceptions.RequestException: Network Error", "trace_id": "N/A"}
{"timestamp": "2025-09-16T22:43:17.469941+09:00", "level": "ERROR", "name": "root", "message": "KRX API('삼성전자') 요청 중 오류: HTTPSConnectionPool(host='apis.data.go.kr', port=443): Max retries exceeded with url: /1160100/service/GetStockSecuritiesInfoService/getStockPriceInfo?serviceKey=m%2BjNX%2FMrO%2FJVlFzMEc%2BDL6Tjn1403dbgFk23bXD6jZcK0DAPPO0wue0rYrJlPXe%2F%2FvBKgRWoIbta%2FBVhiCfetQ%3D%3D&itmsNm=%EC%82%BC%EC%84%B1%EC%A0%84%EC%9E%90&resultType=json&numOfRows=1 (Caused by SSLError(SSLError(1, '[SSL: SSLV3_ALERT_ILLEGAL_PARAMETER] sslv3 alert illegal parameter (_ssl.c:1000)')))", "source": "krx.py:57", "function": "get_stock_price", "exc_info": "Traceback (most recent call last):\n  File \"/root/masamong/venv/lib/python3.12/site-packages/urllib3/connectionpool.py\", line 464, in _make_request\n    self._validate_conn(conn)\n  File \"/root/masamong/venv/lib/python3.12/site-packages/urllib3/connectionpool.py\", line 1093, in _validate_conn\n    conn.connect()\n  File \"/root/masamong/venv/lib/python3.12/site-packages/urllib3/connection.py\", line 790, in connect\n    sock_and_verified = _ssl_wrap_socket_and_match_hostname(\n                        ^^^^^^^^^^^^^^^^^^^^^^^^^^^^^^^^^^^^\n  File \"/root/masamong/venv/lib/python3.12/site-packages/urllib3/connection.py\", line 969, in _ssl_wrap_socket_and_match_hostname\n    ssl_sock = ssl_wrap_socket(\n               ^^^^^^^^^^^^^^^^\n  File \"/root/masamong/venv/lib/python3.12/site-packages/urllib3/util/ssl_.py\", line 480, in ssl_wrap_socket\n    ssl_sock = _ssl_wrap_socket_impl(sock, context, tls_in_tls, server_hostname)\n               ^^^^^^^^^^^^^^^^^^^^^^^^^^^^^^^^^^^^^^^^^^^^^^^^^^^^^^^^^^^^^^^^^\n  File \"/root/masamong/venv/lib/python3.12/site-packages/urllib3/util/ssl_.py\", line 524, in _ssl_wrap_socket_impl\n    return ssl_context.wrap_socket(sock, server_hostname=server_hostname)\n           ^^^^^^^^^^^^^^^^^^^^^^^^^^^^^^^^^^^^^^^^^^^^^^^^^^^^^^^^^^^^^^\n  File \"/usr/lib/python3.12/ssl.py\", line 455, in wrap_socket\n    return self.sslsocket_class._create(\n           ^^^^^^^^^^^^^^^^^^^^^^^^^^^^^\n  File \"/usr/lib/python3.12/ssl.py\", line 1042, in _create\n    self.do_handshake()\n  File \"/usr/lib/python3.12/ssl.py\", line 1320, in do_handshake\n    self._sslobj.do_handshake()\nssl.SSLError: [SSL: SSLV3_ALERT_ILLEGAL_PARAMETER] sslv3 alert illegal parameter (_ssl.c:1000)\n\nDuring handling of the above exception, another exception occurred:\n\nTraceback (most recent call last):\n  File \"/root/masamong/venv/lib/python3.12/site-packages/urllib3/connectionpool.py\", line 787, in urlopen\n    response = self._make_request(\n               ^^^^^^^^^^^^^^^^^^^\n  File \"/root/masamong/venv/lib/python3.12/site-packages/urllib3/connectionpool.py\", line 488, in _make_request\n    raise new_e\nurllib3.exceptions.SSLError: [SSL: SSLV3_ALERT_ILLEGAL_PARAMETER] sslv3 alert illegal parameter (_ssl.c:1000)\n\nThe above exception was the direct cause of the following exception:\n\nTraceback (most recent call last):\n  File \"/root/masamong/venv/lib/python3.12/site-packages/requests/adapters.py\", line 644, in send\n    resp = conn.urlopen(\n           ^^^^^^^^^^^^^\n  File \"/root/masamong/venv/lib/python3.12/site-packages/urllib3/connectionpool.py\", line 841, in urlopen\n    retries = retries.increment(\n              ^^^^^^^^^^^^^^^^^^\n  File \"/root/masamong/venv/lib/python3.12/site-packages/urllib3/util/retry.py\", line 519, in increment\n    raise MaxRetryError(_pool, url, reason) from reason  # type: ignore[arg-type]\n    ^^^^^^^^^^^^^^^^^^^^^^^^^^^^^^^^^^^^^^^^^^^^^^^^^^^\nurllib3.exceptions.MaxRetryError: HTTPSConnectionPool(host='apis.data.go.kr', port=443): Max retries exceeded with url: /1160100/service/GetStockSecuritiesInfoService/getStockPriceInfo?serviceKey=m%2BjNX%2FMrO%2FJVlFzMEc%2BDL6Tjn1403dbgFk23bXD6jZcK0DAPPO0wue0rYrJlPXe%2F%2FvBKgRWoIbta%2FBVhiCfetQ%3D%3D&itmsNm=%EC%82%BC%EC%84%B1%EC%A0%84%EC%9E%90&resultType=json&numOfRows=1 (Caused by SSLError(SSLError(1, '[SSL: SSLV3_ALERT_ILLEGAL_PARAMETER] sslv3 alert illegal parameter (_ssl.c:1000)')))\n\nDuring handling of the above exception, another exception occurred:\n\nTraceback (most recent call last):\n  File \"/root/masamong/utils/api_handlers/krx.py\", line 38, in get_stock_price\n    response = await asyncio.to_thread(session.get, config.KRX_BASE_URL, params=params, timeout=10)\n               ^^^^^^^^^^^^^^^^^^^^^^^^^^^^^^^^^^^^^^^^^^^^^^^^^^^^^^^^^^^^^^^^^^^^^^^^^^^^^^^^^^^^\n  File \"/usr/lib/python3.12/asyncio/threads.py\", line 25, in to_thread\n    return await loop.run_in_executor(None, func_call)\n           ^^^^^^^^^^^^^^^^^^^^^^^^^^^^^^^^^^^^^^^^^^^\n  File \"/usr/lib/python3.12/concurrent/futures/thread.py\", line 58, in run\n    result = self.fn(*self.args, **self.kwargs)\n             ^^^^^^^^^^^^^^^^^^^^^^^^^^^^^^^^^^\n  File \"/root/masamong/venv/lib/python3.12/site-packages/requests/sessions.py\", line 602, in get\n    return self.request(\"GET\", url, **kwargs)\n           ^^^^^^^^^^^^^^^^^^^^^^^^^^^^^^^^^^\n  File \"/root/masamong/venv/lib/python3.12/site-packages/requests/sessions.py\", line 589, in request\n    resp = self.send(prep, **send_kwargs)\n           ^^^^^^^^^^^^^^^^^^^^^^^^^^^^^^\n  File \"/root/masamong/venv/lib/python3.12/site-packages/requests/sessions.py\", line 703, in send\n    r = adapter.send(request, **kwargs)\n        ^^^^^^^^^^^^^^^^^^^^^^^^^^^^^^^\n  File \"/root/masamong/venv/lib/python3.12/site-packages/requests/adapters.py\", line 675, in send\n    raise SSLError(e, request=request)\nrequests.exceptions.SSLError: HTTPSConnectionPool(host='apis.data.go.kr', port=443): Max retries exceeded with url: /1160100/service/GetStockSecuritiesInfoService/getStockPriceInfo?serviceKey=m%2BjNX%2FMrO%2FJVlFzMEc%2BDL6Tjn1403dbgFk23bXD6jZcK0DAPPO0wue0rYrJlPXe%2F%2FvBKgRWoIbta%2FBVhiCfetQ%3D%3D&itmsNm=%EC%82%BC%EC%84%B1%EC%A0%84%EC%9E%90&resultType=json&numOfRows=1 (Caused by SSLError(SSLError(1, '[SSL: SSLV3_ALERT_ILLEGAL_PARAMETER] sslv3 alert illegal parameter (_ssl.c:1000)')))", "trace_id": "N/A"}
{"timestamp": "2025-09-16T22:43:46.465256+09:00", "level": "ERROR", "name": "root", "message": "KRX API('애플') 요청 중 오류: HTTPSConnectionPool(host='apis.data.go.kr', port=443): Max retries exceeded with url: /1160100/service/GetStockSecuritiesInfoService/getStockPriceInfo?serviceKey=m%2BjNX%2FMrO%2FJVlFzMEc%2BDL6Tjn1403dbgFk23bXD6jZcK0DAPPO0wue0rYrJlPXe%2F%2FvBKgRWoIbta%2FBVhiCfetQ%3D%3D&itmsNm=%EC%95%A0%ED%94%8C&resultType=json&numOfRows=1 (Caused by SSLError(SSLError(1, '[SSL: SSLV3_ALERT_ILLEGAL_PARAMETER] sslv3 alert illegal parameter (_ssl.c:1000)')))", "source": "krx.py:57", "function": "get_stock_price", "exc_info": "Traceback (most recent call last):\n  File \"/root/masamong/venv/lib/python3.12/site-packages/urllib3/connectionpool.py\", line 464, in _make_request\n    self._validate_conn(conn)\n  File \"/root/masamong/venv/lib/python3.12/site-packages/urllib3/connectionpool.py\", line 1093, in _validate_conn\n    conn.connect()\n  File \"/root/masamong/venv/lib/python3.12/site-packages/urllib3/connection.py\", line 790, in connect\n    sock_and_verified = _ssl_wrap_socket_and_match_hostname(\n                        ^^^^^^^^^^^^^^^^^^^^^^^^^^^^^^^^^^^^\n  File \"/root/masamong/venv/lib/python3.12/site-packages/urllib3/connection.py\", line 969, in _ssl_wrap_socket_and_match_hostname\n    ssl_sock = ssl_wrap_socket(\n               ^^^^^^^^^^^^^^^^\n  File \"/root/masamong/venv/lib/python3.12/site-packages/urllib3/util/ssl_.py\", line 480, in ssl_wrap_socket\n    ssl_sock = _ssl_wrap_socket_impl(sock, context, tls_in_tls, server_hostname)\n               ^^^^^^^^^^^^^^^^^^^^^^^^^^^^^^^^^^^^^^^^^^^^^^^^^^^^^^^^^^^^^^^^^\n  File \"/root/masamong/venv/lib/python3.12/site-packages/urllib3/util/ssl_.py\", line 524, in _ssl_wrap_socket_impl\n    return ssl_context.wrap_socket(sock, server_hostname=server_hostname)\n           ^^^^^^^^^^^^^^^^^^^^^^^^^^^^^^^^^^^^^^^^^^^^^^^^^^^^^^^^^^^^^^\n  File \"/usr/lib/python3.12/ssl.py\", line 455, in wrap_socket\n    return self.sslsocket_class._create(\n           ^^^^^^^^^^^^^^^^^^^^^^^^^^^^^\n  File \"/usr/lib/python3.12/ssl.py\", line 1042, in _create\n    self.do_handshake()\n  File \"/usr/lib/python3.12/ssl.py\", line 1320, in do_handshake\n    self._sslobj.do_handshake()\nssl.SSLError: [SSL: SSLV3_ALERT_ILLEGAL_PARAMETER] sslv3 alert illegal parameter (_ssl.c:1000)\n\nDuring handling of the above exception, another exception occurred:\n\nTraceback (most recent call last):\n  File \"/root/masamong/venv/lib/python3.12/site-packages/urllib3/connectionpool.py\", line 787, in urlopen\n    response = self._make_request(\n               ^^^^^^^^^^^^^^^^^^^\n  File \"/root/masamong/venv/lib/python3.12/site-packages/urllib3/connectionpool.py\", line 488, in _make_request\n    raise new_e\nurllib3.exceptions.SSLError: [SSL: SSLV3_ALERT_ILLEGAL_PARAMETER] sslv3 alert illegal parameter (_ssl.c:1000)\n\nThe above exception was the direct cause of the following exception:\n\nTraceback (most recent call last):\n  File \"/root/masamong/venv/lib/python3.12/site-packages/requests/adapters.py\", line 644, in send\n    resp = conn.urlopen(\n           ^^^^^^^^^^^^^\n  File \"/root/masamong/venv/lib/python3.12/site-packages/urllib3/connectionpool.py\", line 841, in urlopen\n    retries = retries.increment(\n              ^^^^^^^^^^^^^^^^^^\n  File \"/root/masamong/venv/lib/python3.12/site-packages/urllib3/util/retry.py\", line 519, in increment\n    raise MaxRetryError(_pool, url, reason) from reason  # type: ignore[arg-type]\n    ^^^^^^^^^^^^^^^^^^^^^^^^^^^^^^^^^^^^^^^^^^^^^^^^^^^\nurllib3.exceptions.MaxRetryError: HTTPSConnectionPool(host='apis.data.go.kr', port=443): Max retries exceeded with url: /1160100/service/GetStockSecuritiesInfoService/getStockPriceInfo?serviceKey=m%2BjNX%2FMrO%2FJVlFzMEc%2BDL6Tjn1403dbgFk23bXD6jZcK0DAPPO0wue0rYrJlPXe%2F%2FvBKgRWoIbta%2FBVhiCfetQ%3D%3D&itmsNm=%EC%95%A0%ED%94%8C&resultType=json&numOfRows=1 (Caused by SSLError(SSLError(1, '[SSL: SSLV3_ALERT_ILLEGAL_PARAMETER] sslv3 alert illegal parameter (_ssl.c:1000)')))\n\nDuring handling of the above exception, another exception occurred:\n\nTraceback (most recent call last):\n  File \"/root/masamong/utils/api_handlers/krx.py\", line 38, in get_stock_price\n    response = await asyncio.to_thread(session.get, config.KRX_BASE_URL, params=params, timeout=10)\n               ^^^^^^^^^^^^^^^^^^^^^^^^^^^^^^^^^^^^^^^^^^^^^^^^^^^^^^^^^^^^^^^^^^^^^^^^^^^^^^^^^^^^\n  File \"/usr/lib/python3.12/asyncio/threads.py\", line 25, in to_thread\n    return await loop.run_in_executor(None, func_call)\n           ^^^^^^^^^^^^^^^^^^^^^^^^^^^^^^^^^^^^^^^^^^^\n  File \"/usr/lib/python3.12/concurrent/futures/thread.py\", line 58, in run\n    result = self.fn(*self.args, **self.kwargs)\n             ^^^^^^^^^^^^^^^^^^^^^^^^^^^^^^^^^^\n  File \"/root/masamong/venv/lib/python3.12/site-packages/requests/sessions.py\", line 602, in get\n    return self.request(\"GET\", url, **kwargs)\n           ^^^^^^^^^^^^^^^^^^^^^^^^^^^^^^^^^^\n  File \"/root/masamong/venv/lib/python3.12/site-packages/requests/sessions.py\", line 589, in request\n    resp = self.send(prep, **send_kwargs)\n           ^^^^^^^^^^^^^^^^^^^^^^^^^^^^^^\n  File \"/root/masamong/venv/lib/python3.12/site-packages/requests/sessions.py\", line 703, in send\n    r = adapter.send(request, **kwargs)\n        ^^^^^^^^^^^^^^^^^^^^^^^^^^^^^^^\n  File \"/root/masamong/venv/lib/python3.12/site-packages/requests/adapters.py\", line 675, in send\n    raise SSLError(e, request=request)\nrequests.exceptions.SSLError: HTTPSConnectionPool(host='apis.data.go.kr', port=443): Max retries exceeded with url: /1160100/service/GetStockSecuritiesInfoService/getStockPriceInfo?serviceKey=m%2BjNX%2FMrO%2FJVlFzMEc%2BDL6Tjn1403dbgFk23bXD6jZcK0DAPPO0wue0rYrJlPXe%2F%2FvBKgRWoIbta%2FBVhiCfetQ%3D%3D&itmsNm=%EC%95%A0%ED%94%8C&resultType=json&numOfRows=1 (Caused by SSLError(SSLError(1, '[SSL: SSLV3_ALERT_ILLEGAL_PARAMETER] sslv3 alert illegal parameter (_ssl.c:1000)')))", "trace_id": "N/A"}
{"timestamp": "2025-09-16T22:44:36.764182+09:00", "level": "ERROR", "name": "root", "message": "Foursquare API(35.6895,139.6917) 요청 중 오류: ('Connection broken: IncompleteRead(0 bytes read, 36 more expected)', IncompleteRead(0 bytes read, 36 more expected))", "source": "foursquare.py:51", "function": "get_places_by_coords", "exc_info": "Traceback (most recent call last):\n  File \"/root/masamong/venv/lib/python3.12/site-packages/urllib3/response.py\", line 779, in _error_catcher\n    yield\n  File \"/root/masamong/venv/lib/python3.12/site-packages/urllib3/response.py\", line 925, in _raw_read\n    raise IncompleteRead(self._fp_bytes_read, self.length_remaining)\nurllib3.exceptions.IncompleteRead: IncompleteRead(0 bytes read, 36 more expected)\n\nThe above exception was the direct cause of the following exception:\n\nTraceback (most recent call last):\n  File \"/root/masamong/venv/lib/python3.12/site-packages/requests/models.py\", line 820, in generate\n    yield from self.raw.stream(chunk_size, decode_content=True)\n  File \"/root/masamong/venv/lib/python3.12/site-packages/urllib3/response.py\", line 1091, in stream\n    data = self.read(amt=amt, decode_content=decode_content)\n           ^^^^^^^^^^^^^^^^^^^^^^^^^^^^^^^^^^^^^^^^^^^^^^^^^\n  File \"/root/masamong/venv/lib/python3.12/site-packages/urllib3/response.py\", line 980, in read\n    data = self._raw_read(amt)\n           ^^^^^^^^^^^^^^^^^^^\n  File \"/root/masamong/venv/lib/python3.12/site-packages/urllib3/response.py\", line 903, in _raw_read\n    with self._error_catcher():\n  File \"/usr/lib/python3.12/contextlib.py\", line 158, in __exit__\n    self.gen.throw(value)\n  File \"/root/masamong/venv/lib/python3.12/site-packages/urllib3/response.py\", line 803, in _error_catcher\n    raise ProtocolError(arg, e) from e\nurllib3.exceptions.ProtocolError: ('Connection broken: IncompleteRead(0 bytes read, 36 more expected)', IncompleteRead(0 bytes read, 36 more expected))\n\nDuring handling of the above exception, another exception occurred:\n\nTraceback (most recent call last):\n  File \"/root/masamong/utils/api_handlers/foursquare.py\", line 33, in get_places_by_coords\n    response = await asyncio.to_thread(session.get, url, headers=headers, params=params, timeout=15)\n               ^^^^^^^^^^^^^^^^^^^^^^^^^^^^^^^^^^^^^^^^^^^^^^^^^^^^^^^^^^^^^^^^^^^^^^^^^^^^^^^^^^^^^\n  File \"/usr/lib/python3.12/asyncio/threads.py\", line 25, in to_thread\n    return await loop.run_in_executor(None, func_call)\n           ^^^^^^^^^^^^^^^^^^^^^^^^^^^^^^^^^^^^^^^^^^^\n  File \"/usr/lib/python3.12/concurrent/futures/thread.py\", line 58, in run\n    result = self.fn(*self.args, **self.kwargs)\n             ^^^^^^^^^^^^^^^^^^^^^^^^^^^^^^^^^^\n  File \"/root/masamong/venv/lib/python3.12/site-packages/requests/sessions.py\", line 602, in get\n    return self.request(\"GET\", url, **kwargs)\n           ^^^^^^^^^^^^^^^^^^^^^^^^^^^^^^^^^^\n  File \"/root/masamong/venv/lib/python3.12/site-packages/requests/sessions.py\", line 589, in request\n    resp = self.send(prep, **send_kwargs)\n           ^^^^^^^^^^^^^^^^^^^^^^^^^^^^^^\n  File \"/root/masamong/venv/lib/python3.12/site-packages/requests/sessions.py\", line 746, in send\n    r.content\n  File \"/root/masamong/venv/lib/python3.12/site-packages/requests/models.py\", line 902, in content\n    self._content = b\"\".join(self.iter_content(CONTENT_CHUNK_SIZE)) or b\"\"\n                    ^^^^^^^^^^^^^^^^^^^^^^^^^^^^^^^^^^^^^^^^^^^^^^^\n  File \"/root/masamong/venv/lib/python3.12/site-packages/requests/models.py\", line 822, in generate\n    raise ChunkedEncodingError(e)\nrequests.exceptions.ChunkedEncodingError: ('Connection broken: IncompleteRead(0 bytes read, 36 more expected)', IncompleteRead(0 bytes read, 36 more expected))", "trace_id": "N/A"}
{"timestamp": "2025-09-16T22:53:19.295254+09:00", "level": "ERROR", "name": "root", "message": "Foursquare API(37.5665,126.978) 요청 중 오류: 401 Client Error: Unauthorized for url: https://api.foursquare.com/v3/places/search?ll=37.5665%2C126.978&limit=10&sort=RELEVANCE&query=%EC%84%9C%EC%9A%B8+%EC%B6%94%EC%B2%9C+%EC%9E%A5%EC%86%8C", "source": "foursquare.py:53", "function": "get_places_by_coords", "exc_info": "Traceback (most recent call last):\n  File \"/root/masamong/utils/api_handlers/foursquare.py\", line 36, in get_places_by_coords\n    response.raise_for_status()\n  File \"/root/masamong/venv/lib/python3.12/site-packages/requests/models.py\", line 1026, in raise_for_status\n    raise HTTPError(http_error_msg, response=self)\nrequests.exceptions.HTTPError: 401 Client Error: Unauthorized for url: https://api.foursquare.com/v3/places/search?ll=37.5665%2C126.978&limit=10&sort=RELEVANCE&query=%EC%84%9C%EC%9A%B8+%EC%B6%94%EC%B2%9C+%EC%9E%A5%EC%86%8C", "trace_id": "N/A"}
{"timestamp": "2025-09-16T22:54:07.782596+09:00", "level": "ERROR", "name": "root", "message": "Foursquare API(35.6895,139.6917) 요청 중 오류: 401 Client Error: Unauthorized for url: https://api.foursquare.com/v3/places/search?ll=35.6895%2C139.6917&limit=10&sort=RELEVANCE&query=%EA%B4%80%EA%B4%91%EC%A7%80", "source": "foursquare.py:53", "function": "get_places_by_coords", "exc_info": "Traceback (most recent call last):\n  File \"/root/masamong/utils/api_handlers/foursquare.py\", line 36, in get_places_by_coords\n    response.raise_for_status()\n  File \"/root/masamong/venv/lib/python3.12/site-packages/requests/models.py\", line 1026, in raise_for_status\n    raise HTTPError(http_error_msg, response=self)\nrequests.exceptions.HTTPError: 401 Client Error: Unauthorized for url: https://api.foursquare.com/v3/places/search?ll=35.6895%2C139.6917&limit=10&sort=RELEVANCE&query=%EA%B4%80%EA%B4%91%EC%A7%80", "trace_id": "N/A"}
{"timestamp": "2025-09-16T22:57:51.599698+09:00", "level": "ERROR", "name": "root", "message": "Foursquare API(34.9576,127.6715) 요청 중 오류: 401 Client Error: Unauthorized for url: https://api.foursquare.com/v3/places/search?ll=34.9576%2C127.6715&limit=10&sort=RELEVANCE&query=%EA%B4%80%EA%B4%91%EC%A7%80", "source": "foursquare.py:53", "function": "get_places_by_coords", "exc_info": "Traceback (most recent call last):\n  File \"/root/masamong/utils/api_handlers/foursquare.py\", line 36, in get_places_by_coords\n    response.raise_for_status()\n  File \"/root/masamong/venv/lib/python3.12/site-packages/requests/models.py\", line 1026, in raise_for_status\n    raise HTTPError(http_error_msg, response=self)\nrequests.exceptions.HTTPError: 401 Client Error: Unauthorized for url: https://api.foursquare.com/v3/places/search?ll=34.9576%2C127.6715&limit=10&sort=RELEVANCE&query=%EA%B4%80%EA%B4%91%EC%A7%80", "trace_id": "N/A"}
{"timestamp": "2025-09-16T22:57:52.031910+09:00", "level": "ERROR", "name": "root", "message": "Foursquare API(34.9576,127.6715) 요청 중 오류: 401 Client Error: Unauthorized for url: https://api.foursquare.com/v3/places/search?ll=34.9576%2C127.6715&limit=10&sort=RELEVANCE&query=%EB%A7%9B%EC%A7%91", "source": "foursquare.py:53", "function": "get_places_by_coords", "exc_info": "Traceback (most recent call last):\n  File \"/root/masamong/utils/api_handlers/foursquare.py\", line 36, in get_places_by_coords\n    response.raise_for_status()\n  File \"/root/masamong/venv/lib/python3.12/site-packages/requests/models.py\", line 1026, in raise_for_status\n    raise HTTPError(http_error_msg, response=self)\nrequests.exceptions.HTTPError: 401 Client Error: Unauthorized for url: https://api.foursquare.com/v3/places/search?ll=34.9576%2C127.6715&limit=10&sort=RELEVANCE&query=%EB%A7%9B%EC%A7%91", "trace_id": "N/A"}
{"timestamp": "2025-09-16T23:23:08.813579+09:00", "level": "ERROR", "name": "root", "message": "Ticketmaster API(35.6895,139.6917) 요청 중 오류: 401 Client Error: Unauthorized for url: https://app.ticketmaster.com/discovery/v2/events.json?apikey=SHMPI5CHVLUUAMZEM5H1ZRAACCQSI2CSDLAV1A1REJNQ3DNT&latlong=35.6895%2C139.6917&radius=50&unit=km&startDateTime=2025-09-16T14%3A23%3A07Z&endDateTime=2025-10-16T14%3A23%3A07Z&sort=date%2Casc", "source": "ticketmaster.py:57", "function": "get_events_by_coords", "exc_info": "Traceback (most recent call last):\n  File \"/root/masamong/utils/api_handlers/ticketmaster.py\", line 38, in get_events_by_coords\n    response.raise_for_status()\n  File \"/root/masamong/venv/lib/python3.12/site-packages/requests/models.py\", line 1026, in raise_for_status\n    raise HTTPError(http_error_msg, response=self)\nrequests.exceptions.HTTPError: 401 Client Error: Unauthorized for url: https://app.ticketmaster.com/discovery/v2/events.json?apikey=SHMPI5CHVLUUAMZEM5H1ZRAACCQSI2CSDLAV1A1REJNQ3DNT&latlong=35.6895%2C139.6917&radius=50&unit=km&startDateTime=2025-09-16T14%3A23%3A07Z&endDateTime=2025-10-16T14%3A23%3A07Z&sort=date%2Casc", "trace_id": "N/A"}
{"timestamp": "2025-09-16T23:24:43.224809+09:00", "level": "ERROR", "name": "root", "message": "Ticketmaster API(37.5665,126.978) 요청 중 오류: 401 Client Error: Unauthorized for url: https://app.ticketmaster.com/discovery/v2/events.json?apikey=SHMPI5CHVLUUAMZEM5H1ZRAACCQSI2CSDLAV1A1REJNQ3DNT&latlong=37.5665%2C126.978&radius=50&unit=km&startDateTime=2025-09-16T14%3A24%3A42Z&endDateTime=2025-10-16T14%3A24%3A42Z&sort=date%2Casc", "source": "ticketmaster.py:57", "function": "get_events_by_coords", "exc_info": "Traceback (most recent call last):\n  File \"/root/masamong/utils/api_handlers/ticketmaster.py\", line 38, in get_events_by_coords\n    response.raise_for_status()\n  File \"/root/masamong/venv/lib/python3.12/site-packages/requests/models.py\", line 1026, in raise_for_status\n    raise HTTPError(http_error_msg, response=self)\nrequests.exceptions.HTTPError: 401 Client Error: Unauthorized for url: https://app.ticketmaster.com/discovery/v2/events.json?apikey=SHMPI5CHVLUUAMZEM5H1ZRAACCQSI2CSDLAV1A1REJNQ3DNT&latlong=37.5665%2C126.978&radius=50&unit=km&startDateTime=2025-09-16T14%3A24%3A42Z&endDateTime=2025-10-16T14%3A24%3A42Z&sort=date%2Casc", "trace_id": "N/A"}
{"timestamp": "2025-09-16T23:29:22.786846+09:00", "level": "ERROR", "name": "root", "message": "Foursquare API(35.6895,139.6917) 요청 중 오류: ('Connection broken: IncompleteRead(0 bytes read, 36 more expected)', IncompleteRead(0 bytes read, 36 more expected))", "source": "foursquare.py:53", "function": "get_places_by_coords", "exc_info": "Traceback (most recent call last):\n  File \"/root/masamong/venv/lib/python3.12/site-packages/urllib3/response.py\", line 779, in _error_catcher\n    yield\n  File \"/root/masamong/venv/lib/python3.12/site-packages/urllib3/response.py\", line 925, in _raw_read\n    raise IncompleteRead(self._fp_bytes_read, self.length_remaining)\nurllib3.exceptions.IncompleteRead: IncompleteRead(0 bytes read, 36 more expected)\n\nThe above exception was the direct cause of the following exception:\n\nTraceback (most recent call last):\n  File \"/root/masamong/venv/lib/python3.12/site-packages/requests/models.py\", line 820, in generate\n    yield from self.raw.stream(chunk_size, decode_content=True)\n  File \"/root/masamong/venv/lib/python3.12/site-packages/urllib3/response.py\", line 1091, in stream\n    data = self.read(amt=amt, decode_content=decode_content)\n           ^^^^^^^^^^^^^^^^^^^^^^^^^^^^^^^^^^^^^^^^^^^^^^^^^\n  File \"/root/masamong/venv/lib/python3.12/site-packages/urllib3/response.py\", line 980, in read\n    data = self._raw_read(amt)\n           ^^^^^^^^^^^^^^^^^^^\n  File \"/root/masamong/venv/lib/python3.12/site-packages/urllib3/response.py\", line 903, in _raw_read\n    with self._error_catcher():\n  File \"/usr/lib/python3.12/contextlib.py\", line 158, in __exit__\n    self.gen.throw(value)\n  File \"/root/masamong/venv/lib/python3.12/site-packages/urllib3/response.py\", line 803, in _error_catcher\n    raise ProtocolError(arg, e) from e\nurllib3.exceptions.ProtocolError: ('Connection broken: IncompleteRead(0 bytes read, 36 more expected)', IncompleteRead(0 bytes read, 36 more expected))\n\nDuring handling of the above exception, another exception occurred:\n\nTraceback (most recent call last):\n  File \"/root/masamong/utils/api_handlers/foursquare.py\", line 35, in get_places_by_coords\n    response = await asyncio.to_thread(session.get, url, headers=headers, params=params, timeout=15)\n               ^^^^^^^^^^^^^^^^^^^^^^^^^^^^^^^^^^^^^^^^^^^^^^^^^^^^^^^^^^^^^^^^^^^^^^^^^^^^^^^^^^^^^\n  File \"/usr/lib/python3.12/asyncio/threads.py\", line 25, in to_thread\n    return await loop.run_in_executor(None, func_call)\n           ^^^^^^^^^^^^^^^^^^^^^^^^^^^^^^^^^^^^^^^^^^^\n  File \"/usr/lib/python3.12/concurrent/futures/thread.py\", line 58, in run\n    result = self.fn(*self.args, **self.kwargs)\n             ^^^^^^^^^^^^^^^^^^^^^^^^^^^^^^^^^^\n  File \"/root/masamong/venv/lib/python3.12/site-packages/requests/sessions.py\", line 602, in get\n    return self.request(\"GET\", url, **kwargs)\n           ^^^^^^^^^^^^^^^^^^^^^^^^^^^^^^^^^^\n  File \"/root/masamong/venv/lib/python3.12/site-packages/requests/sessions.py\", line 589, in request\n    resp = self.send(prep, **send_kwargs)\n           ^^^^^^^^^^^^^^^^^^^^^^^^^^^^^^\n  File \"/root/masamong/venv/lib/python3.12/site-packages/requests/sessions.py\", line 746, in send\n    r.content\n  File \"/root/masamong/venv/lib/python3.12/site-packages/requests/models.py\", line 902, in content\n    self._content = b\"\".join(self.iter_content(CONTENT_CHUNK_SIZE)) or b\"\"\n                    ^^^^^^^^^^^^^^^^^^^^^^^^^^^^^^^^^^^^^^^^^^^^^^^\n  File \"/root/masamong/venv/lib/python3.12/site-packages/requests/models.py\", line 822, in generate\n    raise ChunkedEncodingError(e)\nrequests.exceptions.ChunkedEncodingError: ('Connection broken: IncompleteRead(0 bytes read, 36 more expected)', IncompleteRead(0 bytes read, 36 more expected))", "trace_id": "N/A"}
{"timestamp": "2025-09-16T23:30:23.316042+09:00", "level": "ERROR", "name": "root", "message": "Foursquare API(37.5665,126.978) 요청 중 오류: 401 Client Error: Unauthorized for url: https://api.foursquare.com/v3/places/search?ll=37.5665%2C126.978&limit=10&sort=RELEVANCE&query=%EC%8B%A0%EB%82%98%EB%8A%94+%EC%9E%A5%EC%86%8C", "source": "foursquare.py:53", "function": "get_places_by_coords", "exc_info": "Traceback (most recent call last):\n  File \"/root/masamong/utils/api_handlers/foursquare.py\", line 36, in get_places_by_coords\n    response.raise_for_status()\n  File \"/root/masamong/venv/lib/python3.12/site-packages/requests/models.py\", line 1026, in raise_for_status\n    raise HTTPError(http_error_msg, response=self)\nrequests.exceptions.HTTPError: 401 Client Error: Unauthorized for url: https://api.foursquare.com/v3/places/search?ll=37.5665%2C126.978&limit=10&sort=RELEVANCE&query=%EC%8B%A0%EB%82%98%EB%8A%94+%EC%9E%A5%EC%86%8C", "trace_id": "N/A"}
{"timestamp": "2025-09-16T23:42:11.345686+09:00", "level": "ERROR", "name": "root", "message": "RAWG API 처리 중 예기치 않은 오류: 'NoneType' object is not iterable", "source": "rawg.py:92", "function": "get_games", "exc_info": "Traceback (most recent call last):\n  File \"/root/masamong/utils/api_handlers/rawg.py\", line 78, in get_games\n    \"stores\": [store['store']['name'] for store in game.get('stores', []) if store.get('store')]\n              ^^^^^^^^^^^^^^^^^^^^^^^^^^^^^^^^^^^^^^^^^^^^^^^^^^^^^^^^^^^^^^^^^^^^^^^^^^^^^^^^^^\nTypeError: 'NoneType' object is not iterable", "trace_id": "N/A"}
{"timestamp": "2025-09-17T14:44:54.726770+09:00", "level": "ERROR", "name": "root", "message": "RAWG API 처리 중 예기치 않은 오류: 'NoneType' object is not iterable", "source": "rawg.py:92", "function": "get_games", "exc_info": "Traceback (most recent call last):\n  File \"/root/masamong/utils/api_handlers/rawg.py\", line 78, in get_games\n    \"stores\": [store['store']['name'] for store in game.get('stores', []) if store.get('store')]\n              ^^^^^^^^^^^^^^^^^^^^^^^^^^^^^^^^^^^^^^^^^^^^^^^^^^^^^^^^^^^^^^^^^^^^^^^^^^^^^^^^^^\nTypeError: 'NoneType' object is not iterable", "trace_id": "N/A"}
{"timestamp": "2025-09-18T03:34:35.805162+09:00", "level": "ERROR", "name": "root", "message": "Foursquare API(35.68,139.69) 요청 중 오류: Network Error", "source": "foursquare.py:53", "function": "get_places_by_coords", "exc_info": "Traceback (most recent call last):\n  File \"/Users/gimhyeonmin/masamong/utils/api_handlers/foursquare.py\", line 35, in get_places_by_coords\n    response = await asyncio.to_thread(session.get, url, headers=headers, params=params, timeout=15)\n               ^^^^^^^^^^^^^^^^^^^^^^^^^^^^^^^^^^^^^^^^^^^^^^^^^^^^^^^^^^^^^^^^^^^^^^^^^^^^^^^^^^^^^\n  File \"/Library/Frameworks/Python.framework/Versions/3.13/lib/python3.13/asyncio/threads.py\", line 25, in to_thread\n    return await loop.run_in_executor(None, func_call)\n           ^^^^^^^^^^^^^^^^^^^^^^^^^^^^^^^^^^^^^^^^^^^\n  File \"/Library/Frameworks/Python.framework/Versions/3.13/lib/python3.13/concurrent/futures/thread.py\", line 59, in run\n    result = self.fn(*self.args, **self.kwargs)\n  File \"/Library/Frameworks/Python.framework/Versions/3.13/lib/python3.13/unittest/mock.py\", line 1167, in __call__\n    return self._mock_call(*args, **kwargs)\n           ~~~~~~~~~~~~~~~^^^^^^^^^^^^^^^^^\n  File \"/Library/Frameworks/Python.framework/Versions/3.13/lib/python3.13/unittest/mock.py\", line 1171, in _mock_call\n    return self._execute_mock_call(*args, **kwargs)\n           ~~~~~~~~~~~~~~~~~~~~~~~^^^^^^^^^^^^^^^^^\n  File \"/Library/Frameworks/Python.framework/Versions/3.13/lib/python3.13/unittest/mock.py\", line 1226, in _execute_mock_call\n    raise effect\nrequests.exceptions.RequestException: Network Error", "trace_id": "N/A"}
{"timestamp": "2025-09-18T03:34:40.238097+09:00", "level": "ERROR", "name": "root", "message": "OpenWeatherMap API(35.68,139.69) 요청 중 오류: Network Error", "source": "openweathermap.py:53", "function": "get_weather_by_coords", "exc_info": "Traceback (most recent call last):\n  File \"/Users/gimhyeonmin/masamong/utils/api_handlers/openweathermap.py\", line 31, in get_weather_by_coords\n    response = await asyncio.to_thread(session.get, url, params=params, timeout=10)\n               ^^^^^^^^^^^^^^^^^^^^^^^^^^^^^^^^^^^^^^^^^^^^^^^^^^^^^^^^^^^^^^^^^^^^\n  File \"/Library/Frameworks/Python.framework/Versions/3.13/lib/python3.13/asyncio/threads.py\", line 25, in to_thread\n    return await loop.run_in_executor(None, func_call)\n           ^^^^^^^^^^^^^^^^^^^^^^^^^^^^^^^^^^^^^^^^^^^\n  File \"/Library/Frameworks/Python.framework/Versions/3.13/lib/python3.13/concurrent/futures/thread.py\", line 59, in run\n    result = self.fn(*self.args, **self.kwargs)\n  File \"/Library/Frameworks/Python.framework/Versions/3.13/lib/python3.13/unittest/mock.py\", line 1167, in __call__\n    return self._mock_call(*args, **kwargs)\n           ~~~~~~~~~~~~~~~^^^^^^^^^^^^^^^^^\n  File \"/Library/Frameworks/Python.framework/Versions/3.13/lib/python3.13/unittest/mock.py\", line 1171, in _mock_call\n    return self._execute_mock_call(*args, **kwargs)\n           ~~~~~~~~~~~~~~~~~~~~~~~^^^^^^^^^^^^^^^^^\n  File \"/Library/Frameworks/Python.framework/Versions/3.13/lib/python3.13/unittest/mock.py\", line 1226, in _execute_mock_call\n    raise effect\nrequests.exceptions.RequestException: Network Error", "trace_id": "N/A"}
{"timestamp": "2025-09-18T03:34:40.246367+09:00", "level": "ERROR", "name": "root", "message": "Ticketmaster API(35.68,139.69) 요청 중 오류: Network Error", "source": "ticketmaster.py:57", "function": "get_events_by_coords", "exc_info": "Traceback (most recent call last):\n  File \"/Users/gimhyeonmin/masamong/utils/api_handlers/ticketmaster.py\", line 37, in get_events_by_coords\n    response = await asyncio.to_thread(session.get, url, params=params, timeout=15)\n               ^^^^^^^^^^^^^^^^^^^^^^^^^^^^^^^^^^^^^^^^^^^^^^^^^^^^^^^^^^^^^^^^^^^^\n  File \"/Library/Frameworks/Python.framework/Versions/3.13/lib/python3.13/asyncio/threads.py\", line 25, in to_thread\n    return await loop.run_in_executor(None, func_call)\n           ^^^^^^^^^^^^^^^^^^^^^^^^^^^^^^^^^^^^^^^^^^^\n  File \"/Library/Frameworks/Python.framework/Versions/3.13/lib/python3.13/concurrent/futures/thread.py\", line 59, in run\n    result = self.fn(*self.args, **self.kwargs)\n  File \"/Library/Frameworks/Python.framework/Versions/3.13/lib/python3.13/unittest/mock.py\", line 1167, in __call__\n    return self._mock_call(*args, **kwargs)\n           ~~~~~~~~~~~~~~~^^^^^^^^^^^^^^^^^\n  File \"/Library/Frameworks/Python.framework/Versions/3.13/lib/python3.13/unittest/mock.py\", line 1171, in _mock_call\n    return self._execute_mock_call(*args, **kwargs)\n           ~~~~~~~~~~~~~~~~~~~~~~~^^^^^^^^^^^^^^^^^\n  File \"/Library/Frameworks/Python.framework/Versions/3.13/lib/python3.13/unittest/mock.py\", line 1226, in _execute_mock_call\n    raise effect\nrequests.exceptions.RequestException: Network Error", "trace_id": "N/A"}
{"timestamp": "2025-09-18T03:36:14.759998+09:00", "level": "ERROR", "name": "root", "message": "Foursquare API(35.68,139.69) 요청 중 오류: Network Error", "source": "foursquare.py:53", "function": "get_places_by_coords", "exc_info": "Traceback (most recent call last):\n  File \"/Users/gimhyeonmin/masamong/utils/api_handlers/foursquare.py\", line 35, in get_places_by_coords\n    response = await asyncio.to_thread(session.get, url, headers=headers, params=params, timeout=15)\n               ^^^^^^^^^^^^^^^^^^^^^^^^^^^^^^^^^^^^^^^^^^^^^^^^^^^^^^^^^^^^^^^^^^^^^^^^^^^^^^^^^^^^^\n  File \"/Library/Frameworks/Python.framework/Versions/3.13/lib/python3.13/asyncio/threads.py\", line 25, in to_thread\n    return await loop.run_in_executor(None, func_call)\n           ^^^^^^^^^^^^^^^^^^^^^^^^^^^^^^^^^^^^^^^^^^^\n  File \"/Library/Frameworks/Python.framework/Versions/3.13/lib/python3.13/concurrent/futures/thread.py\", line 59, in run\n    result = self.fn(*self.args, **self.kwargs)\n  File \"/Library/Frameworks/Python.framework/Versions/3.13/lib/python3.13/unittest/mock.py\", line 1167, in __call__\n    return self._mock_call(*args, **kwargs)\n           ~~~~~~~~~~~~~~~^^^^^^^^^^^^^^^^^\n  File \"/Library/Frameworks/Python.framework/Versions/3.13/lib/python3.13/unittest/mock.py\", line 1171, in _mock_call\n    return self._execute_mock_call(*args, **kwargs)\n           ~~~~~~~~~~~~~~~~~~~~~~~^^^^^^^^^^^^^^^^^\n  File \"/Library/Frameworks/Python.framework/Versions/3.13/lib/python3.13/unittest/mock.py\", line 1226, in _execute_mock_call\n    raise effect\nrequests.exceptions.RequestException: Network Error", "trace_id": "N/A"}
{"timestamp": "2025-09-18T03:36:19.196713+09:00", "level": "ERROR", "name": "root", "message": "OpenWeatherMap API(35.68,139.69) 요청 중 오류: Network Error", "source": "openweathermap.py:53", "function": "get_weather_by_coords", "exc_info": "Traceback (most recent call last):\n  File \"/Users/gimhyeonmin/masamong/utils/api_handlers/openweathermap.py\", line 31, in get_weather_by_coords\n    response = await asyncio.to_thread(session.get, url, params=params, timeout=10)\n               ^^^^^^^^^^^^^^^^^^^^^^^^^^^^^^^^^^^^^^^^^^^^^^^^^^^^^^^^^^^^^^^^^^^^\n  File \"/Library/Frameworks/Python.framework/Versions/3.13/lib/python3.13/asyncio/threads.py\", line 25, in to_thread\n    return await loop.run_in_executor(None, func_call)\n           ^^^^^^^^^^^^^^^^^^^^^^^^^^^^^^^^^^^^^^^^^^^\n  File \"/Library/Frameworks/Python.framework/Versions/3.13/lib/python3.13/concurrent/futures/thread.py\", line 59, in run\n    result = self.fn(*self.args, **self.kwargs)\n  File \"/Library/Frameworks/Python.framework/Versions/3.13/lib/python3.13/unittest/mock.py\", line 1167, in __call__\n    return self._mock_call(*args, **kwargs)\n           ~~~~~~~~~~~~~~~^^^^^^^^^^^^^^^^^\n  File \"/Library/Frameworks/Python.framework/Versions/3.13/lib/python3.13/unittest/mock.py\", line 1171, in _mock_call\n    return self._execute_mock_call(*args, **kwargs)\n           ~~~~~~~~~~~~~~~~~~~~~~~^^^^^^^^^^^^^^^^^\n  File \"/Library/Frameworks/Python.framework/Versions/3.13/lib/python3.13/unittest/mock.py\", line 1226, in _execute_mock_call\n    raise effect\nrequests.exceptions.RequestException: Network Error", "trace_id": "N/A"}
{"timestamp": "2025-09-18T03:36:19.204964+09:00", "level": "ERROR", "name": "root", "message": "Ticketmaster API(35.68,139.69) 요청 중 오류: Network Error", "source": "ticketmaster.py:57", "function": "get_events_by_coords", "exc_info": "Traceback (most recent call last):\n  File \"/Users/gimhyeonmin/masamong/utils/api_handlers/ticketmaster.py\", line 37, in get_events_by_coords\n    response = await asyncio.to_thread(session.get, url, params=params, timeout=15)\n               ^^^^^^^^^^^^^^^^^^^^^^^^^^^^^^^^^^^^^^^^^^^^^^^^^^^^^^^^^^^^^^^^^^^^\n  File \"/Library/Frameworks/Python.framework/Versions/3.13/lib/python3.13/asyncio/threads.py\", line 25, in to_thread\n    return await loop.run_in_executor(None, func_call)\n           ^^^^^^^^^^^^^^^^^^^^^^^^^^^^^^^^^^^^^^^^^^^\n  File \"/Library/Frameworks/Python.framework/Versions/3.13/lib/python3.13/concurrent/futures/thread.py\", line 59, in run\n    result = self.fn(*self.args, **self.kwargs)\n  File \"/Library/Frameworks/Python.framework/Versions/3.13/lib/python3.13/unittest/mock.py\", line 1167, in __call__\n    return self._mock_call(*args, **kwargs)\n           ~~~~~~~~~~~~~~~^^^^^^^^^^^^^^^^^\n  File \"/Library/Frameworks/Python.framework/Versions/3.13/lib/python3.13/unittest/mock.py\", line 1171, in _mock_call\n    return self._execute_mock_call(*args, **kwargs)\n           ~~~~~~~~~~~~~~~~~~~~~~~^^^^^^^^^^^^^^^^^\n  File \"/Library/Frameworks/Python.framework/Versions/3.13/lib/python3.13/unittest/mock.py\", line 1226, in _execute_mock_call\n    raise effect\nrequests.exceptions.RequestException: Network Error", "trace_id": "N/A"}
{"timestamp": "2025-09-18T03:38:05.671767+09:00", "level": "ERROR", "name": "root", "message": "Foursquare API(35.68,139.69) 요청 중 오류: Network Error", "source": "foursquare.py:53", "function": "get_places_by_coords", "exc_info": "Traceback (most recent call last):\n  File \"/Users/gimhyeonmin/masamong/utils/api_handlers/foursquare.py\", line 35, in get_places_by_coords\n    response = await asyncio.to_thread(session.get, url, headers=headers, params=params, timeout=15)\n               ^^^^^^^^^^^^^^^^^^^^^^^^^^^^^^^^^^^^^^^^^^^^^^^^^^^^^^^^^^^^^^^^^^^^^^^^^^^^^^^^^^^^^\n  File \"/Library/Frameworks/Python.framework/Versions/3.13/lib/python3.13/asyncio/threads.py\", line 25, in to_thread\n    return await loop.run_in_executor(None, func_call)\n           ^^^^^^^^^^^^^^^^^^^^^^^^^^^^^^^^^^^^^^^^^^^\n  File \"/Library/Frameworks/Python.framework/Versions/3.13/lib/python3.13/concurrent/futures/thread.py\", line 59, in run\n    result = self.fn(*self.args, **self.kwargs)\n  File \"/Library/Frameworks/Python.framework/Versions/3.13/lib/python3.13/unittest/mock.py\", line 1167, in __call__\n    return self._mock_call(*args, **kwargs)\n           ~~~~~~~~~~~~~~~^^^^^^^^^^^^^^^^^\n  File \"/Library/Frameworks/Python.framework/Versions/3.13/lib/python3.13/unittest/mock.py\", line 1171, in _mock_call\n    return self._execute_mock_call(*args, **kwargs)\n           ~~~~~~~~~~~~~~~~~~~~~~~^^^^^^^^^^^^^^^^^\n  File \"/Library/Frameworks/Python.framework/Versions/3.13/lib/python3.13/unittest/mock.py\", line 1226, in _execute_mock_call\n    raise effect\nrequests.exceptions.RequestException: Network Error", "trace_id": "N/A"}
{"timestamp": "2025-09-18T03:38:10.094604+09:00", "level": "ERROR", "name": "root", "message": "OpenWeatherMap API(35.68,139.69) 요청 중 오류: Network Error", "source": "openweathermap.py:53", "function": "get_weather_by_coords", "exc_info": "Traceback (most recent call last):\n  File \"/Users/gimhyeonmin/masamong/utils/api_handlers/openweathermap.py\", line 31, in get_weather_by_coords\n    response = await asyncio.to_thread(session.get, url, params=params, timeout=10)\n               ^^^^^^^^^^^^^^^^^^^^^^^^^^^^^^^^^^^^^^^^^^^^^^^^^^^^^^^^^^^^^^^^^^^^\n  File \"/Library/Frameworks/Python.framework/Versions/3.13/lib/python3.13/asyncio/threads.py\", line 25, in to_thread\n    return await loop.run_in_executor(None, func_call)\n           ^^^^^^^^^^^^^^^^^^^^^^^^^^^^^^^^^^^^^^^^^^^\n  File \"/Library/Frameworks/Python.framework/Versions/3.13/lib/python3.13/concurrent/futures/thread.py\", line 59, in run\n    result = self.fn(*self.args, **self.kwargs)\n  File \"/Library/Frameworks/Python.framework/Versions/3.13/lib/python3.13/unittest/mock.py\", line 1167, in __call__\n    return self._mock_call(*args, **kwargs)\n           ~~~~~~~~~~~~~~~^^^^^^^^^^^^^^^^^\n  File \"/Library/Frameworks/Python.framework/Versions/3.13/lib/python3.13/unittest/mock.py\", line 1171, in _mock_call\n    return self._execute_mock_call(*args, **kwargs)\n           ~~~~~~~~~~~~~~~~~~~~~~~^^^^^^^^^^^^^^^^^\n  File \"/Library/Frameworks/Python.framework/Versions/3.13/lib/python3.13/unittest/mock.py\", line 1226, in _execute_mock_call\n    raise effect\nrequests.exceptions.RequestException: Network Error", "trace_id": "N/A"}
{"timestamp": "2025-09-18T03:38:10.099203+09:00", "level": "ERROR", "name": "root", "message": "Ticketmaster API(35.68,139.69) 요청 중 오류: Network Error", "source": "ticketmaster.py:57", "function": "get_events_by_coords", "exc_info": "Traceback (most recent call last):\n  File \"/Users/gimhyeonmin/masamong/utils/api_handlers/ticketmaster.py\", line 37, in get_events_by_coords\n    response = await asyncio.to_thread(session.get, url, params=params, timeout=15)\n               ^^^^^^^^^^^^^^^^^^^^^^^^^^^^^^^^^^^^^^^^^^^^^^^^^^^^^^^^^^^^^^^^^^^^\n  File \"/Library/Frameworks/Python.framework/Versions/3.13/lib/python3.13/asyncio/threads.py\", line 25, in to_thread\n    return await loop.run_in_executor(None, func_call)\n           ^^^^^^^^^^^^^^^^^^^^^^^^^^^^^^^^^^^^^^^^^^^\n  File \"/Library/Frameworks/Python.framework/Versions/3.13/lib/python3.13/concurrent/futures/thread.py\", line 59, in run\n    result = self.fn(*self.args, **self.kwargs)\n  File \"/Library/Frameworks/Python.framework/Versions/3.13/lib/python3.13/unittest/mock.py\", line 1167, in __call__\n    return self._mock_call(*args, **kwargs)\n           ~~~~~~~~~~~~~~~^^^^^^^^^^^^^^^^^\n  File \"/Library/Frameworks/Python.framework/Versions/3.13/lib/python3.13/unittest/mock.py\", line 1171, in _mock_call\n    return self._execute_mock_call(*args, **kwargs)\n           ~~~~~~~~~~~~~~~~~~~~~~~^^^^^^^^^^^^^^^^^\n  File \"/Library/Frameworks/Python.framework/Versions/3.13/lib/python3.13/unittest/mock.py\", line 1226, in _execute_mock_call\n    raise effect\nrequests.exceptions.RequestException: Network Error", "trace_id": "N/A"}
{"timestamp": "2025-09-18T03:38:10.106863+09:00", "level": "ERROR", "name": "root", "message": "Gemini 응답 생성 중 예기치 않은 오류: object MagicMock can't be used in 'await' expression", "source": "ai_handler.py:97", "function": "_safe_generate_content", "exc_info": "Traceback (most recent call last):\n  File \"/Users/gimhyeonmin/masamong/cogs/ai_handler.py\", line 68, in _safe_generate_content\n    if await db_utils.check_api_rate_limit(self.bot.db, limit_key, rpm, rpd):\n       ^^^^^^^^^^^^^^^^^^^^^^^^^^^^^^^^^^^^^^^^^^^^^^^^^^^^^^^^^^^^^^^^^^^^^\n  File \"/Users/gimhyeonmin/masamong/utils/db.py\", line 123, in check_api_rate_limit\n    await db.execute(\"DELETE FROM api_call_log WHERE called_at < ?\", (one_day_ago,))\nTypeError: object MagicMock can't be used in 'await' expression", "guild_id": 123, "user_id": 789, "channel_id": 456, "trace_id": "f89cea7f"}
{"timestamp": "2025-09-18T03:38:10.108166+09:00", "level": "ERROR", "name": "root", "message": "Lite 모델(PM)이 응답을 생성하지 못했습니다.", "source": "ai_handler.py:277", "function": "process_agent_message", "guild_id": 123, "user_id": 789, "channel_id": 456, "trace_id": "f89cea7f"}
{"timestamp": "2025-09-18T03:38:28.189560+09:00", "level": "ERROR", "name": "root", "message": "Foursquare API(35.68,139.69) 요청 중 오류: Network Error", "source": "foursquare.py:53", "function": "get_places_by_coords", "exc_info": "Traceback (most recent call last):\n  File \"/Users/gimhyeonmin/masamong/utils/api_handlers/foursquare.py\", line 35, in get_places_by_coords\n    response = await asyncio.to_thread(session.get, url, headers=headers, params=params, timeout=15)\n               ^^^^^^^^^^^^^^^^^^^^^^^^^^^^^^^^^^^^^^^^^^^^^^^^^^^^^^^^^^^^^^^^^^^^^^^^^^^^^^^^^^^^^\n  File \"/Library/Frameworks/Python.framework/Versions/3.13/lib/python3.13/asyncio/threads.py\", line 25, in to_thread\n    return await loop.run_in_executor(None, func_call)\n           ^^^^^^^^^^^^^^^^^^^^^^^^^^^^^^^^^^^^^^^^^^^\n  File \"/Library/Frameworks/Python.framework/Versions/3.13/lib/python3.13/concurrent/futures/thread.py\", line 59, in run\n    result = self.fn(*self.args, **self.kwargs)\n  File \"/Library/Frameworks/Python.framework/Versions/3.13/lib/python3.13/unittest/mock.py\", line 1167, in __call__\n    return self._mock_call(*args, **kwargs)\n           ~~~~~~~~~~~~~~~^^^^^^^^^^^^^^^^^\n  File \"/Library/Frameworks/Python.framework/Versions/3.13/lib/python3.13/unittest/mock.py\", line 1171, in _mock_call\n    return self._execute_mock_call(*args, **kwargs)\n           ~~~~~~~~~~~~~~~~~~~~~~~^^^^^^^^^^^^^^^^^\n  File \"/Library/Frameworks/Python.framework/Versions/3.13/lib/python3.13/unittest/mock.py\", line 1226, in _execute_mock_call\n    raise effect\nrequests.exceptions.RequestException: Network Error", "trace_id": "N/A"}
{"timestamp": "2025-09-18T03:38:32.624111+09:00", "level": "ERROR", "name": "root", "message": "OpenWeatherMap API(35.68,139.69) 요청 중 오류: Network Error", "source": "openweathermap.py:53", "function": "get_weather_by_coords", "exc_info": "Traceback (most recent call last):\n  File \"/Users/gimhyeonmin/masamong/utils/api_handlers/openweathermap.py\", line 31, in get_weather_by_coords\n    response = await asyncio.to_thread(session.get, url, params=params, timeout=10)\n               ^^^^^^^^^^^^^^^^^^^^^^^^^^^^^^^^^^^^^^^^^^^^^^^^^^^^^^^^^^^^^^^^^^^^\n  File \"/Library/Frameworks/Python.framework/Versions/3.13/lib/python3.13/asyncio/threads.py\", line 25, in to_thread\n    return await loop.run_in_executor(None, func_call)\n           ^^^^^^^^^^^^^^^^^^^^^^^^^^^^^^^^^^^^^^^^^^^\n  File \"/Library/Frameworks/Python.framework/Versions/3.13/lib/python3.13/concurrent/futures/thread.py\", line 59, in run\n    result = self.fn(*self.args, **self.kwargs)\n  File \"/Library/Frameworks/Python.framework/Versions/3.13/lib/python3.13/unittest/mock.py\", line 1167, in __call__\n    return self._mock_call(*args, **kwargs)\n           ~~~~~~~~~~~~~~~^^^^^^^^^^^^^^^^^\n  File \"/Library/Frameworks/Python.framework/Versions/3.13/lib/python3.13/unittest/mock.py\", line 1171, in _mock_call\n    return self._execute_mock_call(*args, **kwargs)\n           ~~~~~~~~~~~~~~~~~~~~~~~^^^^^^^^^^^^^^^^^\n  File \"/Library/Frameworks/Python.framework/Versions/3.13/lib/python3.13/unittest/mock.py\", line 1226, in _execute_mock_call\n    raise effect\nrequests.exceptions.RequestException: Network Error", "trace_id": "N/A"}
{"timestamp": "2025-09-18T03:38:32.630629+09:00", "level": "ERROR", "name": "root", "message": "Ticketmaster API(35.68,139.69) 요청 중 오류: Network Error", "source": "ticketmaster.py:57", "function": "get_events_by_coords", "exc_info": "Traceback (most recent call last):\n  File \"/Users/gimhyeonmin/masamong/utils/api_handlers/ticketmaster.py\", line 37, in get_events_by_coords\n    response = await asyncio.to_thread(session.get, url, params=params, timeout=15)\n               ^^^^^^^^^^^^^^^^^^^^^^^^^^^^^^^^^^^^^^^^^^^^^^^^^^^^^^^^^^^^^^^^^^^^\n  File \"/Library/Frameworks/Python.framework/Versions/3.13/lib/python3.13/asyncio/threads.py\", line 25, in to_thread\n    return await loop.run_in_executor(None, func_call)\n           ^^^^^^^^^^^^^^^^^^^^^^^^^^^^^^^^^^^^^^^^^^^\n  File \"/Library/Frameworks/Python.framework/Versions/3.13/lib/python3.13/concurrent/futures/thread.py\", line 59, in run\n    result = self.fn(*self.args, **self.kwargs)\n  File \"/Library/Frameworks/Python.framework/Versions/3.13/lib/python3.13/unittest/mock.py\", line 1167, in __call__\n    return self._mock_call(*args, **kwargs)\n           ~~~~~~~~~~~~~~~^^^^^^^^^^^^^^^^^\n  File \"/Library/Frameworks/Python.framework/Versions/3.13/lib/python3.13/unittest/mock.py\", line 1171, in _mock_call\n    return self._execute_mock_call(*args, **kwargs)\n           ~~~~~~~~~~~~~~~~~~~~~~~^^^^^^^^^^^^^^^^^\n  File \"/Library/Frameworks/Python.framework/Versions/3.13/lib/python3.13/unittest/mock.py\", line 1226, in _execute_mock_call\n    raise effect\nrequests.exceptions.RequestException: Network Error", "trace_id": "N/A"}
{"timestamp": "2025-09-18T03:38:32.641650+09:00", "level": "ERROR", "name": "root", "message": "Gemini 응답 생성 중 예기치 않은 오류: 'coroutine' object does not support the asynchronous context manager protocol", "source": "ai_handler.py:97", "function": "_safe_generate_content", "exc_info": "Traceback (most recent call last):\n  File \"/Users/gimhyeonmin/masamong/cogs/ai_handler.py\", line 68, in _safe_generate_content\n    if await db_utils.check_api_rate_limit(self.bot.db, limit_key, rpm, rpd):\n       ^^^^^^^^^^^^^^^^^^^^^^^^^^^^^^^^^^^^^^^^^^^^^^^^^^^^^^^^^^^^^^^^^^^^^\n  File \"/Users/gimhyeonmin/masamong/utils/db.py\", line 126, in check_api_rate_limit\n    async with db.execute(\"SELECT COUNT(*) FROM api_call_log WHERE api_type = ? AND called_at >= ?\", (api_type, one_day_ago)) as cursor:\n               ~~~~~~~~~~^^^^^^^^^^^^^^^^^^^^^^^^^^^^^^^^^^^^^^^^^^^^^^^^^^^^^^^^^^^^^^^^^^^^^^^^^^^^^^^^^^^^^^^^^^^^^^^^^^^^\nTypeError: 'coroutine' object does not support the asynchronous context manager protocol", "guild_id": 123, "user_id": 789, "channel_id": 456, "trace_id": "1daf5272"}
{"timestamp": "2025-09-18T03:38:32.642773+09:00", "level": "ERROR", "name": "root", "message": "Lite 모델(PM)이 응답을 생성하지 못했습니다.", "source": "ai_handler.py:277", "function": "process_agent_message", "guild_id": 123, "user_id": 789, "channel_id": 456, "trace_id": "1daf5272"}
{"timestamp": "2025-09-18T03:38:55.587300+09:00", "level": "ERROR", "name": "root", "message": "Foursquare API(35.68,139.69) 요청 중 오류: Network Error", "source": "foursquare.py:53", "function": "get_places_by_coords", "exc_info": "Traceback (most recent call last):\n  File \"/Users/gimhyeonmin/masamong/utils/api_handlers/foursquare.py\", line 35, in get_places_by_coords\n    response = await asyncio.to_thread(session.get, url, headers=headers, params=params, timeout=15)\n               ^^^^^^^^^^^^^^^^^^^^^^^^^^^^^^^^^^^^^^^^^^^^^^^^^^^^^^^^^^^^^^^^^^^^^^^^^^^^^^^^^^^^^\n  File \"/Library/Frameworks/Python.framework/Versions/3.13/lib/python3.13/asyncio/threads.py\", line 25, in to_thread\n    return await loop.run_in_executor(None, func_call)\n           ^^^^^^^^^^^^^^^^^^^^^^^^^^^^^^^^^^^^^^^^^^^\n  File \"/Library/Frameworks/Python.framework/Versions/3.13/lib/python3.13/concurrent/futures/thread.py\", line 59, in run\n    result = self.fn(*self.args, **self.kwargs)\n  File \"/Library/Frameworks/Python.framework/Versions/3.13/lib/python3.13/unittest/mock.py\", line 1167, in __call__\n    return self._mock_call(*args, **kwargs)\n           ~~~~~~~~~~~~~~~^^^^^^^^^^^^^^^^^\n  File \"/Library/Frameworks/Python.framework/Versions/3.13/lib/python3.13/unittest/mock.py\", line 1171, in _mock_call\n    return self._execute_mock_call(*args, **kwargs)\n           ~~~~~~~~~~~~~~~~~~~~~~~^^^^^^^^^^^^^^^^^\n  File \"/Library/Frameworks/Python.framework/Versions/3.13/lib/python3.13/unittest/mock.py\", line 1226, in _execute_mock_call\n    raise effect\nrequests.exceptions.RequestException: Network Error", "trace_id": "N/A"}
{"timestamp": "2025-09-18T03:39:00.024844+09:00", "level": "ERROR", "name": "root", "message": "OpenWeatherMap API(35.68,139.69) 요청 중 오류: Network Error", "source": "openweathermap.py:53", "function": "get_weather_by_coords", "exc_info": "Traceback (most recent call last):\n  File \"/Users/gimhyeonmin/masamong/utils/api_handlers/openweathermap.py\", line 31, in get_weather_by_coords\n    response = await asyncio.to_thread(session.get, url, params=params, timeout=10)\n               ^^^^^^^^^^^^^^^^^^^^^^^^^^^^^^^^^^^^^^^^^^^^^^^^^^^^^^^^^^^^^^^^^^^^\n  File \"/Library/Frameworks/Python.framework/Versions/3.13/lib/python3.13/asyncio/threads.py\", line 25, in to_thread\n    return await loop.run_in_executor(None, func_call)\n           ^^^^^^^^^^^^^^^^^^^^^^^^^^^^^^^^^^^^^^^^^^^\n  File \"/Library/Frameworks/Python.framework/Versions/3.13/lib/python3.13/concurrent/futures/thread.py\", line 59, in run\n    result = self.fn(*self.args, **self.kwargs)\n  File \"/Library/Frameworks/Python.framework/Versions/3.13/lib/python3.13/unittest/mock.py\", line 1167, in __call__\n    return self._mock_call(*args, **kwargs)\n           ~~~~~~~~~~~~~~~^^^^^^^^^^^^^^^^^\n  File \"/Library/Frameworks/Python.framework/Versions/3.13/lib/python3.13/unittest/mock.py\", line 1171, in _mock_call\n    return self._execute_mock_call(*args, **kwargs)\n           ~~~~~~~~~~~~~~~~~~~~~~~^^^^^^^^^^^^^^^^^\n  File \"/Library/Frameworks/Python.framework/Versions/3.13/lib/python3.13/unittest/mock.py\", line 1226, in _execute_mock_call\n    raise effect\nrequests.exceptions.RequestException: Network Error", "trace_id": "N/A"}
{"timestamp": "2025-09-18T03:39:00.034251+09:00", "level": "ERROR", "name": "root", "message": "Ticketmaster API(35.68,139.69) 요청 중 오류: Network Error", "source": "ticketmaster.py:57", "function": "get_events_by_coords", "exc_info": "Traceback (most recent call last):\n  File \"/Users/gimhyeonmin/masamong/utils/api_handlers/ticketmaster.py\", line 37, in get_events_by_coords\n    response = await asyncio.to_thread(session.get, url, params=params, timeout=15)\n               ^^^^^^^^^^^^^^^^^^^^^^^^^^^^^^^^^^^^^^^^^^^^^^^^^^^^^^^^^^^^^^^^^^^^\n  File \"/Library/Frameworks/Python.framework/Versions/3.13/lib/python3.13/asyncio/threads.py\", line 25, in to_thread\n    return await loop.run_in_executor(None, func_call)\n           ^^^^^^^^^^^^^^^^^^^^^^^^^^^^^^^^^^^^^^^^^^^\n  File \"/Library/Frameworks/Python.framework/Versions/3.13/lib/python3.13/concurrent/futures/thread.py\", line 59, in run\n    result = self.fn(*self.args, **self.kwargs)\n  File \"/Library/Frameworks/Python.framework/Versions/3.13/lib/python3.13/unittest/mock.py\", line 1167, in __call__\n    return self._mock_call(*args, **kwargs)\n           ~~~~~~~~~~~~~~~^^^^^^^^^^^^^^^^^\n  File \"/Library/Frameworks/Python.framework/Versions/3.13/lib/python3.13/unittest/mock.py\", line 1171, in _mock_call\n    return self._execute_mock_call(*args, **kwargs)\n           ~~~~~~~~~~~~~~~~~~~~~~~^^^^^^^^^^^^^^^^^\n  File \"/Library/Frameworks/Python.framework/Versions/3.13/lib/python3.13/unittest/mock.py\", line 1226, in _execute_mock_call\n    raise effect\nrequests.exceptions.RequestException: Network Error", "trace_id": "N/A"}
{"timestamp": "2025-09-18T03:39:00.049099+09:00", "level": "ERROR", "name": "root", "message": "에이전트 처리 중 최상위 오류: 'coroutine' object does not support the asynchronous context manager protocol", "source": "ai_handler.py:357", "function": "process_agent_message", "exc_info": "Traceback (most recent call last):\n  File \"/Users/gimhyeonmin/masamong/cogs/ai_handler.py\", line 341, in process_agent_message\n    custom_persona = await db_utils.get_guild_setting(self.bot.db, message.guild.id, 'persona_text')\n                     ^^^^^^^^^^^^^^^^^^^^^^^^^^^^^^^^^^^^^^^^^^^^^^^^^^^^^^^^^^^^^^^^^^^^^^^^^^^^^^^\n  File \"/Users/gimhyeonmin/masamong/utils/db.py\", line 49, in get_guild_setting\n    async with db.execute(f\"SELECT {setting_name} FROM guild_settings WHERE guild_id = ?\", (guild_id,)) as cursor:\n               ~~~~~~~~~~^^^^^^^^^^^^^^^^^^^^^^^^^^^^^^^^^^^^^^^^^^^^^^^^^^^^^^^^^^^^^^^^^^^^^^^^^^^^^^\nTypeError: 'coroutine' object does not support the asynchronous context manager protocol", "guild_id": 123, "user_id": 789, "channel_id": 456, "trace_id": "9efda34d"}
{"timestamp": "2025-09-18T03:39:23.104813+09:00", "level": "ERROR", "name": "root", "message": "Foursquare API(35.68,139.69) 요청 중 오류: Network Error", "source": "foursquare.py:53", "function": "get_places_by_coords", "exc_info": "Traceback (most recent call last):\n  File \"/Users/gimhyeonmin/masamong/utils/api_handlers/foursquare.py\", line 35, in get_places_by_coords\n    response = await asyncio.to_thread(session.get, url, headers=headers, params=params, timeout=15)\n               ^^^^^^^^^^^^^^^^^^^^^^^^^^^^^^^^^^^^^^^^^^^^^^^^^^^^^^^^^^^^^^^^^^^^^^^^^^^^^^^^^^^^^\n  File \"/Library/Frameworks/Python.framework/Versions/3.13/lib/python3.13/asyncio/threads.py\", line 25, in to_thread\n    return await loop.run_in_executor(None, func_call)\n           ^^^^^^^^^^^^^^^^^^^^^^^^^^^^^^^^^^^^^^^^^^^\n  File \"/Library/Frameworks/Python.framework/Versions/3.13/lib/python3.13/concurrent/futures/thread.py\", line 59, in run\n    result = self.fn(*self.args, **self.kwargs)\n  File \"/Library/Frameworks/Python.framework/Versions/3.13/lib/python3.13/unittest/mock.py\", line 1167, in __call__\n    return self._mock_call(*args, **kwargs)\n           ~~~~~~~~~~~~~~~^^^^^^^^^^^^^^^^^\n  File \"/Library/Frameworks/Python.framework/Versions/3.13/lib/python3.13/unittest/mock.py\", line 1171, in _mock_call\n    return self._execute_mock_call(*args, **kwargs)\n           ~~~~~~~~~~~~~~~~~~~~~~~^^^^^^^^^^^^^^^^^\n  File \"/Library/Frameworks/Python.framework/Versions/3.13/lib/python3.13/unittest/mock.py\", line 1226, in _execute_mock_call\n    raise effect\nrequests.exceptions.RequestException: Network Error", "trace_id": "N/A"}
{"timestamp": "2025-09-18T03:39:27.540126+09:00", "level": "ERROR", "name": "root", "message": "OpenWeatherMap API(35.68,139.69) 요청 중 오류: Network Error", "source": "openweathermap.py:53", "function": "get_weather_by_coords", "exc_info": "Traceback (most recent call last):\n  File \"/Users/gimhyeonmin/masamong/utils/api_handlers/openweathermap.py\", line 31, in get_weather_by_coords\n    response = await asyncio.to_thread(session.get, url, params=params, timeout=10)\n               ^^^^^^^^^^^^^^^^^^^^^^^^^^^^^^^^^^^^^^^^^^^^^^^^^^^^^^^^^^^^^^^^^^^^\n  File \"/Library/Frameworks/Python.framework/Versions/3.13/lib/python3.13/asyncio/threads.py\", line 25, in to_thread\n    return await loop.run_in_executor(None, func_call)\n           ^^^^^^^^^^^^^^^^^^^^^^^^^^^^^^^^^^^^^^^^^^^\n  File \"/Library/Frameworks/Python.framework/Versions/3.13/lib/python3.13/concurrent/futures/thread.py\", line 59, in run\n    result = self.fn(*self.args, **self.kwargs)\n  File \"/Library/Frameworks/Python.framework/Versions/3.13/lib/python3.13/unittest/mock.py\", line 1167, in __call__\n    return self._mock_call(*args, **kwargs)\n           ~~~~~~~~~~~~~~~^^^^^^^^^^^^^^^^^\n  File \"/Library/Frameworks/Python.framework/Versions/3.13/lib/python3.13/unittest/mock.py\", line 1171, in _mock_call\n    return self._execute_mock_call(*args, **kwargs)\n           ~~~~~~~~~~~~~~~~~~~~~~~^^^^^^^^^^^^^^^^^\n  File \"/Library/Frameworks/Python.framework/Versions/3.13/lib/python3.13/unittest/mock.py\", line 1226, in _execute_mock_call\n    raise effect\nrequests.exceptions.RequestException: Network Error", "trace_id": "N/A"}
{"timestamp": "2025-09-18T03:39:27.546740+09:00", "level": "ERROR", "name": "root", "message": "Ticketmaster API(35.68,139.69) 요청 중 오류: Network Error", "source": "ticketmaster.py:57", "function": "get_events_by_coords", "exc_info": "Traceback (most recent call last):\n  File \"/Users/gimhyeonmin/masamong/utils/api_handlers/ticketmaster.py\", line 37, in get_events_by_coords\n    response = await asyncio.to_thread(session.get, url, params=params, timeout=15)\n               ^^^^^^^^^^^^^^^^^^^^^^^^^^^^^^^^^^^^^^^^^^^^^^^^^^^^^^^^^^^^^^^^^^^^\n  File \"/Library/Frameworks/Python.framework/Versions/3.13/lib/python3.13/asyncio/threads.py\", line 25, in to_thread\n    return await loop.run_in_executor(None, func_call)\n           ^^^^^^^^^^^^^^^^^^^^^^^^^^^^^^^^^^^^^^^^^^^\n  File \"/Library/Frameworks/Python.framework/Versions/3.13/lib/python3.13/concurrent/futures/thread.py\", line 59, in run\n    result = self.fn(*self.args, **self.kwargs)\n  File \"/Library/Frameworks/Python.framework/Versions/3.13/lib/python3.13/unittest/mock.py\", line 1167, in __call__\n    return self._mock_call(*args, **kwargs)\n           ~~~~~~~~~~~~~~~^^^^^^^^^^^^^^^^^\n  File \"/Library/Frameworks/Python.framework/Versions/3.13/lib/python3.13/unittest/mock.py\", line 1171, in _mock_call\n    return self._execute_mock_call(*args, **kwargs)\n           ~~~~~~~~~~~~~~~~~~~~~~~^^^^^^^^^^^^^^^^^\n  File \"/Library/Frameworks/Python.framework/Versions/3.13/lib/python3.13/unittest/mock.py\", line 1226, in _execute_mock_call\n    raise effect\nrequests.exceptions.RequestException: Network Error", "trace_id": "N/A"}
{"timestamp": "2025-09-18T04:19:25.340276+09:00", "level": "ERROR", "name": "root", "message": "KRX API('삼성전자') 요청 중 오류: HTTPSConnectionPool(host='apis.data.go.kr', port=443): Max retries exceeded with url: /1160100/service/GetStockSecuritiesInfoService/getStockPriceInfo?serviceKey=m%2BjNX%2FMrO%2FJVlFzMEc%2BDL6Tjn1403dbgFk23bXD6jZcK0DAPPO0wue0rYrJlPXe%2F%2FvBKgRWoIbta%2FBVhiCfetQ%3D%3D+&itmsNm=%EC%82%BC%EC%84%B1%EC%A0%84%EC%9E%90&resultType=json&numOfRows=1&basDt=20250917 (Caused by SSLError(SSLError(1, '[SSL: SSLV3_ALERT_ILLEGAL_PARAMETER] sslv3 alert illegal parameter (_ssl.c:1000)')))", "source": "krx.py:158", "function": "get_stock_price", "exc_info": "Traceback (most recent call last):\n  File \"/home/masamong/masamong/venv/lib/python3.12/site-packages/urllib3/connectionpool.py\", line 464, in _make_request\n    self._validate_conn(conn)\n  File \"/home/masamong/masamong/venv/lib/python3.12/site-packages/urllib3/connectionpool.py\", line 1093, in _validate_conn\n    conn.connect()\n  File \"/home/masamong/masamong/venv/lib/python3.12/site-packages/urllib3/connection.py\", line 790, in connect\n    sock_and_verified = _ssl_wrap_socket_and_match_hostname(\n                        ^^^^^^^^^^^^^^^^^^^^^^^^^^^^^^^^^^^^\n  File \"/home/masamong/masamong/venv/lib/python3.12/site-packages/urllib3/connection.py\", line 969, in _ssl_wrap_socket_and_match_hostname\n    ssl_sock = ssl_wrap_socket(\n               ^^^^^^^^^^^^^^^^\n  File \"/home/masamong/masamong/venv/lib/python3.12/site-packages/urllib3/util/ssl_.py\", line 480, in ssl_wrap_socket\n    ssl_sock = _ssl_wrap_socket_impl(sock, context, tls_in_tls, server_hostname)\n               ^^^^^^^^^^^^^^^^^^^^^^^^^^^^^^^^^^^^^^^^^^^^^^^^^^^^^^^^^^^^^^^^^\n  File \"/home/masamong/masamong/venv/lib/python3.12/site-packages/urllib3/util/ssl_.py\", line 524, in _ssl_wrap_socket_impl\n    return ssl_context.wrap_socket(sock, server_hostname=server_hostname)\n           ^^^^^^^^^^^^^^^^^^^^^^^^^^^^^^^^^^^^^^^^^^^^^^^^^^^^^^^^^^^^^^\n  File \"/usr/lib/python3.12/ssl.py\", line 455, in wrap_socket\n    return self.sslsocket_class._create(\n           ^^^^^^^^^^^^^^^^^^^^^^^^^^^^^\n  File \"/usr/lib/python3.12/ssl.py\", line 1042, in _create\n    self.do_handshake()\n  File \"/usr/lib/python3.12/ssl.py\", line 1320, in do_handshake\n    self._sslobj.do_handshake()\nssl.SSLError: [SSL: SSLV3_ALERT_ILLEGAL_PARAMETER] sslv3 alert illegal parameter (_ssl.c:1000)\n\nDuring handling of the above exception, another exception occurred:\n\nTraceback (most recent call last):\n  File \"/home/masamong/masamong/venv/lib/python3.12/site-packages/urllib3/connectionpool.py\", line 787, in urlopen\n    response = self._make_request(\n               ^^^^^^^^^^^^^^^^^^^\n  File \"/home/masamong/masamong/venv/lib/python3.12/site-packages/urllib3/connectionpool.py\", line 488, in _make_request\n    raise new_e\nurllib3.exceptions.SSLError: [SSL: SSLV3_ALERT_ILLEGAL_PARAMETER] sslv3 alert illegal parameter (_ssl.c:1000)\n\nThe above exception was the direct cause of the following exception:\n\nTraceback (most recent call last):\n  File \"/home/masamong/masamong/venv/lib/python3.12/site-packages/requests/adapters.py\", line 644, in send\n    resp = conn.urlopen(\n           ^^^^^^^^^^^^^\n  File \"/home/masamong/masamong/venv/lib/python3.12/site-packages/urllib3/connectionpool.py\", line 841, in urlopen\n    retries = retries.increment(\n              ^^^^^^^^^^^^^^^^^^\n  File \"/home/masamong/masamong/venv/lib/python3.12/site-packages/urllib3/util/retry.py\", line 519, in increment\n    raise MaxRetryError(_pool, url, reason) from reason  # type: ignore[arg-type]\n    ^^^^^^^^^^^^^^^^^^^^^^^^^^^^^^^^^^^^^^^^^^^^^^^^^^^\nurllib3.exceptions.MaxRetryError: HTTPSConnectionPool(host='apis.data.go.kr', port=443): Max retries exceeded with url: /1160100/service/GetStockSecuritiesInfoService/getStockPriceInfo?serviceKey=m%2BjNX%2FMrO%2FJVlFzMEc%2BDL6Tjn1403dbgFk23bXD6jZcK0DAPPO0wue0rYrJlPXe%2F%2FvBKgRWoIbta%2FBVhiCfetQ%3D%3D+&itmsNm=%EC%82%BC%EC%84%B1%EC%A0%84%EC%9E%90&resultType=json&numOfRows=1&basDt=20250917 (Caused by SSLError(SSLError(1, '[SSL: SSLV3_ALERT_ILLEGAL_PARAMETER] sslv3 alert illegal parameter (_ssl.c:1000)')))\n\nDuring handling of the above exception, another exception occurred:\n\nTraceback (most recent call last):\n  File \"/home/masamong/masamong/utils/api_handlers/krx.py\", line 134, in get_stock_price\n    stock_info_raw = await _get_price_from_krx(normalized_name)\n                     ^^^^^^^^^^^^^^^^^^^^^^^^^^^^^^^^^^^^^^^^^^\n  File \"/home/masamong/masamong/utils/api_handlers/krx.py\", line 123, in _get_price_from_krx\n    response = await asyncio.to_thread(session.get, config.KRX_BASE_URL, params=params, timeout=10)\n               ^^^^^^^^^^^^^^^^^^^^^^^^^^^^^^^^^^^^^^^^^^^^^^^^^^^^^^^^^^^^^^^^^^^^^^^^^^^^^^^^^^^^\n  File \"/usr/lib/python3.12/asyncio/threads.py\", line 25, in to_thread\n    return await loop.run_in_executor(None, func_call)\n           ^^^^^^^^^^^^^^^^^^^^^^^^^^^^^^^^^^^^^^^^^^^\n  File \"/usr/lib/python3.12/concurrent/futures/thread.py\", line 58, in run\n    result = self.fn(*self.args, **self.kwargs)\n             ^^^^^^^^^^^^^^^^^^^^^^^^^^^^^^^^^^\n  File \"/home/masamong/masamong/venv/lib/python3.12/site-packages/requests/sessions.py\", line 602, in get\n    return self.request(\"GET\", url, **kwargs)\n           ^^^^^^^^^^^^^^^^^^^^^^^^^^^^^^^^^^\n  File \"/home/masamong/masamong/venv/lib/python3.12/site-packages/requests/sessions.py\", line 589, in request\n    resp = self.send(prep, **send_kwargs)\n           ^^^^^^^^^^^^^^^^^^^^^^^^^^^^^^\n  File \"/home/masamong/masamong/venv/lib/python3.12/site-packages/requests/sessions.py\", line 703, in send\n    r = adapter.send(request, **kwargs)\n        ^^^^^^^^^^^^^^^^^^^^^^^^^^^^^^^\n  File \"/home/masamong/masamong/venv/lib/python3.12/site-packages/requests/adapters.py\", line 675, in send\n    raise SSLError(e, request=request)\nrequests.exceptions.SSLError: HTTPSConnectionPool(host='apis.data.go.kr', port=443): Max retries exceeded with url: /1160100/service/GetStockSecuritiesInfoService/getStockPriceInfo?serviceKey=m%2BjNX%2FMrO%2FJVlFzMEc%2BDL6Tjn1403dbgFk23bXD6jZcK0DAPPO0wue0rYrJlPXe%2F%2FvBKgRWoIbta%2FBVhiCfetQ%3D%3D+&itmsNm=%EC%82%BC%EC%84%B1%EC%A0%84%EC%9E%90&resultType=json&numOfRows=1&basDt=20250917 (Caused by SSLError(SSLError(1, '[SSL: SSLV3_ALERT_ILLEGAL_PARAMETER] sslv3 alert illegal parameter (_ssl.c:1000)')))", "trace_id": "N/A"}
{"timestamp": "2025-09-18T04:19:25.502437+09:00", "level": "ERROR", "name": "root", "message": "Gemini 응답 생성 중 예기치 않은 오류: contents must not be empty", "source": "ai_handler.py:97", "function": "_safe_generate_content", "exc_info": "Traceback (most recent call last):\n  File \"/home/masamong/masamong/cogs/ai_handler.py\", line 72, in _safe_generate_content\n    response = await model.generate_content_async(\n               ^^^^^^^^^^^^^^^^^^^^^^^^^^^^^^^^^^^\n  File \"/home/masamong/masamong/venv/lib/python3.12/site-packages/google/generativeai/generative_models.py\", line 357, in generate_content_async\n    raise TypeError(\"contents must not be empty\")\nTypeError: contents must not be empty", "guild_id": 1406585231850340492, "user_id": 275928240126820352, "channel_id": 1406585232752381970, "trace_id": "9f91bd3a"}
{"timestamp": "2025-09-18T04:19:25.505078+09:00", "level": "ERROR", "name": "root", "message": "Main 모델이 최종 답변을 생성하지 못했습니다.", "source": "ai_handler.py:383", "function": "process_agent_message", "guild_id": 1406585231850340492, "user_id": 275928240126820352, "channel_id": 1406585232752381970, "trace_id": "9f91bd3a"}
